<?xml version="1.0" ?>
<!-- =================================================================================== -->
<!-- |    This document was autogenerated by xacro from standalone_arm.xacro           | -->
<!-- |    EDITING THIS FILE BY HAND IS NOT RECOMMENDED                                 | -->
<!-- =================================================================================== -->
<robot name="alice" xmlns:body="http://playerstage.sourceforge.net/gazebo/xmlschema/#body" xmlns:controller="http://playerstage.sourceforge.net/gazebo/xmlschema/#controller" xmlns:gazebo="http://playerstage.sourceforge.net/gazebo/xmlschema/#gz" xmlns:geom="http://playerstage.sourceforge.net/gazebo/xmlschema/#geom" xmlns:interface="http://playerstage.sourceforge.net/gazebo/xmlschema/#interface" xmlns:joint="http://playerstage.sourceforge.net/gazebo/xmlschema/#joint" xmlns:model="http://playerstage.sourceforge.net/gazebo/xmlschema/#model" xmlns:physics="http://playerstage.sourceforge.net/gazebo/xmlschema/#physics" xmlns:renderable="http://playerstage.sourceforge.net/gazebo/xmlschema/#renderable" xmlns:rendering="http://playerstage.sourceforge.net/gazebo/xmlschema/#rendering" xmlns:sensor="http://playerstage.sourceforge.net/gazebo/xmlschema/#sensor" xmlns:xacro="http://ros.org/wiki/xacro" xmlns:xi="http://www.w3.org/2001/XInclude">
  <!-- Wooden arm base -->
  <link name="wooden_arm_base">
    <origin rpy="0 0 0" xyz="-0 0 0"/>
    <inertial>
      <mass value="0.5"/>
      <origin xyz="0 0 0"/>
      <inertia ixx="1" ixy="0" ixz="0" iyy="1" iyz="0" izz="1"/>
    </inertial>
    <visual name="visual">
      <origin rpy="0 0 0" xyz="0 0 0"/>
      <geometry>
        <mesh filename="package://alice_description/models/box.dae" scale="0.17 0.33 0.02"/>
      </geometry>
      <material name="black">
        <color rgba="0 0 0 1.0"/>
      </material>
    </visual>
    <collision>
      <origin rpy="0 0 0" xyz="0 0 0"/>
      <geometry>
        <mesh filename="package://alice_description/models/box.dae" scale="0.17 0.33 0.02"/>
      </geometry>
    </collision>
  </link>
  <!-- Gazebo color plugin for wooden arm base -->
  <gazebo reference="wooden_arm_base">
    <material>Gazebo/Wood</material>
  </gazebo>
  <link name="root">
    <visual>
      <origin rpy="0 0 0" xyz="0 0 0"/>
      <geometry>
        <box size="0 0 0"/>
      </geometry>
    </visual>
    <collision>
      <origin rpy="0 0 0" xyz="0 0 0"/>
      <geometry>
        <box size="0 0 0"/>
      </geometry>
    </collision>
  </link>
  <!-- Connection between bottom box and wooden arm base -->
  <joint name="bottom_box_to_wooden_arm_base" type="fixed">
    <origin rpy=" 0 0 0" xyz="0.205 0.02 0.15"/>
    <child link="wooden_arm_base"/>
    <parent link="root"/>
  </joint>
  <!-- Metal arm base + little metal bar on which arm is attached -->
  <link name="metal_arm_base">
    <origin rpy="0 0 0" xyz="-0 0 0"/>
    <inertial>
      <mass value="2"/>
      <origin xyz="0 0 0"/>
      <inertia ixx="1" ixy="0" ixz="0" iyy="1" iyz="0" izz="1"/>
    </inertial>
    <visual name="visual">
      <origin rpy="0 0 0" xyz="0 0 0"/>
      <geometry>
        <mesh filename="package://alice_description/models/box.dae" scale="0.15 0.2 0.035"/>
      </geometry>
      <material name="black">
        <color rgba="0 0 0 1.0"/>
      </material>
    </visual>
    <collision>
      <origin rpy="0 0 0" xyz="0 0 0"/>
      <geometry>
        <mesh filename="package://alice_description/models/box.dae" scale="0.15 0.2 0.035"/>
      </geometry>
    </collision>
  </link>
  <!-- Gazebo color plugin for metal arm base -->
  <gazebo reference="metal_arm_base">
    <material>Gazebo/Black</material>
  </gazebo>
  <!-- Connection between wooden arm base and metal arm base -->
  <joint name="wooden_arm_base_to_metal_arm_base" type="fixed">
    <origin rpy=" 0 0 0" xyz="0.01 0 0.0275"/>
    <child link="metal_arm_base"/>
    <parent link="wooden_arm_base"/>
  </joint>
  <link name="arm_base">
    <origin rpy="0 0 0" xyz="-0 0 0"/>
    <inertial>
      <mass value="0"/>
      <origin xyz="0 0 0"/>
      <inertia ixx="1" ixy="0" ixz="0" iyy="1" iyz="0" izz="1"/>
    </inertial>
  </link>
  <joint name="metal_arm_base_to_arm_base" type="fixed">
    <origin rpy=" 0 0 1.57" xyz="0 0 0.0775"/>
    <child link="arm_base"/>
    <parent link="metal_arm_base"/>
  </joint>
  <!-- Connection between metal arm base and mico arm -->
  <link name="mico_link_base">
    <visual>
      <geometry>
        <mesh filename="package://mico_description/meshes/mico_link_base.dae"/>
      </geometry>
      <material name="carbon_fiber">
        <color rgba="0.792156862745098 0.819607843137255 0.933333333333333 1"/>
      </material>
    </visual>
    <collision>
      <geometry>
        <mesh filename="package://mico_description/meshes/mico_link_base.dae"/>
      </geometry>
    </collision>
  </link>
  <joint name="mico_joint_base" type="fixed">
    <parent link="arm_base"/>
    <child link="mico_link_base"/>
    <axis xyz="0 0 0"/>
    <origin rpy="0 0 0" xyz="0 0 0"/>
    <limit effort="30" lower="-6.28318530718" upper="6.28318530718" velocity="5"/>
  </joint>
  <link name="mico_link_1">
    <visual>
      <geometry>
        <mesh filename="package://mico_description/meshes/mico_link_1.dae"/>
      </geometry>
      <material name="carbon_fiber">
        <color rgba="0.792156862745098 0.819607843137255 0.933333333333333 1"/>
      </material>
    </visual>
    <collision>
      <geometry>
        <mesh filename="package://mico_description/meshes/mico_link_1.dae"/>
      </geometry>
    </collision>
  </link>
  <joint name="mico_joint_1" type="continuous">
    <parent link="mico_link_base"/>
    <child link="mico_link_1"/>
    <axis xyz="0 0 1"/>
    <origin rpy="3.14159265359 0 0" xyz="0 0 0.1535"/>
    <limit effort="30" lower="-6.28318530718" upper="6.28318530718" velocity="5"/>
  </joint>
  <transmission name="mico_joint_1_transmission">
    <type>transmission_interface/SimpleTransmission</type>
    <joint name="mico_joint_1">
      <hardwareInterface>PositionJointInterface</hardwareInterface>
    </joint>
    <actuator name="mico_joint_1_motor">
      <mechanicalReduction>1</mechanicalReduction>
    </actuator>
  </transmission>
  <link name="mico_link_2">
    <visual>
      <geometry>
        <mesh filename="package://mico_description/meshes/mico_link_2.dae"/>
      </geometry>
      <material name="carbon_fiber">
        <color rgba="0.792156862745098 0.819607843137255 0.933333333333333 1"/>
      </material>
    </visual>
    <collision>
      <geometry>
        <mesh filename="package://mico_description/meshes/mico_link_2.dae"/>
      </geometry>
    </collision>
  </link>
  <joint name="mico_joint_2" type="revolute">
    <parent link="mico_link_1"/>
    <child link="mico_link_2"/>
    <axis xyz="0 0 1"/>
    <origin rpy="-1.57079632679 -1.57079632679 0" xyz="0 0 -0.1185"/>
    <limit effort="30" lower="0" upper="6.28318530718" velocity="5"/>
  </joint>
  <transmission name="mico_joint_2_transmission">
    <type>transmission_interface/SimpleTransmission</type>
    <joint name="mico_joint_2">
      <hardwareInterface>PositionJointInterface</hardwareInterface>
    </joint>
    <actuator name="mico_joint_2_motor">
      <mechanicalReduction>1</mechanicalReduction>
    </actuator>
  </transmission>
  <link name="mico_link_3">
    <visual>
      <geometry>
        <mesh filename="package://mico_description/meshes/mico_link_3.dae"/>
      </geometry>
      <material name="carbon_fiber">
        <color rgba="0.792156862745098 0.819607843137255 0.933333333333333 1"/>
      </material>
    </visual>
    <collision>
      <geometry>
        <mesh filename="package://mico_description/meshes/mico_link_3.dae"/>
      </geometry>
    </collision>
  </link>
  <joint name="mico_joint_3" type="revolute">
    <parent link="mico_link_2"/>
    <child link="mico_link_3"/>
    <axis xyz="0 0 1"/>
    <origin rpy="3.14159265359 0 3.14159265359" xyz="0.29 0 0"/>
    <limit effort="30" lower="0" upper="6.28318530718" velocity="5"/>
  </joint>
  <transmission name="mico_joint_3_transmission">
    <type>transmission_interface/SimpleTransmission</type>
    <joint name="mico_joint_3">
      <hardwareInterface>PositionJointInterface</hardwareInterface>
    </joint>
    <actuator name="mico_joint_3_motor">
      <mechanicalReduction>1</mechanicalReduction>
    </actuator>
  </transmission>
  <link name="mico_link_4">
    <visual>
      <geometry>
        <mesh filename="package://mico_description/meshes/mico_link_4_5.dae"/>
      </geometry>
      <material name="carbon_fiber">
        <color rgba="0.792156862745098 0.819607843137255 0.933333333333333 1"/>
      </material>
    </visual>
    <collision>
      <geometry>
        <mesh filename="package://mico_description/meshes/mico_link_4_5.dae"/>
      </geometry>
    </collision>
  </link>
  <joint name="mico_joint_4" type="continuous">
    <parent link="mico_link_3"/>
    <child link="mico_link_4"/>
    <axis xyz="0 0 1"/>
    <origin rpy="0 -1.57079632679 0" xyz="0.123 0 -0.00845"/>
    <limit effort="30" lower="-6.28318530718" upper="6.28318530718" velocity="5"/>
  </joint>
  <transmission name="mico_joint_4_transmission">
    <type>transmission_interface/SimpleTransmission</type>
    <joint name="mico_joint_4">
      <hardwareInterface>PositionJointInterface</hardwareInterface>
    </joint>
    <actuator name="mico_joint_4_motor">
      <mechanicalReduction>1</mechanicalReduction>
    </actuator>
  </transmission>
  <link name="mico_link_5">
    <visual>
      <geometry>
        <mesh filename="package://mico_description/meshes/mico_link_4_5.dae"/>
      </geometry>
      <material name="carbon_fiber">
        <color rgba="0.792156862745098 0.819607843137255 0.933333333333333 1"/>
      </material>
    </visual>
    <collision>
      <geometry>
        <mesh filename="package://mico_description/meshes/mico_link_4_5.dae"/>
      </geometry>
    </collision>
  </link>
  <joint name="mico_joint_5" type="continuous">
    <parent link="mico_link_4"/>
    <child link="mico_link_5"/>
    <axis xyz="0 0 1"/>
    <origin rpy="0 0.959931088597 3.14159265359" xyz="0.0343 0 -0.06588"/>
    <limit effort="30" lower="-6.28318530718" upper="6.28318530718" velocity="5"/>
  </joint>
  <transmission name="mico_joint_5_transmission">
    <type>transmission_interface/SimpleTransmission</type>
    <joint name="mico_joint_5">
      <hardwareInterface>PositionJointInterface</hardwareInterface>
    </joint>
    <actuator name="mico_joint_5_motor">
      <mechanicalReduction>1</mechanicalReduction>
    </actuator>
  </transmission>
  <link name="mico_link_hand">
    <visual>
      <geometry>
        <mesh filename="package://mico_description/meshes/mico_link_hand.dae"/>
      </geometry>
      <material name="carbon_fiber">
        <color rgba="0.792156862745098 0.819607843137255 0.933333333333333 1"/>
      </material>
    </visual>
    <collision>
      <geometry>
        <mesh filename="package://mico_description/meshes/mico_link_hand.dae"/>
      </geometry>
    </collision>
  </link>
  <joint name="mico_joint_6" type="continuous">
    <parent link="mico_link_5"/>
    <child link="mico_link_hand"/>
    <axis xyz="0 0 1"/>
    <origin rpy="0 0.959931088597 3.14159265359" xyz="0.0343 0 -0.06588"/>
    <limit effort="30" lower="-6.28318530718" upper="6.28318530718" velocity="5"/>
  </joint>
  <transmission name="mico_joint_6_transmission">
    <type>transmission_interface/SimpleTransmission</type>
    <joint name="mico_joint_6">
      <hardwareInterface>PositionJointInterface</hardwareInterface>
    </joint>
    <actuator name="mico_joint_6_motor">
      <mechanicalReduction>1</mechanicalReduction>
    </actuator>
  </transmission>
  <link name="mico_large_ring_cover_1">
    <visual>
      <geometry>
        <mesh filename="package://mico_description/meshes/mico_large_ring_cover.dae" scale="0.0254 0.0254 0.0254"/>
      </geometry>
      <material name="carbon_fiber">
        <color rgba="0.792156862745098 0.819607843137255 0.933333333333333 1"/>
      </material>
    </visual>
    <collision>
      <geometry>
        <mesh filename="package://mico_description/meshes/mico_large_ring_cover.dae" scale="0.0254 0.0254 0.0254"/>
      </geometry>
    </collision>
  </link>
  <joint name="mico_large_ring_cover_1_joint" type="fixed">
    <parent link="mico_link_base"/>
    <child link="mico_large_ring_cover_1"/>
    <axis xyz="0 0 1"/>
    <origin rpy="3.14159265359 0 0" xyz="0 0 0.1535"/>
    <limit effort="30" lower="-6.28318530718" upper="6.28318530718" velocity="5"/>
  </joint>
  <link name="mico_large_ring_cover_2">
    <visual>
      <geometry>
        <mesh filename="package://mico_description/meshes/mico_large_ring_cover.dae" scale="0.0254 0.0254 0.0254"/>
      </geometry>
      <material name="carbon_fiber">
        <color rgba="0.792156862745098 0.819607843137255 0.933333333333333 1"/>
      </material>
    </visual>
    <collision>
      <geometry>
        <mesh filename="package://mico_description/meshes/mico_large_ring_cover.dae" scale="0.0254 0.0254 0.0254"/>
      </geometry>
    </collision>
  </link>
  <joint name="mico_large_ring_cover_2_joint" type="fixed">
    <parent link="mico_link_1"/>
    <child link="mico_large_ring_cover_2"/>
    <axis xyz="0 0 1"/>
    <origin rpy="-1.57079632679 -1.57079632679 0" xyz="0 0 -0.1185"/>
    <limit effort="30" lower="0" upper="6.28318530718" velocity="5"/>
  </joint>
  <link name="mico_large_ring_cover_3">
    <visual>
      <geometry>
        <mesh filename="package://mico_description/meshes/mico_large_ring_cover.dae" scale="0.0254 0.0254 0.0254"/>
      </geometry>
      <material name="carbon_fiber">
        <color rgba="0.792156862745098 0.819607843137255 0.933333333333333 1"/>
      </material>
    </visual>
    <collision>
      <geometry>
        <mesh filename="package://mico_description/meshes/mico_large_ring_cover.dae" scale="0.0254 0.0254 0.0254"/>
      </geometry>
    </collision>
  </link>
  <joint name="mico_large_ring_cover_3_joint" type="fixed">
    <parent link="mico_link_2"/>
    <child link="mico_large_ring_cover_3"/>
    <axis xyz="0 0 1"/>
    <origin rpy="3.14159265359 0 3.14159265359" xyz="0.29 0 0"/>
    <limit effort="30" lower="0" upper="6.28318530718" velocity="5"/>
  </joint>
  <link name="mico_small_ring_cover_1">
    <visual>
      <geometry>
        <mesh filename="package://mico_description/meshes/mico_small_ring_cover.dae" scale="0.0254 0.0254 0.0254"/>
      </geometry>
      <material name="carbon_fiber">
        <color rgba="0.792156862745098 0.819607843137255 0.933333333333333 1"/>
      </material>
    </visual>
    <collision>
      <geometry>
        <mesh filename="package://mico_description/meshes/mico_small_ring_cover.dae" scale="0.0254 0.0254 0.0254"/>
      </geometry>
    </collision>
  </link>
  <joint name="mico_large_ring_cover_4_joint" type="fixed">
    <parent link="mico_link_3"/>
    <child link="mico_small_ring_cover_1"/>
    <axis xyz="0 0 1"/>
    <origin rpy="0 -1.57079632679 0" xyz="0.123 0 -0.00845"/>
    <limit effort="30" lower="-6.28318530718" upper="6.28318530718" velocity="5"/>
  </joint>
  <link name="mico_small_ring_cover_2">
    <visual>
      <geometry>
        <mesh filename="package://mico_description/meshes/mico_small_ring_cover.dae" scale="0.0254 0.0254 0.0254"/>
      </geometry>
      <material name="carbon_fiber">
        <color rgba="0.792156862745098 0.819607843137255 0.933333333333333 1"/>
      </material>
    </visual>
    <collision>
      <geometry>
        <mesh filename="package://mico_description/meshes/mico_small_ring_cover.dae" scale="0.0254 0.0254 0.0254"/>
      </geometry>
    </collision>
  </link>
  <joint name="mico_large_ring_cover_5_joint" type="fixed">
    <parent link="mico_link_4"/>
    <child link="mico_small_ring_cover_2"/>
    <axis xyz="0 0 1"/>
    <origin rpy="0 0.959931088597 3.14159265359" xyz="0.0343 0 -0.06588"/>
    <limit effort="30" lower="-6.28318530718" upper="6.28318530718" velocity="5"/>
  </joint>
  <link name="mico_small_ring_cover_3">
    <visual>
      <geometry>
        <mesh filename="package://mico_description/meshes/mico_small_ring_cover.dae" scale="0.0254 0.0254 0.0254"/>
      </geometry>
      <material name="carbon_fiber">
        <color rgba="0.792156862745098 0.819607843137255 0.933333333333333 1"/>
      </material>
    </visual>
    <collision>
      <geometry>
        <mesh filename="package://mico_description/meshes/mico_small_ring_cover.dae" scale="0.0254 0.0254 0.0254"/>
      </geometry>
    </collision>
  </link>
  <joint name="mico_large_ring_cover_6_joint" type="fixed">
    <parent link="mico_link_5"/>
    <child link="mico_small_ring_cover_3"/>
    <axis xyz="0 0 1"/>
    <origin rpy="0 0.959931088597 3.14159265359" xyz="0.0343 0 -0.06588"/>
    <limit effort="30" lower="-6.28318530718" upper="6.28318530718" velocity="5"/>
  </joint>
  <link name="mico_link_finger_1">
    <visual>
      <geometry>
        <mesh filename="package://mico_description/meshes/mico_link_finger.dae" scale="0.0254 0.0254 0.0254"/>
      </geometry>
      <material name="carbon_fiber">
        <color rgba="0.792156862745098 0.819607843137255 0.933333333333333 1"/>
      </material>
    </visual>
    <collision>
      <geometry>
        <mesh filename="package://mico_description/meshes/mico_link_finger.dae" scale="0.0254 0.0254 0.0254"/>
      </geometry>
    </collision>
  </link>
  <joint name="mico_joint_finger_1" type="revolute">
    <parent link="mico_link_hand"/>
    <child link="mico_link_finger_1"/>
    <axis xyz="0 0 1"/>
    <origin rpy="-1.5707 1.1 3.1416" xyz="-0.03978 0 -0.10071"/>
    <limit effort="30" lower="0" upper="0.698131700798" velocity="5"/>
  </joint>
  <transmission name="mico_joint_finger_1_transmission">
    <type>transmission_interface/SimpleTransmission</type>
    <joint name="mico_joint_finger_1">
      <hardwareInterface>PositionJointInterface</hardwareInterface>
    </joint>
    <actuator name="mico_joint_finger_1_motor">
      <mechanicalReduction>1</mechanicalReduction>
    </actuator>
  </transmission>
  <link name="mico_link_finger_2">
    <visual>
      <geometry>
        <mesh filename="package://mico_description/meshes/mico_link_finger.dae" scale="0.0254 0.0254 0.0254"/>
      </geometry>
      <material name="carbon_fiber">
        <color rgba="0.792156862745098 0.819607843137255 0.933333333333333 1"/>
      </material>
    </visual>
    <collision>
      <geometry>
        <mesh filename="package://mico_description/meshes/mico_link_finger.dae" scale="0.0254 0.0254 0.0254"/>
      </geometry>
    </collision>
  </link>
  <joint name="mico_joint_finger_2" type="revolute">
    <parent link="mico_link_hand"/>
    <child link="mico_link_finger_2"/>
    <axis xyz="0 0 1"/>
    <origin rpy="-1.5707 1.1 0.0" xyz="0.03978 0 -0.10071"/>
    <limit effort="30" lower="0" upper="0.698131700798" velocity="5"/>
  </joint>
  <transmission name="mico_joint_finger_2_transmission">
    <type>transmission_interface/SimpleTransmission</type>
    <joint name="mico_joint_finger_2">
      <hardwareInterface>PositionJointInterface</hardwareInterface>
    </joint>
    <actuator name="mico_joint_finger_2_motor">
      <mechanicalReduction>1</mechanicalReduction>
    </actuator>
  </transmission>
  <link name="mico_link_finger_tip_1">
    <visual>
      <geometry>
        <mesh filename="package://mico_description/meshes/mico_link_finger_tip.dae" scale="0.0254 0.0254 0.0254"/>
      </geometry>
      <material name="carbon_fiber">
        <color rgba="0.792156862745098 0.819607843137255 0.933333333333333 1"/>
      </material>
    </visual>
    <collision>
      <geometry>
        <mesh filename="package://mico_description/meshes/mico_link_finger_tip.dae" scale="0.0254 0.0254 0.0254"/>
      </geometry>
    </collision>
  </link>
  <joint name="mico_joint_finger_tip_1" type="fixed">
    <parent link="mico_link_finger_1"/>
    <child link="mico_link_finger_tip_1"/>
    <axis xyz="0 0 1"/>
    <origin rpy="0 0 0" xyz="0.044094 -0.0029 0"/>
    <limit effort="30" lower="0" upper="0.698131700798" velocity="5"/>
  </joint>
  <transmission name="mico_joint_finger_tip_1_transmission">
    <type>transmission_interface/SimpleTransmission</type>
    <joint name="mico_joint_finger_tip_1">
      <hardwareInterface>PositionJointInterface</hardwareInterface>
    </joint>
    <actuator name="mico_joint_finger_tip_1_motor">
      <mechanicalReduction>1</mechanicalReduction>
    </actuator>
  </transmission>
  <link name="mico_link_finger_tip_2">
    <visual>
      <geometry>
        <mesh filename="package://mico_description/meshes/mico_link_finger_tip.dae" scale="0.0254 0.0254 0.0254"/>
      </geometry>
      <material name="carbon_fiber">
        <color rgba="0.792156862745098 0.819607843137255 0.933333333333333 1"/>
      </material>
    </visual>
    <collision>
      <geometry>
        <mesh filename="package://mico_description/meshes/mico_link_finger_tip.dae" scale="0.0254 0.0254 0.0254"/>
      </geometry>
    </collision>
  </link>
  <joint name="mico_joint_finger_tip_2" type="fixed">
    <parent link="mico_link_finger_2"/>
    <child link="mico_link_finger_tip_2"/>
    <axis xyz="0 0 1"/>
    <origin rpy="0 0 0" xyz="0.044094 -0.0029 0"/>
    <limit effort="30" lower="0" upper="0.698131700798" velocity="5"/>
  </joint>
  <transmission name="mico_joint_finger_tip_2_transmission">
    <type>transmission_interface/SimpleTransmission</type>
    <joint name="mico_joint_finger_tip_2">
      <hardwareInterface>PositionJointInterface</hardwareInterface>
    </joint>
    <actuator name="mico_joint_finger_tip_2_motor">
      <mechanicalReduction>1</mechanicalReduction>
    </actuator>
  </transmission>
  <gazebo>
    <gripper name="grasping">
      <grasp_check>
        <attach_steps>5</attach_steps>
        <detach_steps>5</detach_steps>
        <min_contact_count>1</min_contact_count>
      </grasp_check>
      <gripper_link>mico_link_finger_1</gripper_link>
      <gripper_link>mico_link_finger_2</gripper_link>
      <gripper_link>mico_link_finger_tip_1</gripper_link>
      <gripper_link>mico_link_finger_tip_2</gripper_link>
      <palm_link>mico_link_hand</palm_link>
      <!--<gripper_link>${link_hand}</gripper_link> -->
      <!-- <palm_link>${link_finger_tip}_1</palm_link> -->
    </gripper>
  </gazebo>
  <gazebo>
    <plugin filename="libgazebo_ros_control.so" name="gazebo_ros_control">
      <robotNamespace>alice</robotNamespace>
    </plugin>
  </gazebo>
</robot>

