<?xml version="1.0"?>
<robot 
    xmlns:sensor="http://playerstage.sourceforge.net/gazebo/xmlschema/#sensor"
    xmlns:controller="http://playerstage.sourceforge.net/gazebo/xmlschema/#controller"
    xmlns:interface="http://playerstage.sourceforge.net/gazebo/xmlschema/#interface"
    xmlns:xacro="http://ros.org/wiki/xacro">

    <property name="base_length" value="0.27"/>
    <property name="base_radius" value="0.05"/>
    <property name="shoulder_radius" value="0.05"/>
    <property name="upper_arm_length" value="0.29"/>
    <property name="upper_arm_radius" value="0.025"/>
    <property name="elbow_radius" value="0.05"/>
    <property name="lower_arm_length" value="0.1233"/>
    <property name="lower_arm_radius" value="0.015"/>
    <property name="wrist_length" value="0.10"/>
    <property name="wrist_radius" value="0.025"/>
    <property name="M_PI" value="3.1415926535897931"/>


<!-- 2012.08.29 - fnh: updated for Gazebo, added *origin parameter -->

    <property name="DEG2RAD" value="0.017453292" />


    <!-- From Kinova Model -->

    <property name="D1" value="0.2102" /> <!--0.27 -->
    <property name="D2" value="0.2900" />
    <property name="D3" value="0.1233" />
    <property name="D4" value="0.0750" />
    <property name="D5" value="0.0750" />
    <property name="D6" value="0.1850" />

    <property name="aa" value="0.47996554429844057" />
    <property name="ca" value="0.88701083317822171" />
    <property name="sa" value="0.46174861323503386" />
    <property name="c2a" value="0.57357643635104627" />
    <property name="s2a" value="0.81915204428899169" />
    <property name="d3b" value="0.012" />
    <property name="d4b" value="0.16557" /> <!-- 0.24927... - 0.207 + 0.1233 -->
    <property name="d5b" value="0.08455364601497567" />
    <property name="d6b" value="0.22727682300748783" />
    <property name="uls" value="0.000001" />
    <property name="uls2" value="0.004" />

    <material name="JacoGrey">
        <color rgba="0.2 0.2 0.9 1.0"/>
    </material>



    <xacro:macro name="mico_arm_v0" params="name parent *origin">

      <!-- The base joint & link -->
      <joint name="${name}_base_joint" type="fixed">
        <insert_block name="origin" />
        <!-- fnh was: <origin xyz="0 0 0" rpy="0 0 0"/> -->
        <parent link="${parent}"/>
        <child link="${name}_base_link"/>
      </joint>

      <link name="${name}_base_link">
        <inertial> <!-- fnh -->
          <origin xyz="0 0 0" />
          <mass value="1.0" />
          <inertia  ixx="1" ixy="0" ixz="0" iyy="1" iyz="0" izz="1" />
        </inertial>
        <visual>
        <material name="JacoGrey" />
          <origin xyz="0 0 0" rpy="0 0 ${M_PI/2}"/>
          <geometry>
            <mesh filename="package://jaco_model/meshes/jaco_base_joint.dae"/>
          </geometry>
        </visual>
        <collision>
          <origin xyz="0 0 0" rpy="0 0 ${M_PI/2}"/>
          <geometry>
            <mesh filename="package://jaco_model/meshes/jaco_base_joint.dae"/>
          </geometry>
        </collision>
      </link>
      <gazebo reference="${name}_base_link"> <!-- fnh -->
        <material>Gazebo/Grey</material>
        <turnGravityOff>false</turnGravityOff>
        <selfCollide>true</selfCollide>
        <mu1>100.0</mu1>
        <mu2>100.0</mu2>
        <kp>1000000.0</kp>
        <kd>1.0</kd>
      </gazebo>

     <!-- First revolute joint & link -->

     <joint name="${name}_shoulder_yaw_joint" type="revolute">
        <!--<origin xyz="0 0 ${D1}" rpy="0 0 0"/>-->
	<origin xyz="0 0 ${D1+uls2}" rpy="0 0 0"/>
        <axis xyz="0 0 1" rpy="0 0 0"/>
        <parent link="${name}_base_link"/>
        <child link="${name}_shoulder_link"/>
        <limit lower="${-M_PI+0.1}" upper="${M_PI-0.1}" effort="200" velocity="${48*DEG2RAD}"/>
        <dynamics damping="50.5"/>
      </joint>
      <transmission name="${name}_shoulder_yaw_joint_transmission">
	<type>transmission_interface/SimpleTransmission</type>
        <actuator name="${name}_shoulder_yaw_joint_motor" >
          <hardwareInterface>EffortJointInterface</hardwareInterface>
          <mechanicalReduction>50</mechanicalReduction>
        </actuator>
        <joint    name="${name}_shoulder_yaw_joint" />
        <mechanicalReduction>50</mechanicalReduction>
        <motorTorqueConstant>1</motorTorqueConstant>
        <pulsesPerRevolution>10000</pulsesPerRevolution>
      </transmission>

      <link name="${name}_shoulder_link">
        <inertial> <!-- fnh -->
          <origin xyz="0 0 0" />
          <mass value="1.0" />
          <inertia  ixx="1" ixy="0" ixz="0" iyy="1" iyz="0" izz="1" />
        </inertial>
        <visual>
        <material name="JacoGrey" />
          <origin xyz="0 0 0" rpy="${M_PI/2} ${-M_PI/2} 0"/>
          <geometry>
            <mesh filename="package://jaco_model/meshes/jaco_shoulder_yaw_joint.dae"/>
          </geometry>
        </visual>
        <collision>
          <origin xyz="0 0 0" rpy="${M_PI/2} ${-M_PI/2} 0"/>
          <geometry>
            <mesh filename="package://jaco_model/meshes/jaco_shoulder_yaw_joint.dae"/>
          </geometry>
        </collision>
      </link>
      <gazebo reference="${name}_shoulder_link"> <!-- fnh -->
        <material>Gazebo/Grey</material>
        <turnGravityOff>false</turnGravityOff>
        <selfCollide>true</selfCollide>
        <mu1>100.0</mu1>
        <mu2>100.0</mu2>
        <kp>1000000.0</kp>
        <kd>1.0</kd>
      </gazebo>

     <!-- Second revolute joint & link -->

     <joint name="${name}_shoulder_pitch_joint" type="revolute">
        <origin xyz="0 ${0-uls} 0" rpy="${-M_PI/2} 0 0"/>
        <axis xyz="0 0 1"/>
        <parent link="${name}_shoulder_link"/>
        <child link="${name}_upper_arm_link"/>
        <limit lower="${-220*DEG2RAD}" upper="${40*DEG2RAD}" effort="300" velocity="${48*DEG2RAD}"/>
        <dynamics damping="50.5"/>
      </joint>
      <transmission name="${name}_shoulder_pitch_joint_transmission">
	<type>transmission_interface/SimpleTransmission</type>
        <actuator name="${name}_shoulder_pitch_joint_motor">
          <hardwareInterface>EffortJointInterface</hardwareInterface>
          <mechanicalReduction>50</mechanicalReduction>
	</actuator>
        <joint    name="${name}_shoulder_pitch_joint" />
        <mechanicalReduction>50</mechanicalReduction>
        <motorTorqueConstant>1</motorTorqueConstant>
        <pulsesPerRevolution>10000</pulsesPerRevolution>
      </transmission>

      <link name="${name}_upper_arm_link">
        <inertial> <!-- fnh -->
          <origin xyz="0 0 0" />
          <mass value="1.0" />
          <inertia  ixx="1" ixy="0" ixz="0" iyy="1" iyz="0" izz="1" />
        </inertial>
        <visual>
        <material name="JacoGrey" />
          <origin xyz="0 0 0" rpy="0 0 ${-M_PI/2}"/>
          <geometry>
            <mesh filename="package://jaco_model/meshes/jaco_shoulder_pitch_joint.dae" scale="1 ${0.29/0.41} 1"/>
          </geometry>
        </visual>
        <collision>
          <origin xyz="0 0 0" rpy="0 0 ${-M_PI/2}"/>
          <geometry>
            <mesh filename="package://jaco_model/meshes/jaco_shoulder_pitch_joint.dae" scale="1 ${0.29/0.41} 1"/>
          </geometry>
        </collision>
      </link>
      <gazebo reference="${name}_upper_arm_link"> <!-- fnh -->
        <material>Gazebo/Grey</material>
        <turnGravityOff>false</turnGravityOff>
        <selfCollide>true</selfCollide>
        <mu1>100.0</mu1>
        <mu2>100.0</mu2>
        <kp>1000000.0</kp>
        <kd>1.0</kd>
      </gazebo>

      <!-- Third revolute joint & link -->

      <joint name="${name}_elbow_pitch_joint" type="revolute">
        <origin xyz="${D2} 0 ${d3b+uls}" rpy="0 0 0"/>
        <axis xyz="0 0 1"/>
        <parent link="${name}_upper_arm_link"/>
        <child link="${name}_lower_arm_link"/>
        <limit lower="${-250*DEG2RAD}" upper="${70*DEG2RAD}" effort="200" velocity="${48*DEG2RAD}"/>
        <dynamics damping="50.5"/>
      </joint>
      <transmission name="${name}_elbow_pitch_joint_transmission">
	<type>transmission_interface/SimpleTransmission</type>
        <actuator name="${name}_elbow_pitch_joint_motor" >
          <hardwareInterface>EffortJointInterface</hardwareInterface>
          <mechanicalReduction>50</mechanicalReduction>
	</actuator>
        <joint    name="${name}_elbow_pitch_joint" />
        <mechanicalReduction>50</mechanicalReduction>
        <motorTorqueConstant>1</motorTorqueConstant>
        <pulsesPerRevolution>10000</pulsesPerRevolution>
      </transmission>

      <link name="${name}_lower_arm_link">
        <inertial> <!-- fnh -->
          <origin xyz="0 0 0" />
          <mass value="0.8" />
          <inertia  ixx="1" ixy="0" ixz="0" iyy="1" iyz="0" izz="1" />
        </inertial>
        <visual>
        <material name="JacoGrey" />
          <origin xyz="0 0 ${-d3b}" rpy="${M_PI} 0 ${M_PI}"/>
          <geometry>
            <mesh filename="package://jaco_model/meshes/jaco_elbow_pitch_joint.dae" scale="1 ${0.1233/0.205} 1"/>
          </geometry>
        </visual>
        <collision>
          <origin xyz="0 0 ${-d3b}" rpy="${M_PI} 0 ${M_PI}"/>
          <geometry>
            <mesh filename="package://jaco_model/meshes/jaco_elbow_pitch_joint.dae" scale="1 ${0.1233/0.205} 1"/>
          </geometry>
        </collision>
      </link>
      <gazebo reference="${name}_lower_arm_link"> <!-- fnh -->
        <material>Gazebo/Grey</material>
        <turnGravityOff>false</turnGravityOff>
        <selfCollide>true</selfCollide>
        <mu1>100.0</mu1>
        <mu2>100.0</mu2>
        <kp>1000000.0</kp>
        <kd>1.0</kd>
      </gazebo>

      <!-- Fourth revolute joint & link -->

      <joint name="${name}_elbow_roll_joint" type="revolute">
        <origin xyz="0 ${d4b+uls} 0 " rpy="${-M_PI/2} 0 0"/>
        <axis xyz="0 0 1"/>
        <parent link="${name}_lower_arm_link"/>
        <child link="${name}_lower_arm_roll_link"/>
        <limit lower="${-M_PI+0.1}" upper="${M_PI-0.1}" effort="40" velocity="${60*DEG2RAD}"/>
        <dynamics damping="50.5"/>
      </joint>
      <transmission name="${name}_elbow_roll_joint_transmission">
	<type>transmission_interface/SimpleTransmission</type>
        <actuator name="${name}_elbow_roll_joint_motor" >
          <hardwareInterface>EffortJointInterface</hardwareInterface>
          <mechanicalReduction>50</mechanicalReduction>
	</actuator>
        <joint    name="${name}_elbow_roll_joint" />
        <mechanicalReduction>50</mechanicalReduction>
        <motorTorqueConstant>1</motorTorqueConstant>
        <pulsesPerRevolution>10000</pulsesPerRevolution>
      </transmission>

      <link name="${name}_lower_arm_roll_link">
        <inertial> <!-- fnh -->
          <origin xyz="0 0 0" />
          <mass value="0.5" />
          <inertia  ixx="1" ixy="0" ixz="0" iyy="1" iyz="0" izz="1" />
        </inertial>
        <visual>
        <material name="JacoGrey" />
          <origin xyz="0 0 ${-d4b + D3}" rpy="${M_PI} 0 ${M_PI/2}"/>
          <geometry>
            <mesh filename="package://jaco_model/meshes/jaco_elbow_roll_joint.dae"/>
          </geometry>
        </visual>
        <collision>
          <origin xyz="0 0 ${-d4b + D3}" rpy="${M_PI} 0 ${M_PI/2}"/>
          <geometry>
            <mesh filename="package://jaco_model/meshes/jaco_elbow_roll_joint.dae"/>
          </geometry>
        </collision>
      </link>
      <gazebo reference="${name}_lower_arm_roll_link"> <!-- fnh -->
        <material>Gazebo/Grey</material>
        <turnGravityOff>false</turnGravityOff>
        <selfCollide>true</selfCollide>
        <mu1>100.0</mu1>
        <mu2>100.0</mu2>
        <kp>1000000.0</kp>
        <kd>1.0</kd>
      </gazebo>

      <!-- Fifth revolute joint & link -->

      <joint name="${name}_wrist_roll_joint" type="revolute">
        <origin xyz="0 ${-d5b * s2a} ${d5b * c2a}" rpy="${2*aa} 0 0"/>
        <axis xyz="0 0 1"/>
        <parent link="${name}_lower_arm_roll_link"/>
        <child link="${name}_wrist_link"/>
        <limit lower="${-M_PI+0.1}" upper="${M_PI-0.1}" effort="40" velocity="${60*DEG2RAD}"/>
        <dynamics damping="50.5"/>
      </joint>
      <transmission name="${name}_wrist_roll_joint_transmission">
	<type>transmission_interface/SimpleTransmission</type>
        <actuator name="${name}_wrist_roll_joint_motor" >
          <hardwareInterface>EffortJointInterface</hardwareInterface>
          <mechanicalReduction>50</mechanicalReduction>
	</actuator>
        <joint    name="${name}_wrist_roll_joint" />
        <mechanicalReduction>50</mechanicalReduction>
        <motorTorqueConstant>1</motorTorqueConstant>
        <pulsesPerRevolution>10000</pulsesPerRevolution>
      </transmission>

      <link name="${name}_wrist_link">
        <inertial> <!-- fnh -->
          <origin xyz="0 0 0" />
          <mass value="0.5" />
          <inertia  ixx="1" ixy="0" ixz="0" iyy="1" iyz="0" izz="1" />
        </inertial>
        <visual>
        <material name="JacoGrey" />
          <origin xyz="0 0 ${-d5b/2}" rpy="0 ${M_PI} ${-M_PI/2}"/>
          <geometry>
            <mesh filename="package://jaco_model/meshes/jaco_wrist_roll_joint.dae"/>
          </geometry>
        </visual>
        <collision>
          <origin xyz="0 0 ${-d5b/2}" rpy="0 ${M_PI} ${-M_PI/2}"/>
          <geometry>
            <mesh filename="package://jaco_model/meshes/jaco_wrist_roll_joint.dae"/>
          </geometry>
        </collision>
      </link>
      <gazebo reference="${name}_wrist_link"> <!-- fnh -->
        <material>Gazebo/Grey</material>
        <turnGravityOff>false</turnGravityOff>
        <selfCollide>true</selfCollide>
        <mu1>100.0</mu1>
        <mu2>100.0</mu2>
        <kp>1000000.0</kp>
        <kd>1.0</kd>
      </gazebo>

      <!-- Sixth revolute joint & link -->
      <joint name="${name}_hand_roll_joint" type="revolute">
        <origin xyz="0 ${-d6b * s2a} ${d6b * c2a}" rpy="${2*aa} 0 0"/>
        <axis xyz="0 0 1"/>
        <parent link="${name}_wrist_link"/>
        <child link="${name}_hand_link"/>
        <limit lower="${-M_PI/2.0-0.1}" upper="${M_PI*1.441}" effort="40" velocity="${60*DEG2RAD}"/>
        <dynamics damping="50.5"/>
      </joint>
      <transmission name="${name}_hand_roll_joint_transmission">
	<type>transmission_interface/SimpleTransmission</type>
        <actuator name="${name}_hand_roll_joint_motor" >
	  <hardwareInterface>EffortJointInterface</hardwareInterface>
          <mechanicalReduction>50</mechanicalReduction>
	</actuator>
        <joint    name="${name}_hand_roll_joint" />
        <mechanicalReduction>50</mechanicalReduction>
        <motorTorqueConstant>1</motorTorqueConstant>
        <pulsesPerRevolution>10000</pulsesPerRevolution>
      </transmission>

      <link name="${name}_hand_link">
        <inertial> <!-- fnh -->
          <origin xyz="0 0 0" />
          <mass value="0.6" />
          <inertia  ixx="1" ixy="0" ixz="0" iyy="1" iyz="0" izz="1" />
        </inertial>
        <visual>
          <material name="JacoGrey" />
          <origin xyz="0 0 ${-D6}" rpy="0 0 ${-M_PI}"/>
          <geometry>
            <mesh filename="package://jaco_model/meshes/jaco_hand_roll_joint.dae"/>
          </geometry>
        </visual>
        <collision>
          <origin xyz="0 0 ${-D6}" rpy="0 0 ${-M_PI}"/>
          <geometry>
            <!--<mesh filename="package://jaco_model/meshes/jaco_hand_roll_joint.stl" scale="0.9 0.9 0.7" />  fnh -->
            <mesh filename="package://jaco_model/meshes/jaco_hand_roll_joint.dae"/>
          </geometry>
        </collision>
      </link>
      <gazebo reference="${name}_hand_link"> <!-- fnh -->
        <material>Gazebo/Grey</material>
        <turnGravityOff>false</turnGravityOff>
        <selfCollide>true</selfCollide>
        <mu1>100.0</mu1>
        <mu2>100.0</mu2>
        <kp>1000000.0</kp>
        <kd>1.0</kd>
      </gazebo>
 
      <!-- First finger (Approximative placing) -->

      <joint name="${name}_finger_1_joint" type="revolute">
        <!-- <origin xyz="-0.036 0.021 ${-0.07}" rpy="0 ${-M_PI/7} 0"/> -->
        <origin xyz="-0.036 0.021 ${-0.07}" rpy="0 ${-M_PI/7} 0"/>
        <axis xyz="0 1 0"/>
        <parent link="${name}_hand_link"/>
        <child link="${name}_finger_1_link"/>
        <limit lower="-0.1" upper="${60*DEG2RAD}"  effort="10" velocity="1.0"/>
        <dynamics damping="50.5"/>
      </joint>
      <transmission name="${name}_finger_1_joint_transmission">
	<type>transmission_interfacmico_arm_v0e/SimpleTransmission</type>
        <actuator name="${name}_finger_1_joint_motor" >
	  <hardwareInterface>EffortJointInterface</hardwareInterface>
          <mechanicalReduction>50</mechanicalReduction>
	</actuator>
        <joint    name="${name}_finger_1_joint" />
        <mechanicalReduction>50</mechanicalReduction>
        <motorTorqueConstant>1</motorTorqueConstant>
        <pulsesPerRevolution>10000</pulsesPerRevolution>
      </transmission>

      <link name="${name}_finger_1_link">
        <inertial> <!-- fnh -->
          <origin xyz="0 0 0" />
          <mass value="0.1" />
          <inertia  ixx="1" ixy="0" ixz="0" iyy="1" iyz="0" izz="1" />
        </inertial>
        <visual>
          <material name="JacoGrey" />
          <origin xyz="0 0 0" rpy="0 0 0"/>
              <geometry>
            <mesh filename="package://jaco_model/meshes/finger_new.dae"/>
          </geometry>
        </visual>
        <collision>
          <origin xyz="0 0 0" rpy="0 0 0"/>
              <geometry>
            <mesh filename="package://jaco_model/meshes/finger_new.dae"/>
          </geometry>
        </collision>
      </link>
      <gazebo reference="${name}_finger_1_link"> <!-- fnh -->
        <material>Gazebo/Grey</material>
        <turnGravityOff>false</turnGravityOff>
        <selfCollide>true</selfCollide>
        <mu1>100.0</mu1>
        <mu2>100.0</mu2>
        <kp>1000000.0</kp>
        <kd>1.0</kd>
      </gazebo>
      
      <!-- Second finger (Approximative placing) -->

      <joint name="${name}_finger_2_joint" type="revolute">
        <origin xyz="0.036 -0 ${-0.07}" rpy="0 ${-M_PI/7} ${-M_PI}"/>
        <axis xyz="0 1 0"/>
        <parent link="${name}_hand_link"/>
        <child link="${name}_finger_2_link"/>
        <limit lower="-0.1" upper="${60*DEG2RAD}"  effort="10" velocity="1.0"/>
        <dynamics damping="50.5"/>
      </joint>
      <transmission name="${name}_finger_2_joint_transmission">
	<type>transmission_interface/SimpleTransmission</type>
        <actuator name="${name}_finger_2_joint_motor" >
	  <hardwareInterface>EffortJointInterface</hardwareInterface>
          <mechanicalReduction>50</mechanicalReduction>
	</actuator>
        <joint    name="${name}_finger_2_joint" />
        <mechanicalReduction>50</mechanicalReduction>
        <motorTorqueConstant>1</motorTorqueConstant>
        <pulsesPerRevolution>10000</pulsesPerRevolution>
      </transmission>

      <link name="${name}_finger_2_link">
        <inertial> <!-- fnh -->
          <origin xyz="0 0 0" />
          <mass value="0.1" />
          <inertia  ixx="1" ixy="0" ixz="0" iyy="1" iyz="0" izz="1" />
        </inertial>
        <visual>
        <material name="JacoGrey" />
          <origin xyz="0 0 0" rpy="0 0 0"/>
          <geometry>
            <mesh filename="package://jaco_model/meshes/finger_new.dae"/>
          </geometry>
        </visual>
        <collision>
          <origin xyz="0 0 0" rpy="0 0 0"/>
          <geometry>
            <mesh filename="package://jaco_model/meshes/finger_new.dae"/>
          </geometry>
        </collision>
      </link>      
      <gazebo reference="${name}_finger_2_link"> <!-- fnh -->
        <material>Gazebo/Grey</material>
        <turnGravityOff>false</turnGravityOff>
        <selfCollide>true</selfCollide>
        <mu1>100.0</mu1>
        <mu2>100.0</mu2>
        <kp>1000000.0</kp>
        <kd>1.0</kd>
      </gazebo>
  
      <!-- Third finger (Approximative placing) -->

      <joint name="${name}_finger_3_joint" type="revolute">
        <origin xyz="-0.036 -0.021 ${-0.07}" rpy="0 ${-M_PI/7} 0"/>
        <axis xyz="0 1 0"/>
        <parent link="${name}_hand_link"/>
        <child link="${name}_finger_3_link"/>
        <limit lower="-0.1" upper="${60*DEG2RAD}"  effort="10" velocity="1.0"/>
        <dynamics damping="50.5"/>
      </joint>
      <transmission name="${name}_finger_3_joint_transmission">
	<type>transmission_interface/SimpleTransmission</type>
        <actuator name="${name}_finger_3_joint_motor" >
	  <hardwareInterface>EffortJointInterface</hardwareInterface>
          <mechanicalReduction>50</mechanicalReduction>
	</actuator>
        <joint    name="${name}_finger_3_joint" />
        <mechanicalReduction>50</mechanicalReduction>
        <motorTorqueConstant>1</motorTorqueConstant>
        <pulsesPerRevolution>10000</pulsesPerRevolution>
      </transmission>

      <link name="${name}_finger_3_link">
        <inertial> <!-- fnh -->
          <origin xyz="0 0 0" />
          <mass value="0.1" />
          <inertia  ixx="1" ixy="0" ixz="0" iyy="1" iyz="0" izz="1" />
        </inertial>
        <visual>
        <material name="JacoGrey" />
          <origin xyz="0 0 0" rpy="0 0 0"/>
          <geometry>
            <mesh filename="package://jaco_model/meshes/finger_new.dae"/>
          </geometry>
        </visual>
        <collision>
          <origin xyz="0 0 0" rpy="0 0 0"/>
          <geometry>
            <mesh filename="package://jaco_model/meshes/finger_new.dae"/>
          </geometry>
        </collision>
      </link>
      <gazebo reference="${name}_finger_3_link"> <!-- fnh -->
        <material>Gazebo/Grey</material>
        <turnGravityOff>false</turnGravityOff>
        <selfCollide>true</selfCollide>
        <mu1>100.0</mu1>
        <mu2>100.0</mu2>
        <kp>1000000.0</kp>
        <kd>1.0</kd>
      </gazebo>

    </xacro:macro>
</robot>
