<?xml version="1.0" ?>
<!-- =================================================================================== -->
<!-- |    This document was autogenerated by xacro from complete_model.urdf.xacro      | -->
<!-- |    EDITING THIS FILE BY HAND IS NOT RECOMMENDED                                 | -->
<!-- =================================================================================== -->
<robot name="sudo" xmlns:controller="http://playerstage.sourceforge.net/gazebo/xmlschema/#controller" xmlns:interface="http://playerstage.sourceforge.net/gazebo/xmlschema/#interface" xmlns:sensor="http://playerstage.sourceforge.net/gazebo/xmlschema/#sensor" xmlns:xacro="http://ros.org/wiki/xacro">
  <!-- Robot base: base_link, chassis (pioneer) and left and right wheel -->
  <link name="base_link">
    <origin rpy="0 0 0" xyz="0 0 0.0"/>
  </link>
  <link name="chassis">
    <inertial>
      <mass value="40"/>
      <!--<origin xyz="-0.05 0 0"/>-->
      <origin xyz="-0.05 0 0"/>
      <inertia ixx="1" ixy="0" ixz="0" iyy="1" iyz="0" izz="1"/>
    </inertial>
    <origin rpy="0 0 0" xyz="0 0 0"/>
    <visual name="visual">
      <origin rpy="0 0 0" xyz="0 0 0.055"/>
      <!-- Pioneer stands 5.5 cm above the ground -->
      <geometry>
        <mesh filename="package://sudo_description/models/pioneer2dx/meshes/chassis.dae"/>
      </geometry>
    </visual>
    <collision>
      <origin rpy="0 0 0" xyz="0 0 0.055"/>
      <geometry>
        <mesh filename="package://sudo_description/models/pioneer2dx/meshes/chassis.dae"/>
      </geometry>
    </collision>
  </link>
  <joint name="base_link_to_chassis" type="fixed">
    <origin rpy="0 0 0" xyz="0 0 0.135"/>
    <!-- The pioneer is 16cm high -->
    <child link="chassis"/>
    <parent link="base_link"/>
  </joint>
  <link name="right_wheel">
    <origin rpy="0 0 0" xyz="0 0 0"/>
    <inertial>
      <mass value="0.5"/>
      <origin xyz="0 0 0"/>
      <inertia ixx="0.012411765597" ixy="0" ixz="0" iyy="0.015218160428" iyz="0" izz="0.011763977943"/>
    </inertial>
    <visual name="visual">
      <origin rpy="0 0 0" xyz="0 0 0"/>
      <geometry>
        <cylinder length="0.05" radius="0.08"/>
        <!-- A single wheel has a diameter of 16 cm -->
      </geometry>
      <material name="black">
        <color rgba="0 0 0 1.0"/>
      </material>
    </visual>
    <collision>
      <origin rpy="0 0 0" xyz="0 0 0"/>
      <geometry>
        <cylinder length="0.05" radius="0.08"/>
      </geometry>
    </collision>
  </link>
  <joint name="right_wheel_hinge" type="continuous">
    <origin rpy="-1.5707 0 0" xyz="0.1 -0.17 -0.055"/>
    <child link="right_wheel"/>
    <parent link="chassis"/>
    <axis xyz=" 0 0 1"/>
    <limit effort="100" velocity="100"/>
    <joint_properties damping="0.0" friction="0.0"/>
  </joint>
  <gazebo reference="right_wheel">
    <material>Gazebo/Black</material>
    <turnGravityOff>false</turnGravityOff>
    <selfCollide>true</selfCollide>
    <mu1>100.0</mu1>
    <mu2>100.0</mu2>
    <kp>1000000.0</kp>
    <kd>1.0</kd>
  </gazebo>
  <transmission name="right_wheel_transmission">
    <type>transmission_interface/SimpleTransmission</type>
    <actuator name="right_wheel_motor">
      <hardwareInterface>EffortJointInterface</hardwareInterface>
      <mechanicalReduction>50</mechanicalReduction>
    </actuator>
    <joint name="right_wheel_hinge"/>
    <mechanicalReduction>50</mechanicalReduction>
    <motorTorqueConstant>1</motorTorqueConstant>
    <pulsesPerRevolution>10000</pulsesPerRevolution>
  </transmission>
  <link name="left_wheel">
    <origin rpy="0 0 0" xyz="0 0 0"/>
    <inertial>
      <mass value="0.5"/>
      <origin xyz="0 0 0"/>
      <inertia ixx="0.012411765597" ixy="0" ixz="0" iyy="0.015218160428" iyz="0" izz="0.011763977943"/>
    </inertial>
    <visual name="visual">
      <origin rpy="0 0 0" xyz="0 0 0"/>
      <geometry>
        <cylinder length="0.05" radius="0.08"/>
      </geometry>
      <material name="black">
        <color rgba="0 0 0 1.0"/>
      </material>
    </visual>
    <collision>
      <origin rpy="0 0 0" xyz="0 0 0"/>
      <geometry>
        <cylinder length="0.05" radius="0.08"/>
      </geometry>
    </collision>
  </link>
  <joint name="left_wheel_hinge" type="continuous">
    <origin rpy="-1.5707 0 0" xyz="0.1 0.17 -0.055"/>
    <child link="left_wheel"/>
    <parent link="chassis"/>
    <axis xyz="0 0 1"/>
    <limit effort="100" velocity="100"/>
    <joint_properties damping="0.0" friction="0.0"/>
  </joint>
  <gazebo reference="left_wheel">
    <material>Gazebo/Black</material>
    <turnGravityOff>false</turnGravityOff>
    <selfCollide>true</selfCollide>
    <mu1>100.0</mu1>
    <mu2>100.0</mu2>
    <kp>1000000.0</kp>
    <kd>1.0</kd>
  </gazebo>
  <transmission name="left_wheel_transmission">
    <type>transmission_interface/SimpleTransmission</type>
    <actuator name="left_wheel_motor">
      <hardwareInterface>EffortJointInterface</hardwareInterface>
      <mechanicalReduction>50</mechanicalReduction>
    </actuator>
    <joint name="left_wheel_hinge"/>
    <mechanicalReduction>50</mechanicalReduction>
    <motorTorqueConstant>1</motorTorqueConstant>
    <pulsesPerRevolution>10000</pulsesPerRevolution>
  </transmission>
  <gazebo>
    <plugin filename="libgazebo_ros_diff_drive.so" name="diff_drive">
      <alwaysOn>true</alwaysOn>
      <!-- For some reason, the wheels need to be swapped otherwise turning left results in turning right -->
      <leftJoint>right_wheel_hinge</leftJoint>
      <rightJoint>left_wheel_hinge</rightJoint>
      <wheelSeparation>0.34</wheelSeparation>
      <wheelDiameter>0.16</wheelDiameter>
      <torque>30</torque>
      <commandTopic>cmd_vel</commandTopic>
      <odometryTopic>odom</odometryTopic>
      <odometryFrame>odom</odometryFrame>
      <robotBaseFrame>base_link</robotBaseFrame>
    </plugin>
  </gazebo>
  <link name="rear_right_wheel">
    <origin rpy="0 0 0" xyz="0 0 0"/>
    <inertial>
      <mass value="0.5"/>
      <origin xyz="0 0 0"/>
      <inertia ixx="0.012411765597" ixy="0" ixz="0" iyy="0.015218160428" iyz="0" izz="0.011763977943"/>
    </inertial>
    <visual name="visual">
      <origin rpy="0 0 0" xyz="0 0 0"/>
      <geometry>
        <cylinder length="0.05" radius="0.08"/>
        <!-- A single wheel has a diameter of 16 cm -->
      </geometry>
      <material name="black">
        <color rgba="0 0 0 1.0"/>
      </material>
    </visual>
    <collision>
      <origin rpy="0 0 0" xyz="0 0 0"/>
      <geometry>
        <cylinder length="0.05" radius="0.08"/>
      </geometry>
    </collision>
  </link>
  <joint name="rear_right_wheel_hinge" type="continuous">
    <origin rpy="-1.5707 0 0" xyz="-0.115 -0.17 -0.055"/>
    <child link="rear_right_wheel"/>
    <parent link="chassis"/>
    <axis xyz=" 0 0 1"/>
    <limit effort="100" velocity="100"/>
    <joint_properties damping="0.0" friction="0.0"/>
  </joint>
  <link name="rear_left_wheel">
    <origin rpy="0 0 0" xyz="0 0 0"/>
    <inertial>
      <mass value="0.5"/>
      <origin xyz="0 0 0"/>
      <inertia ixx="0.012411765597" ixy="0" ixz="0" iyy="0.015218160428" iyz="0" izz="0.011763977943"/>
    </inertial>
    <visual name="visual">
      <origin rpy="0 0 0" xyz="0 0 0"/>
      <geometry>
        <cylinder length="0.05" radius="0.08"/>
      </geometry>
      <material name="black">
        <color rgba="0 0 0 1.0"/>
      </material>
    </visual>
    <collision>
      <origin rpy="0 0 0" xyz="0 0 0"/>
      <geometry>
        <cylinder length="0.05" radius="0.08"/>
      </geometry>
    </collision>
  </link>
  <joint name="rear_left_wheel_hinge" type="continuous">
    <origin rpy="1.5707 0 0" xyz="-0.115 0.17 -0.055"/>
    <child link="rear_left_wheel"/>
    <parent link="chassis"/>
    <axis xyz="0 0 1"/>
    <limit effort="100" velocity="100"/>
    <joint_properties damping="0.0" friction="0.0"/>
  </joint>
  <!-- Bottom part: black box, laser, xtion and laptop stand -->
  <link name="bottom_box">
    <origin rpy="0 0 0" xyz="0 0 0"/>
    <inertial>
      <mass value="10"/>
      <origin xyz="0 0 0"/>
      <inertia ixx="1" ixy="0" ixz="0" iyy="1" iyz="0" izz="1"/>
    </inertial>
    <visual name="visual">
      <origin rpy="0 0 0" xyz="0 0 0"/>
      <geometry>
        <mesh filename="package://sudo_description/models/box.dae" scale="0.31 0.35 0.42"/>
      </geometry>
    </visual>
    <collision>
      <origin rpy="0 0 0" xyz="0 0 0"/>
      <geometry>
        <mesh filename="package://sudo_description/models/box.dae" scale="0.31 0.35 0.02"/>
      </geometry>
    </collision>
  </link>
  <gazebo reference="bottom_box">
    <material>Gazebo/FlatBlack</material>
  </gazebo>
  <joint name="chassis_to_bottom_box" type="fixed">
    <!--<origin rpy=" 0 0 0" xyz="0.08 0 0.33"/>-->
    <origin rpy=" 0 0 0" xyz="0.01 0 0.33"/>
    <child link="bottom_box"/>
    <parent link="chassis"/>
  </joint>
 
  <link name="laser_link">
    <origin rpy="0 0 0" xyz="-0 0 0"/>
    <inertial>
      <mass value="10"/>
      <origin xyz="0 0 0"/>
      <inertia ixx="1" ixy="0" ixz="0" iyy="1" iyz="0" izz="1"/>
    </inertial>
    <visual name="visual">
      <origin rpy="0 0 0" xyz="0 0 0"/>
      <geometry>
        <mesh filename="package://sudo_description/models/hokuyo/meshes/hokuyo.dae"/>
      </geometry>
    </visual>
    <collision>
      <geometry>
        <mesh filename="package://sudo_description/models/hokuyo/meshes/hokuyo.dae"/>
      </geometry>
    </collision>
  </link>
  
  <gazebo reference="laser_link">
    <selfCollide>false</selfCollide>
    <static>true</static>
    <turnGravityOff>false</turnGravityOff>
    <sensor type="gpu_ray" name="head_hokuyo_sensor">
        <pose>0 0 0 0 0 0</pose>
        <visualize>true</visualize>
        <update_rate>200</update_rate>
        <ray>
          <scan>
            <horizontal>
              <samples>720</samples>
              <resolution>1</resolution>
              <min_angle>-1.7</min_angle>
              <max_angle>1.7</max_angle>
            </horizontal>
          </scan>
          <range>
            <min>0.4</min>
            <max>30.0</max>
            <resolution>0.01</resolution>
          </range>
          <noise>
            <type>gaussian</type>
            <!-- Noise parameters based on published spec for Hokuyo laser
                 achieving "+-30mm" accuracy at range < 10m.  A mean of 0.0m and
                 stddev of 0.01m will put 99.7% of samples within 0.03m of the true
                 reading. -->
            <mean>0.0</mean>
            <stddev>0.01</stddev>
          </noise>
        </ray>
        <!-- Plugin to simulate ros laser topic in gazebo and ros-->
        <plugin name="gazebo_ros_head_hokuyo_controller" filename="libgazebo_ros_gpu_laser.so">
          <topicName>/scan</topicName>
          <frameName>laser_link</frameName>
        </plugin>
      </sensor>
  </gazebo>
  
  <joint name="chassis_to_laser_link" type="fixed">
    <!--<origin rpy="0 0 3.14" xyz="-0.2 0 0.15 "/>-->
    <origin rpy="0 0 3.14" xyz="-0.27 0 0.15 "/>
    <child link="laser_link"/>
    <parent link="chassis"/>
  </joint>
  <link name="xtion_link">
    <inertial>
      <mass value="0.200"/>
      <origin rpy="0 0 0" xyz="0 0 0"/>
      <inertia ixx="5.8083e-4" ixy="0" ixz="0" iyy="3.0833e-5" iyz="0" izz="5.9083e-4"/>
    </inertial>
    <visual>
      <origin rpy="0 0 0" xyz="0 0 0"/>
      <geometry>
        <mesh filename="package://sudo_description/models/box.dae" scale="0.035 0.18 0.025"/>
      </geometry>
    </visual>
    <collision>
      <origin rpy="0 0 0" xyz="0 0 0"/>
      <geometry>
        <mesh filename="package://sudo_description/models/box.dae" scale="0.035 0.18 0.025"/>
      </geometry>
    </collision>
  </link>
  <gazebo reference="xtion_link">
    <material>Gazebo/FlatBlack</material>
  </gazebo>
  <joint name="bottom_box_to_xtion" type="fixed">
    <origin rpy=" 0 0 0" xyz="0.1725 0 0.2175"/>
    <child link="xtion_link"/>
    <parent link="bottom_box"/>
  </joint>
  <link name="laptop_stand">
    <origin rpy="0 0 0" xyz="0 0 0"/>
    <inertial>
      <mass value="0.5"/>
      <origin xyz="0 0 0"/>
      <inertia ixx="1" ixy="0" ixz="0" iyy="1" iyz="0" izz="1"/>
    </inertial>
    <visual name="visual">
      <origin rpy="0 0 0" xyz="0 0 0"/>
      <geometry>
        <mesh filename="package://sudo_description/models/box.dae" scale="0.3 0.29 0.05"/>
      </geometry>
      <material name="black">
        <color rgba="0 0 0 1.0"/>
      </material>
    </visual>
    <collision>
      <origin rpy="0 0 0" xyz="0 0 0"/>
      <geometry>
        <mesh filename="package://sudo_description/models/box.dae" scale="0.3 0.29 0.05"/>
      </geometry>
    </collision>
  </link>
  <gazebo reference="laptop_stand">
    <material>Gazebo/Grey</material>
  </gazebo>
  <joint name="bottom_box_to_laptop_stand" type="fixed">
    <origin rpy=" 0 -0.52 0" xyz="-0.125 0 0.235"/>
    <child link="laptop_stand"/>
    <parent link="bottom_box"/>
  </joint>
  <!-- Middle part: bars and emergency buttons -->
  <link name="bar_left">
    <origin rpy="0 0 0" xyz="0 0 0"/>
    <inertial>
      <mass value="1"/>
      <origin xyz="0 0 0"/>
      <inertia ixx="1" ixy="0" ixz="0" iyy="1" iyz="0" izz="1"/>
    </inertial>
    <visual name="visual">
      <geometry>
        <mesh filename="package://sudo_description/models/box.dae" scale=".04 0.03 0.94"/>
      </geometry>
      <material name="black">
        <color rgba="0 0 0 1.0"/>
      </material>
    </visual>
    <collision>
      <geometry>
        <mesh filename="package://sudo_description/models/box.dae" scale=".04 0.03 0.94"/>
      </geometry>
    </collision>
  </link>
  <gazebo reference="bar_left">
    <material>Gazebo/Grey</material>
  </gazebo>
  <joint name="bottom_box_to_bar_left" type="fixed">
    <origin rpy="0 0 0" xyz="0 0.16 0.68"/>
    <child link="bar_left"/>
    <parent link="bottom_box"/>
  </joint>
  <link name="emergency_left">
    <origin rpy="0 0 0" xyz="0 0 0"/>
    <inertial>
      <mass value="0.1"/>
      <origin xyz="0 0 0"/>
      <inertia ixx="1" ixy="0" ixz="0" iyy="1" iyz="0" izz="1"/>
    </inertial>
    <visual name="visual">
      <geometry>
        <mesh filename="package://sudo_description/models/box.dae" scale="0.04 0.07 0.07"/>
      </geometry>
      <material name="black">
        <color rgba="0 0 0 1.0"/>
      </material>
    </visual>
    <collision>
      <geometry>
        <mesh filename="package://sudo_description/models/box.dae" scale="0.04 0.07 0.07"/>
      </geometry>
    </collision>
  </link>
  <gazebo reference="emergency_left">
    <material>Gazebo/FlatBlack</material>
  </gazebo>
  <joint name="bar_left to_emergency_left" type="fixed">
    <origin rpy="0 0 0" xyz="0 0.05 0.06"/>
    <child link="emergency_left"/>
    <parent link="bar_left"/>
  </joint>
  <link name="bar_right">
    <origin rpy="0 0 0" xyz="0 0 0"/>
    <inertial>
      <mass value="1"/>
      <origin xyz="0 0 0"/>
      <inertia ixx="1" ixy="0" ixz="0" iyy="1" iyz="0" izz="1"/>
    </inertial>
    <visual name="visual">
      <geometry>
        <mesh filename="package://sudo_description/models/box.dae" scale="0.04 0.03 0.94"/>
      </geometry>
      <material name="black">
        <color rgba="0 0 0 1.0"/>
      </material>
    </visual>
    <collision>
      <geometry>
        <mesh filename="package://sudo_description/models/box.dae" scale="0.04 0.03 0.94"/>
      </geometry>
    </collision>
  </link>
  <gazebo reference="bar_right">
    <material>Gazebo/Grey</material>
  </gazebo>
  <joint name="bottom_box_to_bar_right" type="fixed">
    <origin rpy="0 0 0" xyz="0 -0.16 0.68"/>
    <child link="bar_right"/>
    <parent link="bottom_box"/>
  </joint>
  <link name="emergency_right">
    <origin rpy="0 0 0" xyz="0 0 0"/>
    <inertial>
      <mass value="0.1"/>
      <origin xyz="0 0 0"/>
      <inertia ixx="1" ixy="0" ixz="0" iyy="1" iyz="0" izz="1"/>
    </inertial>
    <visual name="visual">
      <geometry>
        <mesh filename="package://sudo_description/models/box.dae" scale="0.04 0.07 0.07"/>
      </geometry>
      <material name="black">
        <color rgba="0 0 0 1.0"/>
      </material>
    </visual>
    <collision>
      <geometry>
        <mesh filename="package://sudo_description/models/box.dae" scale="0.04 0.07 0.07"/>
      </geometry>
    </collision>
  </link>
  <gazebo reference="emergency_right">
    <material>Gazebo/FlatBlack</material>
  </gazebo>
  <joint name="bar_right to_emergency_right" type="fixed">
    <origin rpy="0 0 0" xyz="0 -0.05 0.06"/>
    <child link="emergency_right"/>
    <parent link="bar_right"/>
  </joint>
  <!-- Top box: black box and kinects -->
  <link name="top_box">
    <origin rpy="0 0 0" xyz="-0 0 0"/>
    <inertial>
      <mass value="0.5"/>
      <origin xyz="0 0 0"/>
      <inertia ixx="1" ixy="0" ixz="0" iyy="1" iyz="0" izz="1"/>
    </inertial>
    <visual name="visual">
      <origin rpy="0 0 0" xyz="0 0 0"/>
      <geometry>
        <mesh filename="package://sudo_description/models/box.dae" scale="0.04 0.35 0.2"/>
      </geometry>
      <material name="black">
        <color rgba="0 0 0 1.0"/>
      </material>
    </visual>
    <collision>
      <origin rpy="0 0 0" xyz="0 0 0"/>
      <geometry>
        <mesh filename="package://sudo_description/models/box.dae" scale="0.04 0.35 0.2"/>
      </geometry>
    </collision>
  </link>
  <gazebo reference="top_box">
    <material>Gazebo/FlatBlack</material>
  </gazebo>
  <joint name="bar_left_to_top_box" type="fixed">
    <origin rpy=" 0 0 0" xyz="0 -0.16 0.57"/>
    <child link="top_box"/>
    <parent link="bar_left"/>
  </joint>
  <link name="bottom_kinect_box">
    <inertial>
      <mass value="0.25"/>
      <origin xyz="0 0 0"/>
      <inertia ixx="1" ixy="0" ixz="0" iyy="1" iyz="0" izz="1"/>
    </inertial>
    <origin rpy="0 0 0" xyz="0 0 0"/>
    <visual name="visual">
      <origin rpy="0 0 0" xyz="0 0 0"/>
      <geometry>
        <mesh filename="package://sudo_description/models/box.dae" scale="0.09 0.075 0.03"/>
      </geometry>
      <material name="black">
        <color rgba="0 0 0 1.0"/>
      </material>
    </visual>
    <collision>
      <origin rpy="0 0 0" xyz="0 0 0"/>
      <geometry>
        <mesh filename="package://sudo_description/models/box.dae" scale="0.09 0.075 0.03"/>
      </geometry>
    </collision>
  </link>
  <gazebo reference="bottom_kinect_box">
    <material>Gazebo/Grey</material>
  </gazebo>
  <joint name="top_box_to_bottom_kinect_box" type="fixed">
    <origin rpy=" 0 0 0" xyz="0.065 0 -0.085"/>
    <child link="bottom_kinect_box"/>
    <parent link="top_box"/>
  </joint>
  <link name="camera_link">
    <origin rpy="0 0 0" xyz="0 0 0"/>
    <inertial>
      <mass value="0.5"/>
      <origin xyz="0 0 0"/>
      <inertia ixx="1" ixy="0" ixz="0" iyy="1" iyz="0" izz="1"/>
    </inertial>
    <visual name="visual">
      <geometry>
        <mesh filename="package://sudo_description/models/kinect/meshes/kinect.dae"/>
      </geometry>
    </visual>
    <collision>
      <geometry>
        <mesh filename="package://sudo_description/models/kinect/meshes/kinect.dae"/>
      </geometry>
    </collision>
  </link>
  <joint name="bottom_box_to_camera_link" type="fixed">
    <origin rpy="0 1.24 0" xyz="0.16 0 1.15"/>
    <!-- Kinect is placed 2 cm back compared to bottom kinect box -->
    <child link="camera_link"/>
    <parent link="bottom_box"/>
  </joint>
  <gazebo reference="camera_link">
    <selfCollide>false</selfCollide>
    <static>true</static>
    <turnGravityOff>false</turnGravityOff>
    <sensor name="openni_camera_camera" type="depth">
      <pose>0 0 0 0 0 0</pose>
      <always_on>1</always_on>
      <visualize>true</visualize>
      <camera>
        <horizontal_fov>1.047</horizontal_fov>
        <image>
          <width>640</width>
          <height>480</height>
          <format>R8G8B8</format>
        </image>
        <depth_camera/>
        <clip>
          <near>0.1</near>
          <far>100</far>
        </clip>
      </camera>
      <plugin filename="libgazebo_ros_openni_kinect.so" name="camera_controller">
        <alwaysOn>true</alwaysOn>
        <updateRate>15.0</updateRate>
        <cameraName>camera</cameraName>
        <frameName>camera_link</frameName>
        <imageTopicName>rgb/image_raw</imageTopicName>
        <depthImageTopicName>depth/image_raw</depthImageTopicName>
        <pointCloudTopicName>depth/points</pointCloudTopicName>
        <cameraInfoTopicName>rgb/camera_info</cameraInfoTopicName>
        <depthImageCameraInfoTopicName>depth/camera_info</depthImageCameraInfoTopicName>
        <pointCloudCutoff>0.4</pointCloudCutoff>
        <hackBaseline>0.07</hackBaseline>
        <distortionK1>0.0</distortionK1>
        <distortionK2>0.0</distortionK2>
        <distortionK3>0.0</distortionK3>
        <distortionT1>0.0</distortionT1>
        <distortionT2>0.0</distortionT2>
        <CxPrime>0.0</CxPrime>
        <Cx>0.0</Cx>
        <Cy>0.0</Cy>
        <focalLength>0.0</focalLength>
      </plugin>
    </sensor>
  </gazebo>
  <link name="camera2_link">
    <origin rpy="0 0 0" xyz="0 0 0"/>
    <inertial>
      <mass value="0.5"/>
      <origin xyz="0 0 0"/>
      <inertia ixx="1" ixy="0" ixz="0" iyy="1" iyz="0" izz="1"/>
    </inertial>
    <visual name="visual">
      <geometry>
        <mesh filename="package://sudo_description/models/kinect/meshes/kinect.dae"/>
      </geometry>
    </visual>
    <collision>
      <geometry>
        <mesh filename="package://sudo_description/models/kinect/meshes/kinect.dae"/>
      </geometry>
    </collision>
  </link>
  <joint name="bottom_box_to_camera2_link" type="fixed">
    <origin rpy="0 0 0" xyz="0.035 0 1.404"/>
    <!-- The kinect is placed 5.04 cm higher, because mid of kinect is inside the sensor -->
    <child link="camera2_link"/>
    <parent link="bottom_box"/>
  </joint>
  <gazebo reference="camera2_link">
    <selfCollide>false</selfCollide>
    <static>true</static>
    <turnGravityOff>false</turnGravityOff>
    <sensor name="openni_camera_camera" type="depth">
      <pose>0 0 0 0 0 0</pose>
      <always_on>1</always_on>
      <visualize>true</visualize>
      <camera>
        <horizontal_fov>1.047</horizontal_fov>
        <image>
          <width>640</width>
          <height>480</height>
          <format>R8G8B8</format>
        </image>
        <depth_camera/>
        <clip>
          <near>0.1</near>
          <far>100</far>
        </clip>
      </camera>
      <plugin filename="libgazebo_ros_openni_kinect.so" name="camera_controller">
        <alwaysOn>true</alwaysOn>
        <updateRate>10.0</updateRate>
        <cameraName>camera2</cameraName>
        <frameName>camera2_link</frameName>
        <imageTopicName>rgb/image_raw</imageTopicName>
        <depthImageTopicName>depth/image_raw</depthImageTopicName>
        <pointCloudTopicName>depth/points</pointCloudTopicName>
        <cameraInfoTopicName>rgb/camera_info</cameraInfoTopicName>
        <depthImageCameraInfoTopicName>depth/camera_info</depthImageCameraInfoTopicName>
        <pointCloudCutoff>0.4</pointCloudCutoff>
        <hackBaseline>0.07</hackBaseline>
        <distortionK1>0.0</distortionK1>
        <distortionK2>0.0</distortionK2>
        <distortionK3>0.0</distortionK3>
        <distortionT1>0.0</distortionT1>
        <distortionT2>0.0</distortionT2>
        <CxPrime>0.0</CxPrime>
        <Cx>0.0</Cx>
        <Cy>0.0</Cy>
        <focalLength>0.0</focalLength>
      </plugin>
    </sensor>
  </gazebo>

  

</robot>
