<?xml version="1.0" ?>
<!-- =================================================================================== -->
<!-- |    This document was autogenerated by xacro from complete_model.urdf.xacro      | -->
<!-- |    EDITING THIS FILE BY HAND IS NOT RECOMMENDED                                 | -->
<!-- =================================================================================== -->
<robot name="sudo" xmlns:controller="http://playerstage.sourceforge.net/gazebo/xmlschema/#controller" xmlns:interface="http://playerstage.sourceforge.net/gazebo/xmlschema/#interface" xmlns:sensor="http://playerstage.sourceforge.net/gazebo/xmlschema/#sensor" xmlns:xacro="http://ros.org/wiki/xacro">
  <!-- Robot base: base_footprint, chassis (pioneer) and left and right wheel -->
  <link name="base_footprint">
    <origin rpy="0 0 0" xyz="0 0 0.0"/>
  </link>
  <link name="chassis">
    <inertial>
      <mass value="40"/>
      <!--<origin xyz="-0.05 0 0"/>-->
      <origin xyz="-0.05 0 0"/>
      <inertia ixx="1" ixy="0" ixz="0" iyy="1" iyz="0" izz="1"/>
    </inertial>
    <origin rpy="0 0 0" xyz="0 0 0"/>
    <visual name="visual">
      <origin rpy="0 0 0" xyz="0 0 0.055"/>
      <!-- Pioneer stands 5.5 cm above the ground -->
      <geometry>
        <mesh filename="package://sudo_description/models/pioneer2dx/meshes/chassis.dae"/>
      </geometry>
    </visual>
    <collision>
      <origin rpy="0 0 0" xyz="0 0 0.055"/>
      <geometry>
        <mesh filename="package://sudo_description/models/pioneer2dx/meshes/chassis.dae"/>
      </geometry>
    </collision>
  </link>
  <joint name="base_footprint_to_chassis" type="fixed">
    <origin rpy="0 0 0" xyz="0 0 0.135"/>
    <!-- The pioneer is 16cm high -->
    <child link="chassis"/>
    <parent link="base_footprint"/>
  </joint>
  <link name="right_wheel">
    <origin rpy="0 0 0" xyz="0 0 0"/>
    <inertial>
      <mass value="0.5"/>
      <origin xyz="0 0 0"/>
      <inertia ixx="0.012411765597" ixy="0" ixz="0" iyy="0.015218160428" iyz="0" izz="0.011763977943"/>
    </inertial>
    <visual name="visual">
      <origin rpy="0 0 0" xyz="0 0 0"/>
      <geometry>
        <cylinder length="0.05" radius="0.08"/>
        <!-- A single wheel has a diameter of 16 cm -->
      </geometry>
      <material name="black">
        <color rgba="0 0 0 1.0"/>
      </material>
    </visual>
    <collision>
      <origin rpy="0 0 0" xyz="0 0 0"/>
      <geometry>
        <cylinder length="0.05" radius="0.08"/>
      </geometry>
    </collision>
  </link>
  <joint name="right_wheel_hinge" type="continuous">
    <origin rpy="-1.5707 0 0" xyz="0.1 -0.17 -0.055"/>
    <child link="right_wheel"/>
    <parent link="chassis"/>
    <axis xyz=" 0 0 1"/>
    <limit effort="100" velocity="100"/>
    <joint_properties damping="0.0" friction="0.0"/>
  </joint>
  <gazebo reference="right_wheel">
    <material>Gazebo/Black</material>
    <turnGravityOff>false</turnGravityOff>
    <selfCollide>true</selfCollide>
    <mu1>100.0</mu1>
    <mu2>100.0</mu2>
    <kp>1000000.0</kp>
    <kd>1.0</kd>
  </gazebo>
  <transmission name="right_wheel_transmission">
    <type>transmission_interface/SimpleTransmission</type>
    <actuator name="right_wheel_motor">
      <hardwareInterface>EffortJointInterface</hardwareInterface>
      <mechanicalReduction>50</mechanicalReduction>
    </actuator>
    <joint name="right_wheel_hinge"/>
    <mechanicalReduction>50</mechanicalReduction>
    <motorTorqueConstant>1</motorTorqueConstant>
    <pulsesPerRevolution>10000</pulsesPerRevolution>
  </transmission>
  <link name="left_wheel">
    <origin rpy="0 0 0" xyz="0 0 0"/>
    <inertial>
      <mass value="0.5"/>
      <origin xyz="0 0 0"/>
      <inertia ixx="0.012411765597" ixy="0" ixz="0" iyy="0.015218160428" iyz="0" izz="0.011763977943"/>
    </inertial>
    <visual name="visual">
      <origin rpy="0 0 0" xyz="0 0 0"/>
      <geometry>
        <cylinder length="0.05" radius="0.08"/>
      </geometry>
      <material name="black">
        <color rgba="0 0 0 1.0"/>
      </material>
    </visual>
    <collision>
      <origin rpy="0 0 0" xyz="0 0 0"/>
      <geometry>
        <cylinder length="0.05" radius="0.08"/>
      </geometry>
    </collision>
  </link>
  <joint name="left_wheel_hinge" type="continuous">
    <origin rpy="-1.5707 0 0" xyz="0.1 0.17 -0.055"/>
    <child link="left_wheel"/>
    <parent link="chassis"/>
    <axis xyz="0 0 1"/>
    <limit effort="100" velocity="100"/>
    <joint_properties damping="0.0" friction="0.0"/>
  </joint>
  <gazebo reference="left_wheel">
    <material>Gazebo/Black</material>
    <turnGravityOff>false</turnGravityOff>
    <selfCollide>true</selfCollide>
    <mu1>100.0</mu1>
    <mu2>100.0</mu2>
    <kp>1000000.0</kp>
    <kd>1.0</kd>
  </gazebo>
  <transmission name="left_wheel_transmission">
    <type>transmission_interface/SimpleTransmission</type>
    <actuator name="left_wheel_motor">
      <hardwareInterface>EffortJointInterface</hardwareInterface>
      <mechanicalReduction>50</mechanicalReduction>
    </actuator>
    <joint name="left_wheel_hinge"/>
    <mechanicalReduction>50</mechanicalReduction>
    <motorTorqueConstant>1</motorTorqueConstant>
    <pulsesPerRevolution>10000</pulsesPerRevolution>
  </transmission>
  <gazebo>
    <plugin filename="libgazebo_ros_diff_drive.so" name="diff_drive">
      <alwaysOn>true</alwaysOn>
      <!-- For some reason, the wheels need to be swapped otherwise turning left results in turning right -->
      <leftJoint>right_wheel_hinge</leftJoint>
      <rightJoint>left_wheel_hinge</rightJoint>
      <wheelSeparation>0.32</wheelSeparation>
      <wheelDiameter>0.11</wheelDiameter>
      <torque>50</torque>
      <commandTopic>cmd_vel</commandTopic>
      <odometryTopic>odom</odometryTopic>
      <odometryFrame>odom</odometryFrame>
      <robotBaseFrame>base_footprint</robotBaseFrame>
    </plugin>
  </gazebo>
  <link name="rear_right_wheel">
    <origin rpy="0 0 0" xyz="0 0 0"/>
    <inertial>
      <mass value="0.5"/>
      <origin xyz="0 0 0"/>
      <inertia ixx="0.012411765597" ixy="0" ixz="0" iyy="0.015218160428" iyz="0" izz="0.011763977943"/>
    </inertial>
    <visual name="visual">
      <origin rpy="0 0 0" xyz="0 0 0"/>
      <geometry>
        <cylinder length="0.05" radius="0.08"/>
        <!-- A single wheel has a diameter of 16 cm -->
      </geometry>
      <material name="black">
        <color rgba="0 0 0 1.0"/>
      </material>
    </visual>
    <collision>
      <origin rpy="0 0 0" xyz="0 0 0"/>
      <geometry>
        <cylinder length="0.05" radius="0.08"/>
      </geometry>
    </collision>
  </link>
  <joint name="rear_right_wheel_hinge" type="continuous">
    <origin rpy="-1.5707 0 0" xyz="-0.115 -0.17 -0.055"/>
    <child link="rear_right_wheel"/>
    <parent link="chassis"/>
    <axis xyz=" 0 0 1"/>
    <limit effort="100" velocity="100"/>
    <joint_properties damping="0.0" friction="0.0"/>
  </joint>
  <link name="rear_left_wheel">
    <origin rpy="0 0 0" xyz="0 0 0"/>
    <inertial>
      <mass value="0.5"/>
      <origin xyz="0 0 0"/>
      <inertia ixx="0.012411765597" ixy="0" ixz="0" iyy="0.015218160428" iyz="0" izz="0.011763977943"/>
    </inertial>
    <visual name="visual">
      <origin rpy="0 0 0" xyz="0 0 0"/>
      <geometry>
        <cylinder length="0.05" radius="0.08"/>
      </geometry>
      <material name="black">
        <color rgba="0 0 0 1.0"/>
      </material>
    </visual>
    <collision>
      <origin rpy="0 0 0" xyz="0 0 0"/>
      <geometry>
        <cylinder length="0.05" radius="0.08"/>
      </geometry>
    </collision>
  </link>
  <joint name="rear_left_wheel_hinge" type="continuous">
    <origin rpy="1.5707 0 0" xyz="-0.115 0.17 -0.055"/>
    <child link="rear_left_wheel"/>
    <parent link="chassis"/>
    <axis xyz="0 0 1"/>
    <limit effort="100" velocity="100"/>
    <joint_properties damping="0.0" friction="0.0"/>
  </joint>
  <!-- Bottom part: black box, laser, xtion and laptop stand -->
  <link name="bottom_box">
    <origin rpy="0 0 0" xyz="0 0 0"/>
    <inertial>
      <mass value="10"/>
      <origin xyz="0 0 0"/>
      <inertia ixx="1" ixy="0" ixz="0" iyy="1" iyz="0" izz="1"/>
    </inertial>
    <visual name="visual">
      <origin rpy="0 0 0" xyz="0 0 0"/>
      <geometry>
        <mesh filename="package://sudo_description/models/box.dae" scale="0.31 0.35 0.42"/>
      </geometry>
    </visual>
    <collision>
      <origin rpy="0 0 0" xyz="0 0 0"/>
      <geometry>
        <mesh filename="package://sudo_description/models/box.dae" scale="0.31 0.35 0.02"/>
      </geometry>
    </collision>
  </link>
  <gazebo reference="bottom_box">
    <material>Gazebo/FlatBlack</material>
  </gazebo>
  <joint name="chassis_to_bottom_box" type="fixed">
    <!--<origin rpy=" 0 0 0" xyz="0.08 0 0.33"/>-->
    <origin rpy=" 0 0 0" xyz="0.01 0 0.33"/>
    <child link="bottom_box"/>
    <parent link="chassis"/>
  </joint>
  <link name="laser_link">
    <origin rpy="0 0 0" xyz="-0 0 0"/>
    <inertial>
      <mass value="10"/>
      <origin xyz="0 0 0"/>
      <inertia ixx="1" ixy="0" ixz="0" iyy="1" iyz="0" izz="1"/>
    </inertial>
    <visual name="visual">
      <origin rpy="0 0 0" xyz="0 0 0"/>
      <geometry>
        <mesh filename="package://sudo_description/models/hokuyo/meshes/hokuyo.dae"/>
      </geometry>
    </visual>
    <collision>
      <geometry>
        <mesh filename="package://sudo_description/models/hokuyo/meshes/hokuyo.dae"/>
      </geometry>
    </collision>
  </link>
  <joint name="chassis_to_laser_link" type="fixed">
    <!--<origin rpy="0 0 3.14" xyz="-0.2 0 0.15 "/>-->
    <origin rpy="0 0 3.14" xyz="-0.27 0 0.15 "/>
    <child link="laser_link"/>
    <parent link="chassis"/>
  </joint>
  <link name="xtion_link">
    <inertial>
      <mass value="0.200"/>
      <origin rpy="0 0 0" xyz="0 0 0"/>
      <inertia ixx="5.8083e-4" ixy="0" ixz="0" iyy="3.0833e-5" iyz="0" izz="5.9083e-4"/>
    </inertial>
    <visual>
      <origin rpy="0 0 0" xyz="0 0 0"/>
      <geometry>
        <mesh filename="package://sudo_description/models/box.dae" scale="0.035 0.18 0.025"/>
      </geometry>
    </visual>
    <collision>
      <origin rpy="0 0 0" xyz="0 0 0"/>
      <geometry>
        <mesh filename="package://sudo_description/models/box.dae" scale="0.035 0.18 0.025"/>
      </geometry>
    </collision>
  </link>
  <gazebo reference="xtion_link">
    <material>Gazebo/FlatBlack</material>
  </gazebo>
  <joint name="bottom_box_to_xtion" type="fixed">
    <origin rpy=" 0 0 0" xyz="0.1725 0 0.2175"/>
    <child link="xtion_link"/>
    <parent link="bottom_box"/>
  </joint>
  <link name="laptop_stand">
    <origin rpy="0 0 0" xyz="0 0 0"/>
    <inertial>
      <mass value="0.5"/>
      <origin xyz="0 0 0"/>
      <inertia ixx="1" ixy="0" ixz="0" iyy="1" iyz="0" izz="1"/>
    </inertial>
    <visual name="visual">
      <origin rpy="0 0 0" xyz="0 0 0"/>
      <geometry>
        <mesh filename="package://sudo_description/models/box.dae" scale="0.3 0.29 0.05"/>
      </geometry>
      <material name="black">
        <color rgba="0 0 0 1.0"/>
      </material>
    </visual>
    <collision>
      <origin rpy="0 0 0" xyz="0 0 0"/>
      <geometry>
        <mesh filename="package://sudo_description/models/box.dae" scale="0.3 0.29 0.05"/>
      </geometry>
    </collision>
  </link>
  <gazebo reference="laptop_stand">
    <material>Gazebo/Grey</material>
  </gazebo>
  <joint name="bottom_box_to_laptop_stand" type="fixed">
    <origin rpy=" 0 -0.52 0" xyz="-0.125 0 0.235"/>
    <child link="laptop_stand"/>
    <parent link="bottom_box"/>
  </joint>
  <!-- Middle part: bars and emergency buttons -->
  <link name="bar_left">
    <origin rpy="0 0 0" xyz="0 0 0"/>
    <inertial>
      <mass value="1"/>
      <origin xyz="0 0 0"/>
      <inertia ixx="1" ixy="0" ixz="0" iyy="1" iyz="0" izz="1"/>
    </inertial>
    <visual name="visual">
      <geometry>
        <mesh filename="package://sudo_description/models/box.dae" scale=".04 0.03 0.94"/>
      </geometry>
      <material name="black">
        <color rgba="0 0 0 1.0"/>
      </material>
    </visual>
    <collision>
      <geometry>
        <mesh filename="package://sudo_description/models/box.dae" scale=".04 0.03 0.94"/>
      </geometry>
    </collision>
  </link>
  <gazebo reference="bar_left">
    <material>Gazebo/Grey</material>
  </gazebo>
  <joint name="bottom_box_to_bar_left" type="fixed">
    <origin rpy="0 0 0" xyz="0 0.16 0.68"/>
    <child link="bar_left"/>
    <parent link="bottom_box"/>
  </joint>
  <link name="emergency_left">
    <origin rpy="0 0 0" xyz="0 0 0"/>
    <inertial>
      <mass value="0.1"/>
      <origin xyz="0 0 0"/>
      <inertia ixx="1" ixy="0" ixz="0" iyy="1" iyz="0" izz="1"/>
    </inertial>
    <visual name="visual">
      <geometry>
        <mesh filename="package://sudo_description/models/box.dae" scale="0.04 0.07 0.07"/>
      </geometry>
      <material name="black">
        <color rgba="0 0 0 1.0"/>
      </material>
    </visual>
    <collision>
      <geometry>
        <mesh filename="package://sudo_description/models/box.dae" scale="0.04 0.07 0.07"/>
      </geometry>
    </collision>
  </link>
  <gazebo reference="emergency_left">
    <material>Gazebo/FlatBlack</material>
  </gazebo>
  <joint name="bar_left to_emergency_left" type="fixed">
    <origin rpy="0 0 0" xyz="0 0.05 0.06"/>
    <child link="emergency_left"/>
    <parent link="bar_left"/>
  </joint>
  <link name="bar_right">
    <origin rpy="0 0 0" xyz="0 0 0"/>
    <inertial>
      <mass value="1"/>
      <origin xyz="0 0 0"/>
      <inertia ixx="1" ixy="0" ixz="0" iyy="1" iyz="0" izz="1"/>
    </inertial>
    <visual name="visual">
      <geometry>
        <mesh filename="package://sudo_description/models/box.dae" scale="0.04 0.03 0.94"/>
      </geometry>
      <material name="black">
        <color rgba="0 0 0 1.0"/>
      </material>
    </visual>
    <collision>
      <geometry>
        <mesh filename="package://sudo_description/models/box.dae" scale="0.04 0.03 0.94"/>
      </geometry>
    </collision>
  </link>
  <gazebo reference="bar_right">
    <material>Gazebo/Grey</material>
  </gazebo>
  <joint name="bottom_box_to_bar_right" type="fixed">
    <origin rpy="0 0 0" xyz="0 -0.16 0.68"/>
    <child link="bar_right"/>
    <parent link="bottom_box"/>
  </joint>
  <link name="emergency_right">
    <origin rpy="0 0 0" xyz="0 0 0"/>
    <inertial>
      <mass value="0.1"/>
      <origin xyz="0 0 0"/>
      <inertia ixx="1" ixy="0" ixz="0" iyy="1" iyz="0" izz="1"/>
    </inertial>
    <visual name="visual">
      <geometry>
        <mesh filename="package://sudo_description/models/box.dae" scale="0.04 0.07 0.07"/>
      </geometry>
      <material name="black">
        <color rgba="0 0 0 1.0"/>
      </material>
    </visual>
    <collision>
      <geometry>
        <mesh filename="package://sudo_description/models/box.dae" scale="0.04 0.07 0.07"/>
      </geometry>
    </collision>
  </link>
  <gazebo reference="emergency_right">
    <material>Gazebo/FlatBlack</material>
  </gazebo>
  <joint name="bar_right to_emergency_right" type="fixed">
    <origin rpy="0 0 0" xyz="0 -0.05 0.06"/>
    <child link="emergency_right"/>
    <parent link="bar_right"/>
  </joint>
  <!-- Top box: black box and kinects -->
  <link name="top_box">
    <origin rpy="0 0 0" xyz="-0 0 0"/>
    <inertial>
      <mass value="0.5"/>
      <origin xyz="0 0 0"/>
      <inertia ixx="1" ixy="0" ixz="0" iyy="1" iyz="0" izz="1"/>
    </inertial>
    <visual name="visual">
      <origin rpy="0 0 0" xyz="0 0 0"/>
      <geometry>
        <mesh filename="package://sudo_description/models/box.dae" scale="0.04 0.35 0.2"/>
      </geometry>
      <material name="black">
        <color rgba="0 0 0 1.0"/>
      </material>
    </visual>
    <collision>
      <origin rpy="0 0 0" xyz="0 0 0"/>
      <geometry>
        <mesh filename="package://sudo_description/models/box.dae" scale="0.04 0.35 0.2"/>
      </geometry>
    </collision>
  </link>
  <gazebo reference="top_box">
    <material>Gazebo/FlatBlack</material>
  </gazebo>
  <joint name="bar_left_to_top_box" type="fixed">
    <origin rpy=" 0 0 0" xyz="0 -0.16 0.57"/>
    <child link="top_box"/>
    <parent link="bar_left"/>
  </joint>
  <link name="bottom_kinect_box">
    <inertial>
      <mass value="0.25"/>
      <origin xyz="0 0 0"/>
      <inertia ixx="1" ixy="0" ixz="0" iyy="1" iyz="0" izz="1"/>
    </inertial>
    <origin rpy="0 0 0" xyz="0 0 0"/>
    <visual name="visual">
      <origin rpy="0 0 0" xyz="0 0 0"/>
      <geometry>
        <mesh filename="package://sudo_description/models/box.dae" scale="0.09 0.075 0.03"/>
      </geometry>
      <material name="black">
        <color rgba="0 0 0 1.0"/>
      </material>
    </visual>
    <collision>
      <origin rpy="0 0 0" xyz="0 0 0"/>
      <geometry>
        <mesh filename="package://sudo_description/models/box.dae" scale="0.09 0.075 0.03"/>
      </geometry>
    </collision>
  </link>
  <gazebo reference="bottom_kinect_box">
    <material>Gazebo/Grey</material>
  </gazebo>
  <joint name="top_box_to_bottom_kinect_box" type="fixed">
    <origin rpy=" 0 0 0" xyz="0.065 0 -0.085"/>
    <child link="bottom_kinect_box"/>
    <parent link="top_box"/>
  </joint>
  <link name="camera_link">
    <origin rpy="0 0 0" xyz="0 0 0"/>
    <inertial>
      <mass value="0.5"/>
      <origin xyz="0 0 0"/>
      <inertia ixx="1" ixy="0" ixz="0" iyy="1" iyz="0" izz="1"/>
    </inertial>
    <visual name="visual">
      <geometry>
        <mesh filename="package://sudo_description/models/kinect/meshes/kinect.dae"/>
      </geometry>
    </visual>
    <collision>
      <geometry>
        <mesh filename="package://sudo_description/models/kinect/meshes/kinect.dae"/>
      </geometry>
    </collision>
  </link>
  <joint name="bottom_box_to_camera_link" type="fixed">
    <origin rpy="0 1.24 0" xyz="0.16 0 1.15"/>
    <!-- Kinect is placed 2 cm back compared to bottom kinect box -->
    <child link="camera_link"/>
    <parent link="bottom_box"/>
  </joint>
  <gazebo reference="camera_link">
    <selfCollide>false</selfCollide>
    <static>true</static>
    <turnGravityOff>false</turnGravityOff>
    <sensor name="openni_camera_camera" type="depth">
      <pose>0 0 0 0 0 0</pose>
      <always_on>1</always_on>
      <visualize>true</visualize>
      <camera>
        <horizontal_fov>1.047</horizontal_fov>
        <image>
          <width>640</width>
          <height>480</height>
          <format>R8G8B8</format>
        </image>
        <depth_camera/>
        <clip>
          <near>0.1</near>
          <far>100</far>
        </clip>
      </camera>
      <plugin filename="libgazebo_ros_openni_kinect.so" name="camera_controller">
        <alwaysOn>true</alwaysOn>
        <updateRate>10.0</updateRate>
        <cameraName>camera</cameraName>
        <frameName>camera_link</frameName>
        <imageTopicName>rgb/image_raw</imageTopicName>
        <depthImageTopicName>depth/image_raw</depthImageTopicName>
        <pointCloudTopicName>depth/points</pointCloudTopicName>
        <cameraInfoTopicName>rgb/camera_info</cameraInfoTopicName>
        <depthImageCameraInfoTopicName>depth/camera_info</depthImageCameraInfoTopicName>
        <pointCloudCutoff>0.4</pointCloudCutoff>
        <hackBaseline>0.07</hackBaseline>
        <distortionK1>0.0</distortionK1>
        <distortionK2>0.0</distortionK2>
        <distortionK3>0.0</distortionK3>
        <distortionT1>0.0</distortionT1>
        <distortionT2>0.0</distortionT2>
        <CxPrime>0.0</CxPrime>
        <Cx>0.0</Cx>
        <Cy>0.0</Cy>
        <focalLength>0.0</focalLength>
      </plugin>
    </sensor>
  </gazebo>
  <link name="camera2_link">
    <origin rpy="0 0 0" xyz="0 0 0"/>
    <inertial>
      <mass value="0.5"/>
      <origin xyz="0 0 0"/>
      <inertia ixx="1" ixy="0" ixz="0" iyy="1" iyz="0" izz="1"/>
    </inertial>
    <visual name="visual">
      <geometry>
        <mesh filename="package://sudo_description/models/kinect/meshes/kinect.dae"/>
      </geometry>
    </visual>
    <collision>
      <geometry>
        <mesh filename="package://sudo_description/models/kinect/meshes/kinect.dae"/>
      </geometry>
    </collision>
  </link>
  <joint name="bottom_box_to_camera2_link" type="fixed">
    <origin rpy="0 0 0" xyz="0.035 0 1.404"/>
    <!-- The kinect is placed 5.04 cm higher, because mid of kinect is inside the sensor -->
    <child link="camera2_link"/>
    <parent link="bottom_box"/>
  </joint>
  <gazebo reference="camera2_link">
    <selfCollide>false</selfCollide>
    <static>true</static>
    <turnGravityOff>false</turnGravityOff>
    <sensor name="openni_camera_camera" type="depth">
      <pose>0 0 0 0 0 0</pose>
      <always_on>1</always_on>
      <visualize>true</visualize>
      <camera>
        <horizontal_fov>1.047</horizontal_fov>
        <image>
          <width>640</width>
          <height>480</height>
          <format>R8G8B8</format>
        </image>
        <depth_camera/>
        <clip>
          <near>0.1</near>
          <far>100</far>
        </clip>
      </camera>
      <plugin filename="libgazebo_ros_openni_kinect.so" name="camera_controller">
        <alwaysOn>true</alwaysOn>
        <updateRate>10.0</updateRate>
        <cameraName>camera2</cameraName>
        <frameName>camera2_link</frameName>
        <imageTopicName>rgb/image_raw</imageTopicName>
        <depthImageTopicName>depth/image_raw</depthImageTopicName>
        <pointCloudTopicName>depth/points</pointCloudTopicName>
        <cameraInfoTopicName>rgb/camera_info</cameraInfoTopicName>
        <depthImageCameraInfoTopicName>depth/camera_info</depthImageCameraInfoTopicName>
        <pointCloudCutoff>0.4</pointCloudCutoff>
        <hackBaseline>0.07</hackBaseline>
        <distortionK1>0.0</distortionK1>
        <distortionK2>0.0</distortionK2>
        <distortionK3>0.0</distortionK3>
        <distortionT1>0.0</distortionT1>
        <distortionT2>0.0</distortionT2>
        <CxPrime>0.0</CxPrime>
        <Cx>0.0</Cx>
        <Cy>0.0</Cy>
        <focalLength>0.0</focalLength>
      </plugin>
    </sensor>
  </gazebo>
  <!-- Mico arm: piece of wood and arm -->
  <link name="wooden_arm_base">
    <origin rpy="0 0 0" xyz="-0 0 0"/>
    <inertial>
      <mass value="0.5"/>
      <origin xyz="0 0 0"/>
      <inertia ixx="1" ixy="0" ixz="0" iyy="1" iyz="0" izz="1"/>
    </inertial>
    <visual name="visual">
      <origin rpy="0 0 0" xyz="0 0 0"/>
      <geometry>
        <mesh filename="package://sudo_description/models/box.dae" scale="0.17 0.33 0.02"/>
      </geometry>
      <material name="black">
        <color rgba="0 0 0 1.0"/>
      </material>
    </visual>
    <collision>
      <origin rpy="0 0 0" xyz="0 0 0"/>
      <geometry>
        <mesh filename="package://sudo_description/models/box.dae" scale="0.17 0.33 0.02"/>
      </geometry>
    </collision>
  </link>
  <gazebo reference="wooden_arm_base">
    <material>Gazebo/Wood</material>
  </gazebo>
  <joint name="bottom_box_to_wooden_arm_base" type="fixed">
    <origin rpy=" 0 0 0" xyz="0.07 0 0.22"/>
    <child link="wooden_arm_base"/>
    <parent link="bottom_box"/>
  </joint>
  <link name="metal_arm_base">
    <origin rpy="0 0 0" xyz="-0 0 0"/>
    <inertial>
      <mass value="2"/>
      <origin xyz="0 0 0"/>
      <inertia ixx="1" ixy="0" ixz="0" iyy="1" iyz="0" izz="1"/>
    </inertial>
    <visual name="visual">
      <origin rpy="0 0 0" xyz="0 0 0"/>
      <geometry>
        <mesh filename="package://sudo_description/models/box.dae" scale="0.15 0.2 0.035"/>
      </geometry>
      <material name="black">
        <color rgba="0 0 0 1.0"/>
      </material>
    </visual>
    <collision>
      <origin rpy="0 0 0" xyz="0 0 0"/>
      <geometry>
        <mesh filename="package://sudo_description/models/box.dae" scale="0.15 0.2 0.035"/>
      </geometry>
    </collision>
  </link>
  <gazebo reference="metal_arm_base">
    <material>Gazebo/Black</material>
  </gazebo>
  <joint name="wooden_arm_base_to_metal_arm_base" type="fixed">
    <origin rpy=" 0 0 0" xyz="0.01 0 0.0275"/>
    <child link="metal_arm_base"/>
    <parent link="wooden_arm_base"/>
  </joint>
  <link name="arm_base">
    <origin rpy="0 0 0" xyz="-0 0 0"/>
    <inertial>
      <mass value="0"/>
      <origin xyz="0 0 0"/>
      <inertia ixx="1" ixy="0" ixz="0" iyy="1" iyz="0" izz="1"/>
    </inertial>
  </link>
  <joint name="metal_arm_base_to_arm_base" type="fixed">
    <origin rpy=" 0 0 1.57" xyz="0 0 0.0775"/>
    <child link="arm_base"/>
    <parent link="metal_arm_base"/>
  </joint>
  <material name="JacoGrey">
    <color rgba="0.2 0.2 0.9 1.0"/>
  </material>
  <joint name="mico_base_joint" type="fixed">
    <origin rpy="0 0 0" xyz="0 0 0"/>
    <!-- fnh was: <origin xyz="0 0 0" rpy="0 0 0"/> -->
    <parent link="arm_base"/>
    <child link="mico_base_link"/>
  </joint>
  <link name="mico_base_link">
    <inertial>
      <!-- fnh -->
      <origin xyz="0 0 0"/>
      <mass value="1.0"/>
      <inertia ixx="1" ixy="0" ixz="0" iyy="1" iyz="0" izz="1"/>
    </inertial>
    <visual>
      <material name="JacoGrey"/>
      <origin rpy="0 0 1.57079632679" xyz="0 0 0"/>
      <geometry>
        <mesh filename="package://jaco_model/meshes/jaco_base_joint.dae"/>
      </geometry>
    </visual>
    <collision>
      <origin rpy="0 0 1.57079632679" xyz="0 0 0"/>
      <geometry>
        <mesh filename="package://jaco_model/meshes/jaco_base_joint.dae"/>
      </geometry>
    </collision>
  </link>
  <gazebo reference="mico_base_link">
    <!-- fnh -->
    <material>Gazebo/Grey</material>
    <turnGravityOff>false</turnGravityOff>
    <selfCollide>true</selfCollide>
    <mu1>100.0</mu1>
    <mu2>100.0</mu2>
    <kp>1000000.0</kp>
    <kd>1.0</kd>
  </gazebo>
  <joint name="mico_shoulder_yaw_joint" type="revolute">
    <!--<origin xyz="0 0 ${D1}" rpy="0 0 0"/>-->
    <origin rpy="0 0 0" xyz="0 0 0.2142"/>
    <axis rpy="0 0 0" xyz="0 0 1"/>
    <parent link="mico_base_link"/>
    <child link="mico_shoulder_link"/>
    <limit effort="200" lower="-3.04159265359" upper="3.04159265359" velocity="0.837758016"/>
    <dynamics damping="50.5"/>
  </joint>
  <transmission name="mico_shoulder_yaw_joint_transmission">
    <type>transmission_interface/SimpleTransmission</type>
    <actuator name="mico_shoulder_yaw_joint_motor">
      <hardwareInterface>EffortJointInterface</hardwareInterface>
      <mechanicalReduction>50</mechanicalReduction>
    </actuator>
    <joint name="mico_shoulder_yaw_joint"/>
    <mechanicalReduction>50</mechanicalReduction>
    <motorTorqueConstant>1</motorTorqueConstant>
    <pulsesPerRevolution>10000</pulsesPerRevolution>
  </transmission>
  <link name="mico_shoulder_link">
    <inertial>
      <!-- fnh -->
      <origin xyz="0 0 0"/>
      <mass value="1.0"/>
      <inertia ixx="1" ixy="0" ixz="0" iyy="1" iyz="0" izz="1"/>
    </inertial>
    <visual>
      <material name="JacoGrey"/>
      <origin rpy="1.57079632679 -1.57079632679 0" xyz="0 0 0"/>
      <geometry>
        <mesh filename="package://jaco_model/meshes/jaco_shoulder_yaw_joint.dae"/>
      </geometry>
    </visual>
    <collision>
      <origin rpy="1.57079632679 -1.57079632679 0" xyz="0 0 0"/>
      <geometry>
        <mesh filename="package://jaco_model/meshes/jaco_shoulder_yaw_joint.dae"/>
      </geometry>
    </collision>
  </link>
  <gazebo reference="mico_shoulder_link">
    <!-- fnh -->
    <material>Gazebo/Grey</material>
    <turnGravityOff>false</turnGravityOff>
    <selfCollide>true</selfCollide>
    <mu1>100.0</mu1>
    <mu2>100.0</mu2>
    <kp>1000000.0</kp>
    <kd>1.0</kd>
  </gazebo>
  <joint name="mico_shoulder_pitch_joint" type="revolute">
    <origin rpy="-1.57079632679 0 0" xyz="0 -1e-06 0"/>
    <axis xyz="0 0 1"/>
    <parent link="mico_shoulder_link"/>
    <child link="mico_upper_arm_link"/>
    <limit effort="300" lower="-3.83972424" upper="0.69813168" velocity="0.837758016"/>
    <dynamics damping="50.5"/>
  </joint>
  <transmission name="mico_shoulder_pitch_joint_transmission">
    <type>transmission_interface/SimpleTransmission</type>
    <actuator name="mico_shoulder_pitch_joint_motor">
      <hardwareInterface>EffortJointInterface</hardwareInterface>
      <mechanicalReduction>50</mechanicalReduction>
    </actuator>
    <joint name="mico_shoulder_pitch_joint"/>
    <mechanicalReduction>50</mechanicalReduction>
    <motorTorqueConstant>1</motorTorqueConstant>
    <pulsesPerRevolution>10000</pulsesPerRevolution>
  </transmission>
  <link name="mico_upper_arm_link">
    <inertial>
      <!-- fnh -->
      <origin xyz="0 0 0"/>
      <mass value="1.0"/>
      <inertia ixx="1" ixy="0" ixz="0" iyy="1" iyz="0" izz="1"/>
    </inertial>
    <visual>
      <material name="JacoGrey"/>
      <origin rpy="0 0 -1.57079632679" xyz="0 0 0"/>
      <geometry>
        <mesh filename="package://jaco_model/meshes/jaco_shoulder_pitch_joint.dae" scale="1 0.707317073171 1"/>
      </geometry>
    </visual>
    <collision>
      <origin rpy="0 0 -1.57079632679" xyz="0 0 0"/>
      <geometry>
        <mesh filename="package://jaco_model/meshes/jaco_shoulder_pitch_joint.dae" scale="1 0.707317073171 1"/>
      </geometry>
    </collision>
  </link>
  <gazebo reference="mico_upper_arm_link">
    <!-- fnh -->
    <material>Gazebo/Grey</material>
    <turnGravityOff>false</turnGravityOff>
    <selfCollide>true</selfCollide>
    <mu1>100.0</mu1>
    <mu2>100.0</mu2>
    <kp>1000000.0</kp>
    <kd>1.0</kd>
  </gazebo>
  <joint name="mico_elbow_pitch_joint" type="revolute">
    <origin rpy="0 0 0" xyz="0.29 0 0.012001"/>
    <axis xyz="0 0 1"/>
    <parent link="mico_upper_arm_link"/>
    <child link="mico_lower_arm_link"/>
    <limit effort="200" lower="-4.363323" upper="1.22173044" velocity="0.837758016"/>
    <dynamics damping="50.5"/>
  </joint>
  <transmission name="mico_elbow_pitch_joint_transmission">
    <type>transmission_interface/SimpleTransmission</type>
    <actuator name="mico_elbow_pitch_joint_motor">
      <hardwareInterface>EffortJointInterface</hardwareInterface>
      <mechanicalReduction>50</mechanicalReduction>
    </actuator>
    <joint name="mico_elbow_pitch_joint"/>
    <mechanicalReduction>50</mechanicalReduction>
    <motorTorqueConstant>1</motorTorqueConstant>
    <pulsesPerRevolution>10000</pulsesPerRevolution>
  </transmission>
  <link name="mico_lower_arm_link">
    <inertial>
      <!-- fnh -->
      <origin xyz="0 0 0"/>
      <mass value="0.8"/>
      <inertia ixx="1" ixy="0" ixz="0" iyy="1" iyz="0" izz="1"/>
    </inertial>
    <visual>
      <material name="JacoGrey"/>
      <origin rpy="3.14159265359 0 3.14159265359" xyz="0 0 -0.012"/>
      <geometry>
        <mesh filename="package://jaco_model/meshes/jaco_elbow_pitch_joint.dae" scale="1 0.601463414634 1"/>
      </geometry>
    </visual>
    <collision>
      <origin rpy="3.14159265359 0 3.14159265359" xyz="0 0 -0.012"/>
      <geometry>
        <mesh filename="package://jaco_model/meshes/jaco_elbow_pitch_joint.dae" scale="1 0.601463414634 1"/>
      </geometry>
    </collision>
  </link>
  <gazebo reference="mico_lower_arm_link">
    <!-- fnh -->
    <material>Gazebo/Grey</material>
    <turnGravityOff>false</turnGravityOff>
    <selfCollide>true</selfCollide>
    <mu1>100.0</mu1>
    <mu2>100.0</mu2>
    <kp>1000000.0</kp>
    <kd>1.0</kd>
  </gazebo>
  <joint name="mico_elbow_roll_joint" type="revolute">
    <origin rpy="-1.57079632679 0 0" xyz="0 0.165571 0 "/>
    <axis xyz="0 0 1"/>
    <parent link="mico_lower_arm_link"/>
    <child link="mico_lower_arm_roll_link"/>
    <limit effort="40" lower="-3.04159265359" upper="3.04159265359" velocity="1.04719752"/>
    <dynamics damping="50.5"/>
  </joint>
  <transmission name="mico_elbow_roll_joint_transmission">
    <type>transmission_interface/SimpleTransmission</type>
    <actuator name="mico_elbow_roll_joint_motor">
      <hardwareInterface>EffortJointInterface</hardwareInterface>
      <mechanicalReduction>50</mechanicalReduction>
    </actuator>
    <joint name="mico_elbow_roll_joint"/>
    <mechanicalReduction>50</mechanicalReduction>
    <motorTorqueConstant>1</motorTorqueConstant>
    <pulsesPerRevolution>10000</pulsesPerRevolution>
  </transmission>
  <link name="mico_lower_arm_roll_link">
    <inertial>
      <!-- fnh -->
      <origin xyz="0 0 0"/>
      <mass value="0.5"/>
      <inertia ixx="1" ixy="0" ixz="0" iyy="1" iyz="0" izz="1"/>
    </inertial>
    <visual>
      <material name="JacoGrey"/>
      <origin rpy="3.14159265359 0 1.57079632679" xyz="0 0 -0.04227"/>
      <geometry>
        <mesh filename="package://jaco_model/meshes/jaco_elbow_roll_joint.dae"/>
      </geometry>
    </visual>
    <collision>
      <origin rpy="3.14159265359 0 1.57079632679" xyz="0 0 -0.04227"/>
      <geometry>
        <mesh filename="package://jaco_model/meshes/jaco_elbow_roll_joint.dae"/>
      </geometry>
    </collision>
  </link>
  <gazebo reference="mico_lower_arm_roll_link">
    <!-- fnh -->
    <material>Gazebo/Grey</material>
    <turnGravityOff>false</turnGravityOff>
    <selfCollide>true</selfCollide>
    <mu1>100.0</mu1>
    <mu2>100.0</mu2>
    <kp>1000000.0</kp>
    <kd>1.0</kd>
  </gazebo>
  <joint name="mico_wrist_roll_joint" type="revolute">
    <origin rpy="0.959931088597 0 0" xyz="0 -0.0692622919853 0.0484979789618"/>
    <axis xyz="0 0 1"/>
    <parent link="mico_lower_arm_roll_link"/>
    <child link="mico_wrist_link"/>
    <limit effort="40" lower="-3.04159265359" upper="3.04159265359" velocity="1.04719752"/>
    <dynamics damping="50.5"/>
  </joint>
  <transmission name="mico_wrist_roll_joint_transmission">
    <type>transmission_interface/SimpleTransmission</type>
    <actuator name="mico_wrist_roll_joint_motor">
      <hardwareInterface>EffortJointInterface</hardwareInterface>
      <mechanicalReduction>50</mechanicalReduction>
    </actuator>
    <joint name="mico_wrist_roll_joint"/>
    <mechanicalReduction>50</mechanicalReduction>
    <motorTorqueConstant>1</motorTorqueConstant>
    <pulsesPerRevolution>10000</pulsesPerRevolution>
  </transmission>
  <link name="mico_wrist_link">
    <inertial>
      <!-- fnh -->
      <origin xyz="0 0 0"/>
      <mass value="0.5"/>
      <inertia ixx="1" ixy="0" ixz="0" iyy="1" iyz="0" izz="1"/>
    </inertial>
    <visual>
      <material name="JacoGrey"/>
      <origin rpy="0 3.14159265359 -1.57079632679" xyz="0 0 -0.0422768230075"/>
      <geometry>
        <mesh filename="package://jaco_model/meshes/jaco_wrist_roll_joint.dae"/>
      </geometry>
    </visual>
    <collision>
      <origin rpy="0 3.14159265359 -1.57079632679" xyz="0 0 -0.0422768230075"/>
      <geometry>
        <mesh filename="package://jaco_model/meshes/jaco_wrist_roll_joint.dae"/>
      </geometry>
    </collision>
  </link>
  <gazebo reference="mico_wrist_link">
    <!-- fnh -->
    <material>Gazebo/Grey</material>
    <turnGravityOff>false</turnGravityOff>
    <selfCollide>true</selfCollide>
    <mu1>100.0</mu1>
    <mu2>100.0</mu2>
    <kp>1000000.0</kp>
    <kd>1.0</kd>
  </gazebo>
  <joint name="mico_hand_roll_joint" type="revolute">
    <origin rpy="0.959931088597 0 0" xyz="0 -0.186174274186 0.130360630206"/>
    <axis xyz="0 0 1"/>
    <parent link="mico_wrist_link"/>
    <child link="mico_hand_link"/>
    <limit effort="40" lower="-1.67079632679" upper="4.52703501382" velocity="1.04719752"/>
    <dynamics damping="50.5"/>
  </joint>
  <transmission name="mico_hand_roll_joint_transmission">
    <type>transmission_interface/SimpleTransmission</type>
    <actuator name="mico_hand_roll_joint_motor">
      <hardwareInterface>EffortJointInterface</hardwareInterface>
      <mechanicalReduction>50</mechanicalReduction>
    </actuator>
    <joint name="mico_hand_roll_joint"/>
    <mechanicalReduction>50</mechanicalReduction>
    <motorTorqueConstant>1</motorTorqueConstant>
    <pulsesPerRevolution>10000</pulsesPerRevolution>
  </transmission>
  <link name="mico_hand_link">
    <inertial>
      <!-- fnh -->
      <origin xyz="0 0 0"/>
      <mass value="0.6"/>
      <inertia ixx="1" ixy="0" ixz="0" iyy="1" iyz="0" izz="1"/>
    </inertial>
    <visual>
      <material name="JacoGrey"/>
      <origin rpy="0 0 -3.14159265359" xyz="0 0 -0.185"/>
      <geometry>
        <mesh filename="package://jaco_model/meshes/jaco_hand_roll_joint.dae"/>
      </geometry>
    </visual>
    <collision>
      <origin rpy="0 0 -3.14159265359" xyz="0 0 -0.185"/>
      <geometry>
        <!--<mesh filename="package://jaco_model/meshes/jaco_hand_roll_joint.stl" scale="0.9 0.9 0.7" />  fnh -->
        <mesh filename="package://jaco_model/meshes/jaco_hand_roll_joint.dae"/>
      </geometry>
    </collision>
  </link>
  <gazebo reference="mico_hand_link">
    <!-- fnh -->
    <material>Gazebo/Grey</material>
    <turnGravityOff>false</turnGravityOff>
    <selfCollide>true</selfCollide>
    <mu1>100.0</mu1>
    <mu2>100.0</mu2>
    <kp>1000000.0</kp>
    <kd>1.0</kd>
  </gazebo>
  <joint name="mico_finger_1_joint" type="revolute">
    <!-- <origin xyz="-0.036 0.021 ${-0.07}" rpy="0 ${-M_PI/7} 0"/> -->
    <origin rpy="0 -0.448798950513 0" xyz="-0.036 0.021 -0.07"/>
    <axis xyz="0 1 0"/>
    <parent link="mico_hand_link"/>
    <child link="mico_finger_1_link"/>
    <limit effort="10" lower="-0.1" upper="1.04719752" velocity="1.0"/>
    <dynamics damping="50.5"/>
  </joint>
  <transmission name="mico_finger_1_joint_transmission">
    <type>transmission_interface/SimpleTransmission</type>
    <actuator name="mico_finger_1_joint_motor">
      <hardwareInterface>EffortJointInterface</hardwareInterface>
      <mechanicalReduction>50</mechanicalReduction>
    </actuator>
    <joint name="mico_finger_1_joint"/>
    <mechanicalReduction>50</mechanicalReduction>
    <motorTorqueConstant>1</motorTorqueConstant>
    <pulsesPerRevolution>10000</pulsesPerRevolution>
  </transmission>
  <link name="mico_finger_1_link">
    <inertial>
      <!-- fnh -->
      <origin xyz="0 0 0"/>
      <mass value="0.1"/>
      <inertia ixx="1" ixy="0" ixz="0" iyy="1" iyz="0" izz="1"/>
    </inertial>
    <visual>
      <material name="JacoGrey"/>
      <origin rpy="0 0 0" xyz="0 0 0"/>
      <geometry>
        <mesh filename="package://jaco_model/meshes/finger_new.dae"/>
      </geometry>
    </visual>
    <collision>
      <origin rpy="0 0 0" xyz="0 0 0"/>
      <geometry>
        <mesh filename="package://jaco_model/meshes/finger_new.dae"/>
      </geometry>
    </collision>
  </link>
  <gazebo reference="mico_finger_1_link">
    <!-- fnh -->
    <material>Gazebo/Grey</material>
    <turnGravityOff>false</turnGravityOff>
    <selfCollide>true</selfCollide>
    <mu1>100.0</mu1>
    <mu2>100.0</mu2>
    <kp>1000000.0</kp>
    <kd>1.0</kd>
  </gazebo>
  <joint name="mico_finger_2_joint" type="revolute">
    <origin rpy="0 -0.448798950513 -3.14159265359" xyz="0.036 -0 -0.07"/>
    <axis xyz="0 1 0"/>
    <parent link="mico_hand_link"/>
    <child link="mico_finger_2_link"/>
    <limit effort="10" lower="-0.1" upper="1.04719752" velocity="1.0"/>
    <dynamics damping="50.5"/>
  </joint>
  <transmission name="mico_finger_2_joint_transmission">
    <type>transmission_interface/SimpleTransmission</type>
    <actuator name="mico_finger_2_joint_motor">
      <hardwareInterface>EffortJointInterface</hardwareInterface>
      <mechanicalReduction>50</mechanicalReduction>
    </actuator>
    <joint name="mico_finger_2_joint"/>
    <mechanicalReduction>50</mechanicalReduction>
    <motorTorqueConstant>1</motorTorqueConstant>
    <pulsesPerRevolution>10000</pulsesPerRevolution>
  </transmission>
  <link name="mico_finger_2_link">
    <inertial>
      <!-- fnh -->
      <origin xyz="0 0 0"/>
      <mass value="0.1"/>
      <inertia ixx="1" ixy="0" ixz="0" iyy="1" iyz="0" izz="1"/>
    </inertial>
    <visual>
      <material name="JacoGrey"/>
      <origin rpy="0 0 0" xyz="0 0 0"/>
      <geometry>
        <mesh filename="package://jaco_model/meshes/finger_new.dae"/>
      </geometry>
    </visual>
    <collision>
      <origin rpy="0 0 0" xyz="0 0 0"/>
      <geometry>
        <mesh filename="package://jaco_model/meshes/finger_new.dae"/>
      </geometry>
    </collision>
  </link>
  <gazebo reference="mico_finger_2_link">
    <!-- fnh -->
    <material>Gazebo/Grey</material>
    <turnGravityOff>false</turnGravityOff>
    <selfCollide>true</selfCollide>
    <mu1>100.0</mu1>
    <mu2>100.0</mu2>
    <kp>1000000.0</kp>
    <kd>1.0</kd>
  </gazebo>
  <joint name="mico_finger_3_joint" type="revolute">
    <origin rpy="0 -0.448798950513 0" xyz="-0.036 -0.021 -0.07"/>
    <axis xyz="0 1 0"/>
    <parent link="mico_hand_link"/>
    <child link="mico_finger_3_link"/>
    <limit effort="10" lower="-0.1" upper="1.04719752" velocity="1.0"/>
    <dynamics damping="50.5"/>
  </joint>
  <transmission name="mico_finger_3_joint_transmission">
    <type>transmission_interface/SimpleTransmission</type>
    <actuator name="mico_finger_3_joint_motor">
      <hardwareInterface>EffortJointInterface</hardwareInterface>
      <mechanicalReduction>50</mechanicalReduction>
    </actuator>
    <joint name="mico_finger_3_joint"/>
    <mechanicalReduction>50</mechanicalReduction>
    <motorTorqueConstant>1</motorTorqueConstant>
    <pulsesPerRevolution>10000</pulsesPerRevolution>
  </transmission>
  <link name="mico_finger_3_link">
    <inertial>
      <!-- fnh -->
      <origin xyz="0 0 0"/>
      <mass value="0.1"/>
      <inertia ixx="1" ixy="0" ixz="0" iyy="1" iyz="0" izz="1"/>
    </inertial>
    <visual>
      <material name="JacoGrey"/>
      <origin rpy="0 0 0" xyz="0 0 0"/>
      <geometry>
        <mesh filename="package://jaco_model/meshes/finger_new.dae"/>
      </geometry>
    </visual>
    <collision>
      <origin rpy="0 0 0" xyz="0 0 0"/>
      <geometry>
        <mesh filename="package://jaco_model/meshes/finger_new.dae"/>
      </geometry>
    </collision>
  </link>
  <gazebo reference="mico_finger_3_link">
    <!-- fnh -->
    <material>Gazebo/Grey</material>
    <turnGravityOff>false</turnGravityOff>
    <selfCollide>true</selfCollide>
    <mu1>100.0</mu1>
    <mu2>100.0</mu2>
    <kp>1000000.0</kp>
    <kd>1.0</kd>
  </gazebo>
  <gazebo>
    <plugin filename="libgazebo_ros_control.so" name="gazebo_ros_control">
      <robotNamespace>sudo</robotNamespace>
    </plugin>
  </gazebo>
</robot>
