<robot name="sudo" xmlns:controller="http://playerstage.sourceforge.net/gazebo/xmlschema/#controller" xmlns:interface="http://playerstage.sourceforge.net/gazebo/xmlschema/#interface" xmlns:sensor="http://playerstage.sourceforge.net/gazebo/xmlschema/#sensor" xmlns:xacro="http://www.ros.org/wiki/xacro">

<!-- Base footprint -->
<link name="base_footprint">
    <origin rpy="0 0 0" xyz="0 0 0.0"/>
</link>


<!-- Pioneer 2 Chassis -->
<link name="chassis">
    <inertial>
        <mass value="40"/>
        <!--<origin xyz="-0.05 0 0"/>-->
        <origin xyz="-0.05 0 0"/>
        <inertia ixx="1" ixy="0" ixz="0" iyy="1" iyz="0" izz="1"/>
    </inertial>
    <origin rpy="0 0 0" xyz="0 0 0"/>
    <visual name="visual">
        <origin rpy="0 0 0" xyz="0 0 0.055"/> <!-- Pioneer stands 5.5 cm above the ground -->
        <geometry>
            <mesh filename="package://sudo_description/models/pioneer2dx/meshes/chassis.dae"/>
        </geometry>
    </visual>
    <collision>
        <origin rpy="0 0 0" xyz="0 0 0.055"/>
        <geometry>
            <mesh filename="package://sudo_description/models/pioneer2dx/meshes/chassis.dae"/>
        </geometry>
    </collision>
</link>

<!-- Connection between chassis and base footprint -->
<joint name="base_footprint_to_chassis" type="fixed">
    <origin rpy="0 0 0" xyz="0 0 0.135"/> <!-- The pioneer is 16cm high -->
    <child link="chassis"/>
    <parent link="base_footprint"/>
</joint>


<!-- Right weel -->
<link name="right_wheel">
    <origin rpy="0 0 0" xyz="0 0 0"/>
    <inertial>
        <mass value="0.5"/>
        <origin xyz="0 0 0"/>
        <inertia ixx="0.012411765597" ixy="0" ixz="0" iyy="0.015218160428" iyz="0" izz="0.011763977943"/>
    </inertial>
    <visual name="visual">
        <origin xyz="0 0 0" rpy="0 0 0"/>
        <geometry>
            <cylinder length="0.05" radius="0.08"/> <!-- A single wheel has a diameter of 16 cm -->
        </geometry>
        <material name="black">
            <color rgba="0 0 0 1.0"/>
        </material>
    </visual>
    <collision>
        <origin xyz="0 0 0" rpy="0 0 0"/>
        <geometry>
            <cylinder length="0.05" radius="0.08"/>
        </geometry>
    </collision>
</link>

<!-- Connection between right wheel and chassis -->
<joint name="right_wheel_hinge" type="continuous">
    <origin rpy="-1.5707 0 0" xyz="0.1 -0.17 -0.055"/>
    <child link="right_wheel"/>
    <parent link="chassis"/>
    <axis xyz=" 0 0 1"/>
    <limit effort="100" velocity="100"/>
    <joint_properties damping="0.0" friction="0.0"/>
</joint>

<gazebo reference="right_wheel">
    <material>Gazebo/Black</material>
    <turnGravityOff>false</turnGravityOff>
    <selfCollide>true</selfCollide>
    <mu1>100.0</mu1>
    <mu2>100.0</mu2>
    <kp>1000000.0</kp>
    <kd>1.0</kd>
</gazebo>

<transmission name="right_wheel_transmission">
    <type>transmission_interface/SimpleTransmission</type>
    <actuator name="right_wheel_motor">
        <hardwareInterface>EffortJointInterface</hardwareInterface>
        <mechanicalReduction>50</mechanicalReduction>
    </actuator>
    <joint name="right_wheel_hinge"/>
    <mechanicalReduction>50</mechanicalReduction>
    <motorTorqueConstant>1</motorTorqueConstant>
    <pulsesPerRevolution>10000</pulsesPerRevolution>
</transmission>


<!-- Left wheel -->
<link name="left_wheel">
    <origin rpy="0 0 0" xyz="0 0 0"/>
    <inertial>
        <mass value="0.5"/>
        <origin xyz="0 0 0"/>
        <inertia ixx="0.012411765597" ixy="0" ixz="0" iyy="0.015218160428" iyz="0" izz="0.011763977943"/>
    </inertial>
    <visual name="visual">
        <origin xyz="0 0 0" rpy="0 0 0"/>
        <geometry>
            <cylinder length="0.05" radius="0.08"/>
        </geometry>
        <material name="black">
            <color rgba="0 0 0 1.0"/>
        </material>
    </visual>
    <collision>
        <origin xyz="0 0 0" rpy="0 0 0"/>
        <geometry>
            <cylinder length="0.05" radius="0.08"/>
        </geometry>
    </collision>
</link>

<!-- Connection between left wheel and chassis -->
<joint name="left_wheel_hinge" type="continuous">
    <origin rpy="-1.5707 0 0" xyz="0.1 0.17 -0.055"/>
    <child link="left_wheel"/>
    <parent link="chassis"/>
    <axis xyz="0 0 1"/>
    <limit effort="100" velocity="100"/>
    <joint_properties damping="0.0" friction="0.0"/>
</joint>

<gazebo reference="left_wheel">
    <material>Gazebo/Black</material>
    <turnGravityOff>false</turnGravityOff>
    <selfCollide>true</selfCollide>
    <mu1>100.0</mu1>
    <mu2>100.0</mu2>
    <kp>1000000.0</kp>
    <kd>1.0</kd>
</gazebo>
  
<transmission name="left_wheel_transmission">
    <type>transmission_interface/SimpleTransmission</type>
    <actuator name="left_wheel_motor">
        <hardwareInterface>EffortJointInterface</hardwareInterface>
        <mechanicalReduction>50</mechanicalReduction>
    </actuator>
    <joint name="left_wheel_hinge"/>
    <mechanicalReduction>50</mechanicalReduction>
    <motorTorqueConstant>1</motorTorqueConstant>
    <pulsesPerRevolution>10000</pulsesPerRevolution>
</transmission>



<!-- Gazebo diff_drive plugin -->
<gazebo> 
    <plugin filename="libgazebo_ros_diff_drive.so" name="diff_drive">
        <alwaysOn>true</alwaysOn>
        <!-- For some reason, the wheels need to be swapped otherwise turning left results in turning right -->
        <leftJoint>right_wheel_hinge</leftJoint>
        <rightJoint>left_wheel_hinge</rightJoint>
        <wheelSeparation>0.32</wheelSeparation>
        <wheelDiameter>0.11</wheelDiameter>
        <torque>50</torque>
        <commandTopic>cmd_vel</commandTopic>
        <odometryTopic>odom</odometryTopic>
        <odometryFrame>odom</odometryFrame>
        <robotBaseFrame>base_footprint</robotBaseFrame>
    </plugin>
</gazebo>



<!-- Rear right weel -->
<link name="rear_right_wheel">
    <origin rpy="0 0 0" xyz="0 0 0"/>
    <inertial>
        <mass value="0.5"/>
        <origin xyz="0 0 0"/>
        <inertia ixx="0.012411765597" ixy="0" ixz="0" iyy="0.015218160428" iyz="0" izz="0.011763977943"/>
    </inertial>
    <visual name="visual">
        <origin xyz="0 0 0" rpy="0 0 0"/>
        <geometry>
            <cylinder length="0.05" radius="0.08"/> <!-- A single wheel has a diameter of 16 cm -->
        </geometry>
        <material name="black">
            <color rgba="0 0 0 1.0"/>
        </material>
    </visual>
    <collision>
        <origin xyz="0 0 0" rpy="0 0 0"/>
        <geometry>
            <cylinder length="0.05" radius="0.08"/>
        </geometry>
    </collision>
</link>

<!-- Connection between rear right wheel and chassis -->
<joint name="rear_right_wheel_hinge" type="continuous">
    <origin rpy="-1.5707 0 0" xyz="-0.115 -0.17 -0.055"/>
    <child link="rear_right_wheel"/>
    <parent link="chassis"/>
    <axis xyz=" 0 0 1"/>
    <limit effort="100" velocity="100"/>
    <joint_properties damping="0.0" friction="0.0"/>
</joint>


<!-- Rear left wheel -->
<link name="rear_left_wheel">
    <origin rpy="0 0 0" xyz="0 0 0"/>
    <inertial>
        <mass value="0.5"/>
        <origin xyz="0 0 0"/>
        <inertia ixx="0.012411765597" ixy="0" ixz="0" iyy="0.015218160428" iyz="0" izz="0.011763977943"/>
    </inertial>
    <visual name="visual">
        <origin xyz="0 0 0" rpy="0 0 0"/>
        <geometry>
            <cylinder length="0.05" radius="0.08"/>
        </geometry>
        <material name="black">
            <color rgba="0 0 0 1.0"/>
        </material>
    </visual>
    <collision>
        <origin xyz="0 0 0" rpy="0 0 0"/>
        <geometry>
            <cylinder length="0.05" radius="0.08"/>
        </geometry>
    </collision>
</link>

<!-- Connection between rear left wheel and chassis -->
<joint name="rear_left_wheel_hinge" type="continuous">
    <origin rpy="1.5707 0 0" xyz="-0.115 0.17 -0.055"/>
    <child link="rear_left_wheel"/>
    <parent link="chassis"/>
    <axis xyz="0 0 1"/>
    <limit effort="100" velocity="100"/>
    <joint_properties damping="0.0" friction="0.0"/>
</joint>

</robot>