<?xml version="1.0" ?>
<!-- =================================================================================== -->
<!-- |    This document was autogenerated by xacro from complete_model.urdf.xacro      | -->
<!-- |    EDITING THIS FILE BY HAND IS NOT RECOMMENDED                                 | -->
<!-- =================================================================================== -->
<robot name="sudo" xmlns:controller="http://playerstage.sourceforge.net/gazebo/xmlschema/#controller" xmlns:interface="http://playerstage.sourceforge.net/gazebo/xmlschema/#interface" xmlns:sensor="http://playerstage.sourceforge.net/gazebo/xmlschema/#sensor" xmlns:xacro="http://ros.org/wiki/xacro">
  <!-- Robot base: base_link, chassis (pioneer) and left and right wheel -->
 
  
  

  <!-- Mico arm: piece of wood and arm -->
 
  <link name="metal_arm_base">
    <origin rpy="0 0 0" xyz="0 0 0"/>
    <visual name="visual">
      <origin rpy="0 0 0" xyz="0 0 0"/>
      <geometry>
        <mesh filename="package://sudo_description/models/box.dae" scale="0.15 0.2 0.035"/>
      </geometry>
      <material name="black">
        <color rgba="0 0 0 1.0"/>
      </material>
    </visual>
    <collision>
      <origin rpy="0 0 0" xyz="0 0 0"/>
      <geometry>
        <mesh filename="package://sudo_description/models/box.dae" scale="0.15 0.2 0.035"/>
      </geometry>
    </collision>
  </link>
  <gazebo reference="metal_arm_base">
    <material>Gazebo/Black</material>
  </gazebo>

  <link name="arm_base">
    <origin rpy="0 0 0" xyz="-0 0 0"/>
    <inertial>
      <mass value="200"/>
      <origin xyz="0 0 0"/>
      <inertia ixx="1" ixy="0" ixz="0" iyy="1" iyz="0" izz="1"/>
    </inertial>
  </link>
  <joint name="metal_arm_base_to_arm_base" type="fixed">
    <origin rpy=" 0 0 0" xyz="0 0 0.0775"/>
    <child link="arm_base"/>
    <parent link="metal_arm_base"/>
  </joint>
  <material name="JacoGrey">
    <color rgba="0.2 0.2 0.9 1.0"/>
  </material>
  <joint name="mico_base_joint" type="fixed">
    <origin rpy="0 0 0" xyz="0 0 0"/>
    <!-- fnh was: <origin xyz="0 0 0" rpy="0 0 0"/> -->
    <parent link="arm_base"/>
    <child link="mico_base_link"/>
  </joint>
  <link name="mico_base_link">
    <inertial>
      <!-- fnh -->
      <origin xyz="0.0018698 4.3975E-06 0.00076788"/>
      <mass value="1.0"/>
      <inertia ixx="1" ixy="0" ixz="0" iyy="1" iyz="0" izz="1"/>
    </inertial>
    <visual>
      <material name="JacoGrey"/>
      <origin rpy="0 0 0" xyz="0 0 0"/>
      <geometry>
        <mesh filename="package://jaco_model/meshesNew/jaco_base_joint.STL"/>
      </geometry>
    </visual>
    <collision>
      <origin rpy="0 0 0" xyz="0 0 0"/>
      <geometry>
        <mesh filename="package://jaco_model/meshesNew/jaco_base_joint.STL"/>
      </geometry>
    </collision>
  </link>
  <gazebo reference="mico_base_link">
    <!-- fnh -->
    <material>Gazebo/Grey</material>
    <turnGravityOff>false</turnGravityOff>
    <selfCollide>true</selfCollide>
    <mu1>100.0</mu1>
    <mu2>100.0</mu2>
    <kp>1000000.0</kp>
    <kd>1.0</kd>
  </gazebo>

  <joint name="mico_shoulder_yaw_joint" type="revolute">
    <!--<origin xyz="0 0 ${D1}" rpy="0 0 0"/>-->
    <origin rpy="-3.1416 4.3794E-14 1.8406E-28" xyz="0 0 0.09425"/>
    <axis rpy="0 0 0" xyz="0 0 1"/>
    <parent link="mico_base_link"/>
    <child link="mico_shoulder_link"/>
    <limit effort="200" lower="-3.04159265359" upper="3.04159265359" velocity="0.837758016"/>
    <dynamics damping="50.5"/>
  </joint>
  <transmission name="mico_shoulder_yaw_joint_transmission">
    <type>transmission_interface/SimpleTransmission</type>
    <actuator name="mico_shoulder_yaw_joint_motor">
      <hardwareInterface>EffortJointInterface</hardwareInterface>
      <mechanicalReduction>50</mechanicalReduction>
    </actuator>
    <joint name="mico_shoulder_yaw_joint"/>
    <mechanicalReduction>50</mechanicalReduction>
    <motorTorqueConstant>1</motorTorqueConstant>
    <pulsesPerRevolution>10000</pulsesPerRevolution>
  </transmission>
  <link name="mico_shoulder_link">
    <inertial>
      <origin xyz="9.8364E-07 0.014125 -0.070452"/>
      <mass value="1.0"/>
      <inertia ixx="1" ixy="0" ixz="0" iyy="1" iyz="0" izz="1"/>
    </inertial>
    <visual>
      <material name="JacoGrey"/>
      <origin rpy="0 0 0" xyz="0 0 0"/>
      <geometry>
        <mesh filename="package://jaco_model/meshesNew/jaco_shoulder_yaw_joint.STL"/>
      </geometry>
    </visual>
    <collision>
      <origin rpy="0 0 0" xyz="0 0 0"/>
      <geometry>
        <mesh filename="package://jaco_model/meshesNew/jaco_shoulder_yaw_joint.STL"/>
      </geometry>
    </collision>
  </link>
  <gazebo reference="mico_shoulder_link">
    <!-- fnh -->
    <material>Gazebo/Grey</material>
    <turnGravityOff>false</turnGravityOff>
    <selfCollide>true</selfCollide>
    <mu1>100.0</mu1>
    <mu2>100.0</mu2>
    <kp>1000000.0</kp>
    <kd>1.0</kd>
  </gazebo>


  <joint name="mico_shoulder_pitch_joint" type="revolute">
    <origin rpy="-1.5708 4.3794E-14 0" xyz="0 -0.00625 -0.12325"/>
    <axis xyz="0 0 1"/>
    <parent link="mico_shoulder_link"/>
    <child link="mico_upper_arm_link"/>
    <limit effort="300" lower="-3.83972424" upper="0.69813168" velocity="0.837758016"/>
    <dynamics damping="50.5"/>
  </joint>
  <transmission name="mico_shoulder_pitch_joint_transmission">
    <type>transmission_interface/SimpleTransmission</type>
    <actuator name="mico_shoulder_pitch_joint_motor">
      <hardwareInterface>EffortJointInterface</hardwareInterface>
      <mechanicalReduction>50</mechanicalReduction>
    </actuator>
    <joint name="mico_shoulder_pitch_joint"/>
    <mechanicalReduction>50</mechanicalReduction>
    <motorTorqueConstant>1</motorTorqueConstant>
    <pulsesPerRevolution>10000</pulsesPerRevolution>
  </transmission>
  <link name="mico_upper_arm_link">
    <inertial>
      <origin xyz="-1.5264E-05 0.13777 -0.021034"/>
      <mass value="1.0"/>
      <inertia ixx="1" ixy="0" ixz="0" iyy="1" iyz="0" izz="1"/>
    </inertial>
    <visual>
      <material name="JacoGrey"/>
      <origin rpy="0 0 0" xyz="0 0 0"/>
      <geometry>
        <mesh filename="package://jaco_model/meshesNew/jaco_shoulder_pitch_joint.STL"/>
      </geometry>
    </visual>
    <collision>
      <origin rpy="0 0 0" xyz="0 0 0"/>
      <geometry>
        <mesh filename="package://jaco_model/meshesNew/jaco_shoulder_pitch_joint.STL"/>
      </geometry>
    </collision>
  </link>
  <gazebo reference="mico_upper_arm_link">
    <!-- fnh -->
    <material>Gazebo/Grey</material>
    <turnGravityOff>false</turnGravityOff>
    <selfCollide>true</selfCollide>
    <mu1>100.0</mu1>
    <mu2>100.0</mu2>
    <kp>1000000.0</kp>
    <kd>1.0</kd>
  </gazebo>


  <joint name="mico_elbow_pitch_joint" type="revolute">
    <origin rpy="3.1416 0 3.1416" xyz="0 0.29 0"/>
    <axis xyz="0 0 -1"/>
    <parent link="mico_upper_arm_link"/>
    <child link="mico_lower_arm_link"/>
    <limit effort="200" lower="-4.363323" upper="1.22173044" velocity="0.837758016"/>
    <dynamics damping="50.5"/>
  </joint>
  <transmission name="mico_elbow_pitch_joint_transmission">
    <type>transmission_interface/SimpleTransmission</type>
    <actuator name="mico_elbow_pitch_joint_motor">
      <hardwareInterface>EffortJointInterface</hardwareInterface>
      <mechanicalReduction>50</mechanicalReduction>
    </actuator>
    <joint name="mico_elbow_pitch_joint"/>
    <mechanicalReduction>50</mechanicalReduction>
    <motorTorqueConstant>1</motorTorqueConstant>
    <pulsesPerRevolution>10000</pulsesPerRevolution>
  </transmission>
  <link name="mico_lower_arm_link">
    <inertial>
      <origin xyz="3.3265E-06 0.035568 -0.023918"/>
      <mass value="0.8"/>
      <inertia ixx="1" ixy="0" ixz="0" iyy="1" iyz="0" izz="1"/>
    </inertial>
    <visual>
      <material name="JacoGrey"/>
      <origin rpy="0 0 0" xyz="0 0 0"/>
      <geometry>
        <mesh filename="package://jaco_model/meshesNew/jaco_elbow_pitch_joint.STL"/>
      </geometry>
    </visual>
    <collision>
      <origin rpy="0 0 0" xyz="0 0 0"/>
      <geometry>
        <mesh filename="package://jaco_model/meshesNew/jaco_elbow_pitch_joint.STL"/>
      </geometry>
    </collision>
  </link>
  <gazebo reference="mico_lower_arm_link">
    <!-- fnh -->
    <material>Gazebo/Grey</material>
    <turnGravityOff>false</turnGravityOff>
    <selfCollide>true</selfCollide>
    <mu1>100.0</mu1>
    <mu2>100.0</mu2>
    <kp>1000000.0</kp>
    <kd>1.0</kd>
  </gazebo>


  <joint name="mico_elbow_roll_joint" type="revolute">
    <origin rpy="1.5708 -2.3904E-31 6.8996E-15" xyz="0 0.127 -0.01325"/>
    <axis xyz="0 0 -1"/>
    <parent link="mico_lower_arm_link"/>
    <child link="mico_lower_arm_roll_link"/>
    <limit effort="40" lower="-3.04159265359" upper="3.04159265359" velocity="1.04719752"/>
    <dynamics damping="50.5"/>
  </joint>
  <transmission name="mico_elbow_roll_joint_transmission">
    <type>transmission_interface/SimpleTransmission</type>
    <actuator name="mico_elbow_roll_joint_motor">
      <hardwareInterface>EffortJointInterface</hardwareInterface>
      <mechanicalReduction>50</mechanicalReduction>
    </actuator>
    <joint name="mico_elbow_roll_joint"/>
    <mechanicalReduction>50</mechanicalReduction>
    <motorTorqueConstant>1</motorTorqueConstant>
    <pulsesPerRevolution>10000</pulsesPerRevolution>
  </transmission>
  <link name="mico_lower_arm_roll_link">
    <inertial>
      <!-- fnh -->
      <origin xyz="-3.8615E-05 0.0067766 -0.027417"/>
      <mass value="0.5"/>
      <inertia ixx="1" ixy="0" ixz="0" iyy="1" iyz="0" izz="1"/>
    </inertial>
    <visual>
      <material name="JacoGrey"/>
      <origin rpy="0 0 0" xyz="0 0 0"/>
      <geometry>
        <mesh filename="package://jaco_model/meshesNew/jaco_elbow_roll_joint.STL"/>
      </geometry>
    </visual>
    <collision>
      <origin rpy="0 0 0" xyz="0 0 0"/>
      <geometry>
        <mesh filename="package://jaco_model/meshesNew/jaco_elbow_roll_joint.STL"/>
      </geometry>
    </collision>
  </link>
  <gazebo reference="mico_lower_arm_roll_link">
    <!-- fnh -->
    <material>Gazebo/Grey</material>
    <turnGravityOff>false</turnGravityOff>
    <selfCollide>true</selfCollide>
    <mu1>100.0</mu1>
    <mu2>100.0</mu2>
    <kp>1000000.0</kp>
    <kd>1.0</kd>
  </gazebo>


  <joint name="mico_wrist_roll_joint" type="revolute">
    <origin rpy="1.0472 -1.1202E-14 -7.4515E-15" xyz="0 0.040276 -0.062261"/>
    <axis xyz="0 0 1"/>
    <parent link="mico_lower_arm_roll_link"/>
    <child link="mico_wrist_link"/>
    <limit effort="40" lower="-3.04159265359" upper="3.04159265359" velocity="1.04719752"/>
    <dynamics damping="50.5"/>
  </joint>
  <transmission name="mico_wrist_roll_joint_transmission">
    <type>transmission_interface/SimpleTransmission</type>
    <actuator name="mico_wrist_roll_joint_motor">
      <hardwareInterface>EffortJointInterface</hardwareInterface>
      <mechanicalReduction>50</mechanicalReduction>
    </actuator>
    <joint name="mico_wrist_roll_joint"/>
    <mechanicalReduction>50</mechanicalReduction>
    <motorTorqueConstant>1</motorTorqueConstant>
    <pulsesPerRevolution>10000</pulsesPerRevolution>
  </transmission>
  <link name="mico_wrist_link">
    <inertial>
      <!-- fnh -->
      <origin xyz="3.8855E-05 -0.006776 -0.027417"/>
      <mass value="0.5"/>
      <inertia ixx="1" ixy="0" ixz="0" iyy="1" iyz="0" izz="1"/>
    </inertial>
    <visual>
      <material name="JacoGrey"/>
      <origin rpy="0 0 0" xyz="0 0 0"/>
      <geometry>
        <mesh filename="package://jaco_model/meshesNew/jaco_wrist_roll_joint.STL"/>
      </geometry>
    </visual>
    <collision>
      <origin rpy="0 0 0" xyz="0 0 0"/>
      <geometry>
        <mesh filename="package://jaco_model/meshesNew/jaco_wrist_roll_joint.STL"/>
      </geometry>
    </collision>
  </link>
  <gazebo reference="mico_wrist_link">
    <!-- fnh -->
    <material>Gazebo/Grey</material>
    <turnGravityOff>false</turnGravityOff>
    <selfCollide>true</selfCollide>
    <mu1>100.0</mu1>
    <mu2>100.0</mu2>
    <kp>1000000.0</kp>
    <kd>1.0</kd>
  </gazebo>


  <joint name="mico_hand_roll_joint" type="revolute">
    <origin rpy="-1.0472 4.7648E-15 6.6501E-15" xyz="0 -0.040276 -0.062261"/>
    <axis xyz="0 0 1"/>
    <parent link="mico_wrist_link"/>
    <child link="mico_hand_link"/>
    <limit effort="40" lower="-1.67079632679" upper="4.52703501382" velocity="1.04719752"/>
    <dynamics damping="50.5"/>
  </joint>
  <transmission name="mico_hand_roll_joint_transmission">
    <type>transmission_interface/SimpleTransmission</type>
    <actuator name="mico_hand_roll_joint_motor">
      <hardwareInterface>EffortJointInterface</hardwareInterface>
      <mechanicalReduction>50</mechanicalReduction>
    </actuator>
    <joint name="mico_hand_roll_joint"/>
    <mechanicalReduction>50</mechanicalReduction>
    <motorTorqueConstant>1</motorTorqueConstant>
    <pulsesPerRevolution>10000</pulsesPerRevolution>
  </transmission>
  <link name="mico_hand_link">
    <inertial>
      <!-- fnh -->
      <origin xyz="-0.0014195 7.8354E-06 -0.066076"/>
      <mass value="0.6"/>
      <inertia ixx="1" ixy="0" ixz="0" iyy="1" iyz="0" izz="1"/>
    </inertial>
    <visual>
      <material name="JacoGrey"/>
      <origin rpy="0 0 0" xyz="0 0 0"/>
      <geometry>
        <mesh filename="package://jaco_model/meshesNew/jaco_hand_roll_joint.STL"/>
      </geometry>
    </visual>
    <collision>
      <origin rpy="0 0 0" xyz="0 0 0"/>
      <geometry>
        <mesh filename="package://jaco_model/meshesNew/jaco_hand_roll_joint.STL"/>
      </geometry>
    </collision>
  </link>
  <gazebo reference="mico_hand_link">
    <!-- fnh -->
    <material>Gazebo/Grey</material>
    <turnGravityOff>false</turnGravityOff>
    <selfCollide>true</selfCollide>
    <mu1>100.0</mu1>
    <mu2>100.0</mu2>
    <kp>1000000.0</kp>
    <kd>1.0</kd>
  </gazebo>

 <link name="Finger_1_Proximal_Link">
    <inertial>
      <origin
        xyz="0.0172616572113394 0.0105538611465319 -0.0112506191776746"
        rpy="0 0 0" />
      <mass
        value="0.0106365214895162" />
      <inertia
        ixx="2.41074761126296E-06"
        ixy="6.22421954028106E-07"
        ixz="-2.46521467551818E-11"
        iyy="1.51566092378154E-06"
        iyz="4.24681773393991E-11"
        izz="2.54988112393165E-06" />
    </inertial>
    <visual>
      <origin
        xyz="0 0 0"
        rpy="0 0 0" />
      <geometry>
        <mesh
          filename="package://jaco_model/meshesNew/Finger_1_Proximal_Link.STL" />
      </geometry>
    </visual>
    <collision>
      <origin
        xyz="0 0 0"
        rpy="0 0 0" />
      <geometry>
        <mesh
          filename="package://jaco_model/meshesNew/Finger_1_Proximal_Link.STL" />
      </geometry>
    </collision>
  </link>
 <gazebo reference="Finger_1_Proximal_Link">
    <!-- fnh -->
    <material>Gazebo/Grey</material>
    <turnGravityOff>false</turnGravityOff>
    <selfCollide>true</selfCollide>
    <mu1>100.0</mu1>
    <mu2>100.0</mu2>
    <kp>1000000.0</kp>
    <kd>1.0</kd>
  </gazebo>
  <joint
    name="Finger_1_Proximal_Joint"
    type="revolute">
    <origin
      xyz="-0.013746 0.030948 -0.11107"
      rpy="-1.5708 3.3457E-16 1.5708" />
    <parent
      link="mico_hand_link" />
    <child
      link="Finger_1_Proximal_Link" />
    <axis
      xyz="0 0 1" />
    <limit
      lower="0"
      upper="0.78"
      effort="0"
      velocity="0" />
  </joint>
 <transmission name="Finger_1_Proximal_Joint_transmission">
    <type>transmission_interface/SimpleTransmission</type>
    <actuator name="Finger_1_Proximal_Joint_motor">
      <hardwareInterface>EffortJointInterface</hardwareInterface>
      <mechanicalReduction>50</mechanicalReduction>
    </actuator>
    <joint name="Finger_1_Proximal_Joint"/>
    <mechanicalReduction>50</mechanicalReduction>
    <motorTorqueConstant>1</motorTorqueConstant>
    <pulsesPerRevolution>10000</pulsesPerRevolution>
  </transmission>

  <link name="Finger_1_Distal_Link">
    <inertial>
      <origin
        xyz="0.0126210373400246 0.00643480436760779 -0.0112500681940836"
        rpy="0 0 0" />
      <mass
        value="0.0121939442358921" />
      <inertia
        ixx="1.65156773375087E-06"
        ixy="9.54167272729886E-07"
        ixz="-1.00860347569415E-11"
        iyy="1.49606028082548E-06"
        iyz="-1.22490314303896E-11"
        izz="2.37956623675183E-06" />
    </inertial>
    <visual>
      <origin
        xyz="0 0 0"
        rpy="0 0 0" />
      <geometry>
        <mesh
          filename="package://jaco_model/meshesNew/Finger_1_Distal_Link.STL" />
      </geometry>
    </visual>
    <collision>
      <origin
        xyz="0 0 0"
        rpy="0 0 0" />
      <geometry>
        <mesh
          filename="package://jaco_model/meshesNew/Finger_1_Distal_Link.STL" />
      </geometry>
    </collision>
  </link>
  <gazebo reference="Finger_1_Distal_Link">
    <!-- fnh -->
    <material>Gazebo/Grey</material>
    <turnGravityOff>false</turnGravityOff>
    <selfCollide>true</selfCollide>
    <mu1>100.0</mu1>
    <mu2>100.0</mu2>
    <kp>1000000.0</kp>
    <kd>1.0</kd>
  </gazebo>
  <joint
    name="Finger_1_Distal_Joint"
    type="revolute">
    <origin
      xyz="0.026055 0.035582 0"
      rpy="-4.0279E-17 6.1154E-17 -4.7179E-31" />
    <parent
      link="Finger_1_Proximal_Link" />
    <child
      link="Finger_1_Distal_Link" />
    <axis
      xyz="0 0 -1" />
    <limit
      lower="0"
      upper="0.78"
      effort="0"
      velocity="0" />
  </joint>
 <transmission name="Finger_1_Distal_Joint_transmission">
    <type>transmission_interface/SimpleTransmission</type>
    <actuator name="Finger_1_Distal_Joint_motor">
      <hardwareInterface>EffortJointInterface</hardwareInterface>
      <mechanicalReduction>50</mechanicalReduction>
    </actuator>
    <joint name="Finger_1_Distal_Joint"/>
    <mechanicalReduction>50</mechanicalReduction>
    <motorTorqueConstant>1</motorTorqueConstant>
    <pulsesPerRevolution>10000</pulsesPerRevolution>
  </transmission>


<link
    name="Finger_2_Proximal_Link">
    <inertial>
      <origin
        xyz="-0.0172616584345737 -0.0105538552511416 0.0112493808527515"
        rpy="0 0 0" />
      <mass
        value="0.0106365251828778" />
      <inertia
        ixx="2.41074854318984E-06"
        ixy="6.22421733493864E-07"
        ixz="2.47092382285307E-11"
        iyy="1.51566070025321E-06"
        iyz="-4.24941314480507E-11"
        izz="2.54988230315087E-06" />
    </inertial>
    <visual>
      <origin
        xyz="0 0 0"
        rpy="0 0 0" />
      <geometry>
        <mesh
          filename="package://jaco_model/meshesNew/Finger_2_Proximal_Link.STL" />
      </geometry>
      <material
        name="">
        <color
          rgba="0.792156862745098 0.819607843137255 0.933333333333333 1" />
      </material>
    </visual>
    <collision>
      <origin
        xyz="0 0 0"
        rpy="0 0 0" />
      <geometry>
        <mesh
          filename="package://jaco_model/meshesNew/Finger_2_Proximal_Link.STL" />
      </geometry>
    </collision>
  </link>
<gazebo reference="Finger_2_Proximal_Link">
    <!-- fnh -->
    <material>Gazebo/Grey</material>
    <turnGravityOff>false</turnGravityOff>
    <selfCollide>true</selfCollide>
    <mu1>100.0</mu1>
    <mu2>100.0</mu2>
    <kp>1000000.0</kp>
    <kd>1.0</kd>
  </gazebo>
  <joint
    name="Finger_2_Proximal_Joint"
    type="revolute">
    <origin
      xyz="-0.013746 -0.030948 -0.11107"
      rpy="1.5708 3.3457E-16 1.5708" />
    <parent
      link="mico_hand_link" />
    <child
      link="Finger_2_Proximal_Link" />
    <axis
      xyz="0 0 1" />
    <limit
      lower="0"
      upper="0.78"
      effort="0"
      velocity="0" />
  </joint>
<transmission name="Finger_2_Proximal_Joint_transmission">
    <type>transmission_interface/SimpleTransmission</type>
    <actuator name="Finger_2_Proximal_Joint_motor">
      <hardwareInterface>EffortJointInterface</hardwareInterface>
      <mechanicalReduction>50</mechanicalReduction>
    </actuator>
    <joint name="Finger_2_Proximal_Joint"/>
    <mechanicalReduction>50</mechanicalReduction>
    <motorTorqueConstant>1</motorTorqueConstant>
    <pulsesPerRevolution>10000</pulsesPerRevolution>
  </transmission>

  <link name="Finger_2_Distal_Link">
    <inertial>
      <origin
        xyz="-0.0126210373425155 -0.00643480437565225 0.0112499318045061"
        rpy="0 0 0" />
      <mass
        value="0.012193944229752" />
      <inertia
        ixx="1.65156773202737E-06"
        ixy="9.54167272215506E-07"
        ixz="1.00859417239942E-11"
        iyy="1.49606028060199E-06"
        iyz="1.22487380227665E-11"
        izz="2.37956623494218E-06" />
    </inertial>
    <visual>
      <origin
        xyz="0 0 0"
        rpy="0 0 0" />
      <geometry>
        <mesh
          filename="package://jaco_model/meshesNew/Finger_2_Distal_Link.STL" />
      </geometry>
      <material
        name="">
        <color
          rgba="0.792156862745098 0.819607843137255 0.933333333333333 1" />
      </material>
    </visual>
    <collision>
      <origin
        xyz="0 0 0"
        rpy="0 0 0" />
      <geometry>
        <mesh
          filename="package://jaco_model/meshesNew/Finger_2_Distal_Link.STL" />
      </geometry>
    </collision>
  </link>
<gazebo reference="Finger_2_Distal_Link">
    <!-- fnh -->
    <material>Gazebo/Grey</material>
    <turnGravityOff>false</turnGravityOff>
    <selfCollide>true</selfCollide>
    <mu1>100.0</mu1>
    <mu2>100.0</mu2>
    <kp>1000000.0</kp>
    <kd>1.0</kd>
  </gazebo>
  <joint
    name="Finger_2_Distal_Joint"
    type="revolute">
    <origin
      xyz="-0.026055 -0.035582 0"
      rpy="4.8081E-17 -4.6577E-17 -5.6023E-31" />
    <parent
      link="Finger_2_Proximal_Link" />
    <child
      link="Finger_2_Distal_Link" />
    <axis
      xyz="0 0 -1" />
    <limit
      lower="0"
      upper="0.78"
      effort="0"
      velocity="0" />
  </joint>
<transmission name="Finger_2_Distal_Joint_transmission">
    <type>transmission_interface/SimpleTransmission</type>
    <actuator name="Finger_2_Distal_Joint_motor">
      <hardwareInterface>EffortJointInterface</hardwareInterface>
      <mechanicalReduction>50</mechanicalReduction>
    </actuator>
    <joint name="Finger_2_Distal_Joint"/>
    <mechanicalReduction>50</mechanicalReduction>
    <motorTorqueConstant>1</motorTorqueConstant>
    <pulsesPerRevolution>10000</pulsesPerRevolution>
  </transmission>



  <gazebo>
    <plugin filename="libgazebo_ros_control.so" name="gazebo_ros_control">
      <robotNamespace>/sudo</robotNamespace>
    </plugin>
  </gazebo>
</robot>
