<?xml version="1.0" ?>
<!-- =================================================================================== -->
<!-- |    This document was autogenerated by xacro from complete_model.urdf.xacro      | -->
<!-- |    EDITING THIS FILE BY HAND IS NOT RECOMMENDED                                 | -->
<!-- =================================================================================== -->
<robot name="sudo" xmlns:controller="http://playerstage.sourceforge.net/gazebo/xmlschema/#controller" xmlns:interface="http://playerstage.sourceforge.net/gazebo/xmlschema/#interface" xmlns:sensor="http://playerstage.sourceforge.net/gazebo/xmlschema/#sensor" xmlns:xacro="http://ros.org/wiki/xacro">
  <!-- Robot base: base_link, chassis (pioneer) and left and right wheel -->
 
  
  

  <!-- Mico arm: piece of wood and arm -->
 
  <link name="metal_arm_base">
    <origin rpy="0 0 0" xyz="0 0 0"/>
    <visual name="visual">
      <origin rpy="0 0 0" xyz="0 0 0"/>
      <geometry>
        <mesh filename="package://sudo_description/models/box.dae" scale="0.15 0.2 0.035"/>
      </geometry>
      <material name="black">
        <color rgba="0 0 0 1.0"/>
      </material>
    </visual>
    <collision>
      <origin rpy="0 0 0" xyz="0 0 0"/>
      <geometry>
        <mesh filename="package://sudo_description/models/box.dae" scale="0.15 0.2 0.035"/>
      </geometry>
    </collision>
  </link>
  <gazebo reference="metal_arm_base">
    <material>Gazebo/Black</material>
  </gazebo>

  <link name="arm_base">
    <origin rpy="0 0 0" xyz="-0 0 0"/>
    <inertial>
      <mass value="200"/>
      <origin xyz="0 0 0"/>
      <inertia ixx="1" ixy="0" ixz="0" iyy="1" iyz="0" izz="1"/>
    </inertial>
  </link>
  <joint name="metal_arm_base_to_arm_base" type="fixed">
    <origin rpy=" 0 0 1.57" xyz="0 0 0.0775"/>
    <child link="arm_base"/>
    <parent link="metal_arm_base"/>
  </joint>
  <material name="JacoGrey">
    <color rgba="0.2 0.2 0.9 1.0"/>
  </material>
  <joint name="mico_base_joint" type="fixed">
    <origin rpy="0 0 0" xyz="0 0 0"/>
    <!-- fnh was: <origin xyz="0 0 0" rpy="0 0 0"/> -->
    <parent link="arm_base"/>
    <child link="mico_base_link"/>
  </joint>
  <link name="mico_base_link">
    <inertial>
      <!-- fnh -->
      <origin xyz="0 0 0"/>
      <mass value="1.0"/>
      <inertia ixx="1" ixy="0" ixz="0" iyy="1" iyz="0" izz="1"/>
    </inertial>
    <visual>
      <material name="JacoGrey"/>
      <origin rpy="0 0 1.57079632679" xyz="0 0 0"/>
      <geometry>
        <mesh filename="package://jaco_model/meshes/jaco_base_joint.dae"/>
      </geometry>
    </visual>
    <collision>
      <origin rpy="0 0 1.57079632679" xyz="0 0 0"/>
      <geometry>
        <mesh filename="package://jaco_model/meshes/jaco_base_joint.dae"/>
      </geometry>
    </collision>
  </link>
  <gazebo reference="mico_base_link">
    <!-- fnh -->
    <material>Gazebo/Grey</material>
    <turnGravityOff>false</turnGravityOff>
    <selfCollide>true</selfCollide>
    <mu1>100.0</mu1>
    <mu2>100.0</mu2>
    <kp>1000000.0</kp>
    <kd>1.0</kd>
  </gazebo>
  <joint name="mico_shoulder_yaw_joint" type="revolute">
    <!--<origin xyz="0 0 ${D1}" rpy="0 0 0"/>-->
    <origin rpy="0 0 0" xyz="0 0 0.2142"/>
    <axis rpy="0 0 0" xyz="0 0 1"/>
    <parent link="mico_base_link"/>
    <child link="mico_shoulder_link"/>
    <limit effort="200" lower="-3.04159265359" upper="3.04159265359" velocity="0.837758016"/>
    <dynamics damping="50.5"/>
  </joint>
  <transmission name="mico_shoulder_yaw_joint_transmission">
    <type>transmission_interface/SimpleTransmission</type>
    <actuator name="mico_shoulder_yaw_joint_motor">
      <hardwareInterface>EffortJointInterface</hardwareInterface>
      <mechanicalReduction>50</mechanicalReduction>
    </actuator>
    <joint name="mico_shoulder_yaw_joint"/>
    <mechanicalReduction>50</mechanicalReduction>
    <motorTorqueConstant>1</motorTorqueConstant>
    <pulsesPerRevolution>10000</pulsesPerRevolution>
  </transmission>
  <link name="mico_shoulder_link">
    <inertial>
      <!-- fnh -->
      <origin xyz="0 0 0"/>
      <mass value="1.0"/>
      <inertia ixx="1" ixy="0" ixz="0" iyy="1" iyz="0" izz="1"/>
    </inertial>
    <visual>
      <material name="JacoGrey"/>
      <origin rpy="1.57079632679 -1.57079632679 0" xyz="0 0 0"/>
      <geometry>
        <mesh filename="package://jaco_model/meshes/jaco_shoulder_yaw_joint.dae"/>
      </geometry>
    </visual>
    <collision>
      <origin rpy="1.57079632679 -1.57079632679 0" xyz="0 0 0"/>
      <geometry>
        <mesh filename="package://jaco_model/meshes/jaco_shoulder_yaw_joint.dae"/>
      </geometry>
    </collision>
  </link>
  <gazebo reference="mico_shoulder_link">
    <!-- fnh -->
    <material>Gazebo/Grey</material>
    <turnGravityOff>false</turnGravityOff>
    <selfCollide>true</selfCollide>
    <mu1>100.0</mu1>
    <mu2>100.0</mu2>
    <kp>1000000.0</kp>
    <kd>1.0</kd>
  </gazebo>
  <joint name="mico_shoulder_pitch_joint" type="revolute">
    <origin rpy="-1.57079632679 0 0" xyz="0 -1e-06 0"/>
    <axis xyz="0 0 1"/>
    <parent link="mico_shoulder_link"/>
    <child link="mico_upper_arm_link"/>
    <limit effort="300" lower="-3.83972424" upper="0.69813168" velocity="0.837758016"/>
    <dynamics damping="50.5"/>
  </joint>
  <transmission name="mico_shoulder_pitch_joint_transmission">
    <type>transmission_interface/SimpleTransmission</type>
    <actuator name="mico_shoulder_pitch_joint_motor">
      <hardwareInterface>EffortJointInterface</hardwareInterface>
      <mechanicalReduction>50</mechanicalReduction>
    </actuator>
    <joint name="mico_shoulder_pitch_joint"/>
    <mechanicalReduction>50</mechanicalReduction>
    <motorTorqueConstant>1</motorTorqueConstant>
    <pulsesPerRevolution>10000</pulsesPerRevolution>
  </transmission>
  <link name="mico_upper_arm_link">
    <inertial>
      <!-- fnh -->
      <origin xyz="0 0 0"/>
      <mass value="1.0"/>
      <inertia ixx="1" ixy="0" ixz="0" iyy="1" iyz="0" izz="1"/>
    </inertial>
    <visual>
      <material name="JacoGrey"/>
      <origin rpy="0 0 -1.57079632679" xyz="0 0 0"/>
      <geometry>
        <mesh filename="package://jaco_model/meshes/jaco_shoulder_pitch_joint.dae" scale="1 0.707317073171 1"/>
      </geometry>
    </visual>
    <collision>
      <origin rpy="0 0 -1.57079632679" xyz="0 0 0"/>
      <geometry>
        <mesh filename="package://jaco_model/meshes/jaco_shoulder_pitch_joint.dae" scale="1 0.707317073171 1"/>
      </geometry>
    </collision>
  </link>
  <gazebo reference="mico_upper_arm_link">
    <!-- fnh -->
    <material>Gazebo/Grey</material>
    <turnGravityOff>false</turnGravityOff>
    <selfCollide>true</selfCollide>
    <mu1>100.0</mu1>
    <mu2>100.0</mu2>
    <kp>1000000.0</kp>
    <kd>1.0</kd>
  </gazebo>
  <joint name="mico_elbow_pitch_joint" type="revolute">
    <origin rpy="0 0 0" xyz="0.29 0 0.012001"/>
    <axis xyz="0 0 1"/>
    <parent link="mico_upper_arm_link"/>
    <child link="mico_lower_arm_link"/>
    <limit effort="200" lower="-4.363323" upper="1.22173044" velocity="0.837758016"/>
    <dynamics damping="50.5"/>
  </joint>
  <transmission name="mico_elbow_pitch_joint_transmission">
    <type>transmission_interface/SimpleTransmission</type>
    <actuator name="mico_elbow_pitch_joint_motor">
      <hardwareInterface>EffortJointInterface</hardwareInterface>
      <mechanicalReduction>50</mechanicalReduction>
    </actuator>
    <joint name="mico_elbow_pitch_joint"/>
    <mechanicalReduction>50</mechanicalReduction>
    <motorTorqueConstant>1</motorTorqueConstant>
    <pulsesPerRevolution>10000</pulsesPerRevolution>
  </transmission>
  <link name="mico_lower_arm_link">
    <inertial>
      <!-- fnh -->
      <origin xyz="0 0 0"/>
      <mass value="0.8"/>
      <inertia ixx="1" ixy="0" ixz="0" iyy="1" iyz="0" izz="1"/>
    </inertial>
    <visual>
      <material name="JacoGrey"/>
      <origin rpy="3.14159265359 0 3.14159265359" xyz="0 0 -0.012"/>
      <geometry>
        <mesh filename="package://jaco_model/meshes/jaco_elbow_pitch_joint.dae" scale="1 0.601463414634 1"/>
      </geometry>
    </visual>
    <collision>
      <origin rpy="3.14159265359 0 3.14159265359" xyz="0 0 -0.012"/>
      <geometry>
        <mesh filename="package://jaco_model/meshes/jaco_elbow_pitch_joint.dae" scale="1 0.601463414634 1"/>
      </geometry>
    </collision>
  </link>
  <gazebo reference="mico_lower_arm_link">
    <!-- fnh -->
    <material>Gazebo/Grey</material>
    <turnGravityOff>false</turnGravityOff>
    <selfCollide>true</selfCollide>
    <mu1>100.0</mu1>
    <mu2>100.0</mu2>
    <kp>1000000.0</kp>
    <kd>1.0</kd>
  </gazebo>
  <joint name="mico_elbow_roll_joint" type="revolute">
    <origin rpy="-1.57079632679 0 0" xyz="0 0.165571 0 "/>
    <axis xyz="0 0 1"/>
    <parent link="mico_lower_arm_link"/>
    <child link="mico_lower_arm_roll_link"/>
    <limit effort="40" lower="-3.04159265359" upper="3.04159265359" velocity="1.04719752"/>
    <dynamics damping="50.5"/>
  </joint>
  <transmission name="mico_elbow_roll_joint_transmission">
    <type>transmission_interface/SimpleTransmission</type>
    <actuator name="mico_elbow_roll_joint_motor">
      <hardwareInterface>EffortJointInterface</hardwareInterface>
      <mechanicalReduction>50</mechanicalReduction>
    </actuator>
    <joint name="mico_elbow_roll_joint"/>
    <mechanicalReduction>50</mechanicalReduction>
    <motorTorqueConstant>1</motorTorqueConstant>
    <pulsesPerRevolution>10000</pulsesPerRevolution>
  </transmission>
  <link name="mico_lower_arm_roll_link">
    <inertial>
      <!-- fnh -->
      <origin xyz="0 0 0"/>
      <mass value="0.5"/>
      <inertia ixx="1" ixy="0" ixz="0" iyy="1" iyz="0" izz="1"/>
    </inertial>
    <visual>
      <material name="JacoGrey"/>
      <origin rpy="3.14159265359 0 1.57079632679" xyz="0 0 -0.04227"/>
      <geometry>
        <mesh filename="package://jaco_model/meshes/jaco_elbow_roll_joint.dae"/>
      </geometry>
    </visual>
    <collision>
      <origin rpy="3.14159265359 0 1.57079632679" xyz="0 0 -0.04227"/>
      <geometry>
        <mesh filename="package://jaco_model/meshes/jaco_elbow_roll_joint.dae"/>
      </geometry>
    </collision>
  </link>
  <gazebo reference="mico_lower_arm_roll_link">
    <!-- fnh -->
    <material>Gazebo/Grey</material>
    <turnGravityOff>false</turnGravityOff>
    <selfCollide>true</selfCollide>
    <mu1>100.0</mu1>
    <mu2>100.0</mu2>
    <kp>1000000.0</kp>
    <kd>1.0</kd>
  </gazebo>
  <joint name="mico_wrist_roll_joint" type="revolute">
    <origin rpy="0.959931088597 0 0" xyz="0 -0.0692622919853 0.0484979789618"/>
    <axis xyz="0 0 1"/>
    <parent link="mico_lower_arm_roll_link"/>
    <child link="mico_wrist_link"/>
    <limit effort="40" lower="-3.04159265359" upper="3.04159265359" velocity="1.04719752"/>
    <dynamics damping="50.5"/>
  </joint>
  <transmission name="mico_wrist_roll_joint_transmission">
    <type>transmission_interface/SimpleTransmission</type>
    <actuator name="mico_wrist_roll_joint_motor">
      <hardwareInterface>EffortJointInterface</hardwareInterface>
      <mechanicalReduction>50</mechanicalReduction>
    </actuator>
    <joint name="mico_wrist_roll_joint"/>
    <mechanicalReduction>50</mechanicalReduction>
    <motorTorqueConstant>1</motorTorqueConstant>
    <pulsesPerRevolution>10000</pulsesPerRevolution>
  </transmission>
  <link name="mico_wrist_link">
    <inertial>
      <!-- fnh -->
      <origin xyz="0 0 0"/>
      <mass value="0.5"/>
      <inertia ixx="1" ixy="0" ixz="0" iyy="1" iyz="0" izz="1"/>
    </inertial>
    <visual>
      <material name="JacoGrey"/>
      <origin rpy="0 3.14159265359 -1.57079632679" xyz="0 0 -0.0422768230075"/>
      <geometry>
        <mesh filename="package://jaco_model/meshes/jaco_wrist_roll_joint.dae"/>
      </geometry>
    </visual>
    <collision>
      <origin rpy="0 3.14159265359 -1.57079632679" xyz="0 0 -0.0422768230075"/>
      <geometry>
        <mesh filename="package://jaco_model/meshes/jaco_wrist_roll_joint.dae"/>
      </geometry>
    </collision>
  </link>
  <gazebo reference="mico_wrist_link">
    <!-- fnh -->
    <material>Gazebo/Grey</material>
    <turnGravityOff>false</turnGravityOff>
    <selfCollide>true</selfCollide>
    <mu1>100.0</mu1>
    <mu2>100.0</mu2>
    <kp>1000000.0</kp>
    <kd>1.0</kd>
  </gazebo>
  <joint name="mico_hand_roll_joint" type="revolute">
    <origin rpy="0.959931088597 0 0" xyz="0 -0.186174274186 0.130360630206"/>
    <axis xyz="0 0 1"/>
    <parent link="mico_wrist_link"/>
    <child link="mico_hand_link"/>
    <limit effort="40" lower="-1.67079632679" upper="4.52703501382" velocity="1.04719752"/>
    <dynamics damping="50.5"/>
  </joint>
  <transmission name="mico_hand_roll_joint_transmission">
    <type>transmission_interface/SimpleTransmission</type>
    <actuator name="mico_hand_roll_joint_motor">
      <hardwareInterface>EffortJointInterface</hardwareInterface>
      <mechanicalReduction>50</mechanicalReduction>
    </actuator>
    <joint name="mico_hand_roll_joint"/>
    <mechanicalReduction>50</mechanicalReduction>
    <motorTorqueConstant>1</motorTorqueConstant>
    <pulsesPerRevolution>10000</pulsesPerRevolution>
  </transmission>
  <link name="mico_hand_link">
    <inertial>
      <!-- fnh -->
      <origin xyz="0 0 0"/>
      <mass value="0.6"/>
      <inertia ixx="1" ixy="0" ixz="0" iyy="1" iyz="0" izz="1"/>
    </inertial>
    <visual>
      <material name="JacoGrey"/>
      <origin rpy="0 0 -3.14159265359" xyz="0 0 -0.185"/>
      <geometry>
        <mesh filename="package://jaco_model/meshes/jaco_hand_roll_joint.dae"/>
      </geometry>
    </visual>
    <collision>
      <origin rpy="0 0 -3.14159265359" xyz="0 0 -0.185"/>
      <geometry>
        <!--<mesh filename="package://jaco_model/meshes/jaco_hand_roll_joint.stl" scale="0.9 0.9 0.7" />  fnh -->
        <mesh filename="package://jaco_model/meshes/jaco_hand_roll_joint.dae"/>
      </geometry>
    </collision>
  </link>
  <gazebo reference="mico_hand_link">
    <!-- fnh -->
    <material>Gazebo/Grey</material>
    <turnGravityOff>false</turnGravityOff>
    <selfCollide>true</selfCollide>
    <mu1>100.0</mu1>
    <mu2>100.0</mu2>
    <kp>1000000.0</kp>
    <kd>1.0</kd>
  </gazebo>
  <joint name="mico_finger_1_joint" type="revolute">
    <!-- <origin xyz="-0.036 0.021 ${-0.07}" rpy="0 ${-M_PI/7} 0"/> -->
    <origin rpy="0 -0.448798950513 0" xyz="-0.036 0.021 -0.07"/>
    <axis xyz="0 1 0"/>
    <parent link="mico_hand_link"/>
    <child link="mico_finger_1_link"/>
    <limit effort="10" lower="-0.1" upper="1.04719752" velocity="1.0"/>
    <dynamics damping="50.5"/>
  </joint>
  <transmission name="mico_finger_1_joint_transmission">
    <type>transmission_interface/SimpleTransmission</type>
    <actuator name="mico_finger_1_joint_motor">
      <hardwareInterface>EffortJointInterface</hardwareInterface>
      <mechanicalReduction>50</mechanicalReduction>
    </actuator>
    <joint name="mico_finger_1_joint"/>
    <mechanicalReduction>50</mechanicalReduction>
    <motorTorqueConstant>1</motorTorqueConstant>
    <pulsesPerRevolution>10000</pulsesPerRevolution>
  </transmission>
  <link name="mico_finger_1_link">
    <inertial>
      <!-- fnh -->
      <origin xyz="0 0 0"/>
      <mass value="0.1"/>
      <inertia ixx="1" ixy="0" ixz="0" iyy="1" iyz="0" izz="1"/>
    </inertial>
    <visual>
      <material name="JacoGrey"/>
      <origin rpy="0 0 0" xyz="0 0 0"/>
      <geometry>
        <mesh filename="package://jaco_model/meshes/finger_new.dae"/>
      </geometry>
    </visual>
    <collision>
      <origin rpy="0 0 0" xyz="0 0 0"/>
      <geometry>
        <mesh filename="package://jaco_model/meshes/finger_new.dae"/>
      </geometry>
    </collision>
  </link>
  <gazebo reference="mico_finger_1_link">
    <!-- fnh -->
    <material>Gazebo/Grey</material>
    <turnGravityOff>false</turnGravityOff>
    <selfCollide>true</selfCollide>
    <mu1>100.0</mu1>
    <mu2>100.0</mu2>
    <kp>1000000.0</kp>
    <kd>1.0</kd>
  </gazebo>
  <joint name="mico_finger_2_joint" type="revolute">
    <origin rpy="0 -0.448798950513 -3.14159265359" xyz="0.036 -0 -0.07"/>
    <axis xyz="0 1 0"/>
    <parent link="mico_hand_link"/>
    <child link="mico_finger_2_link"/>
    <limit effort="10" lower="-0.1" upper="1.04719752" velocity="1.0"/>
    <dynamics damping="50.5"/>
  </joint>
  <transmission name="mico_finger_2_joint_transmission">
    <type>transmission_interface/SimpleTransmission</type>
    <actuator name="mico_finger_2_joint_motor">
      <hardwareInterface>EffortJointInterface</hardwareInterface>
      <mechanicalReduction>50</mechanicalReduction>
    </actuator>
    <joint name="mico_finger_2_joint"/>
    <mechanicalReduction>50</mechanicalReduction>
    <motorTorqueConstant>1</motorTorqueConstant>
    <pulsesPerRevolution>10000</pulsesPerRevolution>
  </transmission>
  <link name="mico_finger_2_link">
    <inertial>
      <!-- fnh -->
      <origin xyz="0 0 0"/>
      <mass value="0.1"/>
      <inertia ixx="1" ixy="0" ixz="0" iyy="1" iyz="0" izz="1"/>
    </inertial>
    <visual>
      <material name="JacoGrey"/>
      <origin rpy="0 0 0" xyz="0 0 0"/>
      <geometry>
        <mesh filename="package://jaco_model/meshes/finger_new.dae"/>
      </geometry>
    </visual>
    <collision>
      <origin rpy="0 0 0" xyz="0 0 0"/>
      <geometry>
        <mesh filename="package://jaco_model/meshes/finger_new.dae"/>
      </geometry>
    </collision>
  </link>
  <gazebo reference="mico_finger_2_link">
    <!-- fnh -->
    <material>Gazebo/Grey</material>
    <turnGravityOff>false</turnGravityOff>
    <selfCollide>true</selfCollide>
    <mu1>100.0</mu1>
    <mu2>100.0</mu2>
    <kp>1000000.0</kp>
    <kd>1.0</kd>
  </gazebo>
  <joint name="mico_finger_3_joint" type="revolute">
    <origin rpy="0 -0.448798950513 0" xyz="-0.036 -0.021 -0.07"/>
    <axis xyz="0 1 0"/>
    <parent link="mico_hand_link"/>
    <child link="mico_finger_3_link"/>
    <limit effort="10" lower="-0.1" upper="1.04719752" velocity="1.0"/>
    <dynamics damping="50.5"/>
  </joint>
  <transmission name="mico_finger_3_joint_transmission">
    <type>transmission_interface/SimpleTransmission</type>
    <actuator name="mico_finger_3_joint_motor">
      <hardwareInterface>EffortJointInterface</hardwareInterface>
      <mechanicalReduction>50</mechanicalReduction>
    </actuator>
    <joint name="mico_finger_3_joint"/>
    <mechanicalReduction>50</mechanicalReduction>
    <motorTorqueConstant>1</motorTorqueConstant>
    <pulsesPerRevolution>10000</pulsesPerRevolution>
  </transmission>
  <link name="mico_finger_3_link">
    <inertial>
      <!-- fnh -->
      <origin xyz="0 0 0"/>
      <mass value="0.1"/>
      <inertia ixx="1" ixy="0" ixz="0" iyy="1" iyz="0" izz="1"/>
    </inertial>
    <visual>
      <material name="JacoGrey"/>
      <origin rpy="0 0 0" xyz="0 0 0"/>
      <geometry>
        <mesh filename="package://jaco_model/meshes/finger_new.dae"/>
      </geometry>
    </visual>
    <collision>
      <origin rpy="0 0 0" xyz="0 0 0"/>
      <geometry>
        <mesh filename="package://jaco_model/meshes/finger_new.dae"/>
      </geometry>
    </collision>
  </link>
  <gazebo reference="mico_finger_3_link">
    <!-- fnh -->
    <material>Gazebo/Grey</material>
    <turnGravityOff>false</turnGravityOff>
    <selfCollide>true</selfCollide>
    <mu1>100.0</mu1>
    <mu2>100.0</mu2>
    <kp>1000000.0</kp>
    <kd>1.0</kd>
  </gazebo>
  <gazebo>
    <plugin filename="libgazebo_ros_control.so" name="gazebo_ros_control">
      <robotNamespace>/sudo</robotNamespace>
    </plugin>
  </gazebo>
</robot>
