<?xml version="1.0" ?>
<!-- =================================================================================== -->
<!-- |    This document was autogenerated by xacro from model.urdf.xacro               | -->
<!-- |    EDITING THIS FILE BY HAND IS NOT RECOMMENDED                                 | -->
<!-- =================================================================================== -->

<robot name="sudo" xmlns:controller="http://playerstage.sourceforge.net/gazebo/xmlschema/#controller" xmlns:interface="http://playerstage.sourceforge.net/gazebo/xmlschema/#interface" xmlns:sensor="http://playerstage.sourceforge.net/gazebo/xmlschema/#sensor" xmlns:xacro="http://ros.org/wiki/xacro">
  <link name="base_footprint">
    <origin rpy="0 0 0" xyz="0 0 0.0"/>
  </link>
  
  <joint name="base_footprint_to_chassis" type="fixed">
    <origin rpy="0 0 0" xyz="0 0 0.16"/>
    <child link="chassis"/>
    <parent link="base_footprint"/>
  </joint>
  <!-- Pioneer 2 Chassis-->
  <link name="chassis">
     <inertial>
      <mass value="40"/>
      <!--<origin xyz="-0.025 0 -0.223"/>-->
      <origin xyz="-0.05 0 0"/>
      <inertia ixx="1" ixy="0" ixz="0" iyy="1" iyz="0" izz="1"/>
    </inertial>
    <origin rpy="0 0 0" xyz="0 0 0.16"/>
    <visual name="visual">
      <origin rpy="0 0 0" xyz="0 0 0.04"/>
      <geometry>
        <mesh filename="package://sudo_description/models/pioneer2dx/meshes/chassis.dae"/>
      </geometry>
    </visual>
    <visual name="castor_visual">
      <origin rpy="0 0 0" xyz="-0.200 0 -0.12"/>
      <geometry>
        <sphere radius="0.04"/>
      </geometry>
      <material name="black">
        <color rgba="0 0 0 1.0"/>
      </material>
    </visual>
    <collision>
      <origin rpy="0 0 0" xyz="0 0 0.04"/>
      <geometry>
        <mesh filename="package://sudo_description/models/pioneer2dx/meshes/chassis.dae"/>
      </geometry>
    </collision>
    <collision name="castor_collision">
      <origin rpy="0 0 0" xyz="-0.200 0 -0.12"/>
      <geometry>
        <sphere radius="0.02"/>
      </geometry>
    </collision>
  </link>
 
  <!-- Bottom cube of Sudo-->
  <link name="bottom_body_box">
    <visual name="visual">
    <origin xyz="0 0 0" rpy="0 0 0"/>
      <geometry>
        <box size="0.315 0.38 0.42"/>
      </geometry>
      <material name="black">
        <color rgba="0 0 0 1.0"/>
      </material>
    </visual>
    <collision>
    <origin xyz="0 0 0" rpy="0 0 0"/>
      <geometry>
        <box size="0.315 0.38 0.42"/>
      </geometry>
    </collision>
  </link>
 

  <!-- The link for sick laser. The used model is actually hokoyu-->
  <link name="laser_link">
    <origin rpy="0 0 3.14" xyz="-0.2 0 0.3"/>
    <visual name="visual">
    <origin xyz="0 0 0" rpy="0 0 0"/>
      <geometry>
        <mesh filename="package://sudo_description/models/hokuyo/meshes/hokuyo.dae"/>
      </geometry>
    </visual>
  </link>



  <link name="right_wheel">
    <origin rpy="1.5707 1.5707 0" xyz="0.1 -0.17 0.08"/>
    <inertial>
      <mass value="0.5"/>
      <origin xyz="0 0 0"/>
      <inertia ixx="0.012411765597" ixy="0" ixz="0" iyy="0.015218160428" iyz="0" izz="0.011763977943"/>
    </inertial>
    <visual name="visual">
    <origin xyz="0 0 0" rpy="0 0 0"/>
      <geometry>
        <cylinder length="0.05" radius="0.11"/>
      </geometry>
      <material name="black">
        <color rgba="0 0 0 1.0"/>
      </material>
    </visual>
    <collision>
    <origin xyz="0 0 0" rpy="0 0 0"/>
      <geometry>
        <cylinder length="0.05" radius="0.11"/>
      </geometry>
    </collision>
  </link>

  <gazebo reference="right_wheel">
    <!-- fnh -->
    <material>Gazebo/Black</material>
    <turnGravityOff>false</turnGravityOff>
    <selfCollide>true</selfCollide>
    <mu1>100.0</mu1>
    <mu2>100.0</mu2>
    <kp>1000000.0</kp>
    <kd>1.0</kd>
  </gazebo>    

  <link name="left_wheel">
    <origin rpy="1.5707 1.5707 0" xyz="0.1 0.17 0.08"/>
    <inertial>
      <mass value="0.5"/>
      <origin xyz="0 0 0"/>
      <inertia ixx="0.012411765597" ixy="0" ixz="0" iyy="0.015218160428" iyz="0" izz="0.011763977943"/>
    </inertial>
    <visual name="visual">
    <origin xyz="0 0 0" rpy="0 0 0"/>
      <geometry>
        <cylinder length="0.05" radius="0.11"/>
      </geometry>
      <material name="black">
        <color rgba="0 0 0 1.0"/>
      </material>
    </visual>
    <collision>
        <origin xyz="0 0 0" rpy="0 0 0"/>
      <geometry>
        <cylinder length="0.05" radius="0.11"/>
      </geometry>
    </collision>
  </link>

  <gazebo reference="left_wheel">
    <!-- fnh -->
    <material>Gazebo/Black</material>
    <turnGravityOff>false</turnGravityOff>
    <selfCollide>true</selfCollide>
    <mu1>100.0</mu1>
    <mu2>100.0</mu2>
    <kp>1000000.0</kp>
    <kd>1.0</kd>
  </gazebo>
  

  <joint name="left_wheel_hinge" type="continuous">
    <origin rpy="1.5707 0 0" xyz="0.1 0.17 -0.03"/>
    <child link="left_wheel"/>
    <parent link="chassis"/>
    <axis xyz="0 1 0"/>
    <limit effort="100" velocity="100"/>
    <joint_properties damping="0.0" friction="0.0"/>
  </joint>
  
    <transmission name="left_wheel_transmission">
    <type>transmission_interface/SimpleTransmission</type>
    <actuator name="left_wheel_motor">
      <hardwareInterface>EffortJointInterface</hardwareInterface>
      <mechanicalReduction>50</mechanicalReduction>
    </actuator>
    <joint name="left_wheel_hinge"/>
    <mechanicalReduction>50</mechanicalReduction>
    <motorTorqueConstant>1</motorTorqueConstant>
    <pulsesPerRevolution>10000</pulsesPerRevolution>
  </transmission>
  
  <joint name="right_wheel_hinge" type="continuous">
    <origin rpy="1.5707 0 0" xyz="0.1 -0.17 -0.03"/>
    <child link="right_wheel"/>
    <parent link="chassis"/>
    <axis xyz=" 0 1 0"/>
    <limit effort="100" velocity="100"/>
    <joint_properties damping="0.0" friction="0.0"/>
  </joint>
  <transmission name="right_wheel_transmission">
    <type>transmission_interface/SimpleTransmission</type>
    <actuator name="right_wheel_motor">
      <hardwareInterface>EffortJointInterface</hardwareInterface>
      <mechanicalReduction>50</mechanicalReduction>
    </actuator>
    <joint name="right_wheel_hinge"/>
    <mechanicalReduction>50</mechanicalReduction>
    <motorTorqueConstant>1</motorTorqueConstant>
    <pulsesPerRevolution>10000</pulsesPerRevolution>
  </transmission>
  <!-- Gazebo diff_drive plugin-->
  <gazebo> 
  <plugin filename="libgazebo_ros_diff_drive.so" name="diff_drive">
      <alwaysOn>true</alwaysOn>
      <leftJoint>left_wheel_hinge</leftJoint>
      <rightJoint>right_wheel_hinge</rightJoint>
      <wheelSeparation>0.32</wheelSeparation>
      <wheelDiameter>0.11</wheelDiameter>
      <torque>50</torque>
      <commandTopic>cmd_vel</commandTopic>
      <odometryTopic>odom</odometryTopic>
      <odometryFrame>odom</odometryFrame>
      <robotBaseFrame>base_footprint</robotBaseFrame>
  </plugin>
  </gazebo>

  
  <!-- Connection between chassis and bottom rectangular box-->
  <joint name="chassis_to_bottom" type="fixed">
    <origin rpy=" 0 0 0" xyz="0 0 0.315"/>
    <child link="bottom_body_box"/>
    <parent link="chassis"/>
  </joint>
  <!-- Connection between chassis and laser-->
  <joint name="laser_to_chassis" type="fixed">
    <origin rpy="0 0 3.14" xyz="-0.2 0 0.15 "/>
    <child link="laser_link"/>
    <parent link="chassis"/>
  </joint>

  <!-- Mico -->
  <material name="JacoGrey">
    <color rgba="0.2 0.2 0.9 1.0"/>
  </material>
  
  <!-- Mico Base-->
  <joint name="mico_base_joint" type="fixed">
    <origin rpy="0 0 1.57" xyz="0.1 0 0.31"/>
    <!-- fnh was: <origin xyz="0 0 0" rpy="0 0 0"/> -->
    <parent link="bottom_body_box"/>
    <child link="mico_base_link"/>
  </joint>
  <link name="mico_base_link">
    <inertial>
      <!-- fnh -->
      <origin xyz="0 0 0"/>
      <mass value="1.0"/>
      <inertia ixx="1" ixy="0" ixz="0" iyy="1" iyz="0" izz="1"/>
    </inertial>
    <visual>
      <material name="JacoGrey"/>
      <origin rpy="0 0 1.57079632679" xyz="0 0 0"/>
      <geometry>
        <mesh filename="package://jaco_description/meshes/jaco_base_joint.dae"/>
      </geometry>
    </visual>
    <collision>
      <origin rpy="0 0 1.57079632679" xyz="0 0 0"/>
      <geometry>
        <mesh filename="package://jaco_description/meshes/jaco_base_joint.dae"/>
      </geometry>
    </collision>
  </link>
  
  <gazebo reference="mico_base_link">
    <!-- fnh -->
    <material>Gazebo/Grey</material>
    <turnGravityOff>false</turnGravityOff>
    <selfCollide>true</selfCollide>
    <mu1>100.0</mu1>
    <mu2>100.0</mu2>
    <kp>1000000.0</kp>
    <kd>1.0</kd>
  </gazebo>
  
  <joint name="mico_shoulder_yaw_joint" type="revolute">
    <!--<origin xyz="0 0 ${D1}" rpy="0 0 0"/>-->
    <origin rpy="3.14159265359 0 3.14159265359" xyz="0 0 0.2142"/>
    <axis rpy="0 0 0" xyz="0 0 1"/>
    <parent link="mico_base_link"/>
    <child link="mico_shoulder_link"/>
    <limit effort="200" lower="-3.04159265359" upper="3.04159265359" velocity="0.837758016"/>
    <dynamics damping="50.5"/>
  </joint>
  <transmission name="mico_shoulder_yaw_joint_transmission">
    <type>transmission_interface/SimpleTransmission</type>
    <actuator name="mico_shoulder_yaw_joint_motor">
      <hardwareInterface>EffortJointInterface</hardwareInterface>
      <mechanicalReduction>50</mechanicalReduction>
    </actuator>
    <joint name="mico_shoulder_yaw_joint"/>
    <mechanicalReduction>50</mechanicalReduction>
    <motorTorqueConstant>1</motorTorqueConstant>
    <pulsesPerRevolution>10000</pulsesPerRevolution>
  </transmission>
  <link name="mico_shoulder_link">
    <inertial>
      <!-- fnh -->
      <origin xyz="0 0 0"/>
      <mass value="1.0"/>
      <inertia ixx="1" ixy="0" ixz="0" iyy="1" iyz="0" izz="1"/>
    </inertial>
    <visual>
      <material name="JacoGrey"/>
      <origin rpy="1.57079632679 -1.57079632679 0" xyz="0 0 0"/>
      <geometry>
        <mesh filename="package://jaco_description/meshes/jaco_shoulder_yaw_joint.dae"/>
      </geometry>
    </visual>
    <collision>
      <origin rpy="1.57079632679 -1.57079632679 0" xyz="0 0 0"/>
      <geometry>
        <mesh filename="package://jaco_description/meshes/jaco_shoulder_yaw_joint.dae"/>
      </geometry>
    </collision>
  </link>
  <gazebo reference="mico_shoulder_link">
    <!-- fnh -->
    <material>Gazebo/Grey</material>
    <turnGravityOff>false</turnGravityOff>
    <selfCollide>true</selfCollide>
    <mu1>100.0</mu1>
    <mu2>100.0</mu2>
    <kp>1000000.0</kp>
    <kd>1.0</kd>
  </gazebo>
  <joint name="mico_shoulder_pitch_joint" type="revolute">
    <origin rpy="-1.570796327 3.14159265359 0" xyz="0 -1e-06 0"/>
    <axis xyz="0 0 1"/>
    <parent link="mico_shoulder_link"/>
    <child link="mico_upper_arm_link"/>
    <limit effort="300" lower="-3.83972424" upper="0.69813168" velocity="0.837758016"/>
    <dynamics damping="50.5"/>
  </joint>
  <transmission name="mico_shoulder_pitch_joint_transmission">
    <type>transmission_interface/SimpleTransmission</type>
    <actuator name="mico_shoulder_pitch_joint_motor">
      <hardwareInterface>EffortJointInterface</hardwareInterface>
      <mechanicalReduction>50</mechanicalReduction>
    </actuator>
    <joint name="mico_shoulder_pitch_joint"/>
    <mechanicalReduction>50</mechanicalReduction>
    <motorTorqueConstant>1</motorTorqueConstant>
    <pulsesPerRevolution>10000</pulsesPerRevolution>
  </transmission>
  <link name="mico_upper_arm_link">
    <inertial>
      <!-- fnh -->
      <origin xyz="0 0 0"/>
      <mass value="1.0"/>
      <inertia ixx="1" ixy="0" ixz="0" iyy="1" iyz="0" izz="1"/>
    </inertial>
    <visual>
      <material name="JacoGrey"/>
      <origin rpy="0 0 -1.57079632679" xyz="0 0 0"/>
      <geometry>
        <mesh filename="package://jaco_description/meshes/jaco_shoulder_pitch_joint.dae" scale="1 0.707317073171 1"/>
      </geometry>
    </visual>
    <collision>
      <origin rpy="0 0 -1.57079632679" xyz="0 0 0"/>
      <geometry>
        <mesh filename="package://jaco_description/meshes/jaco_shoulder_pitch_joint.dae" scale="1 0.707317073171 1"/>
      </geometry>
    </collision>
  </link>
  <gazebo reference="mico_upper_arm_link">
    <!-- fnh -->
    <material>Gazebo/Grey</material>
    <turnGravityOff>false</turnGravityOff>
    <selfCollide>true</selfCollide>
    <mu1>100.0</mu1>
    <mu2>100.0</mu2>
    <kp>1000000.0</kp>
    <kd>1.0</kd>
  </gazebo>
  <joint name="mico_elbow_pitch_joint" type="revolute">
    <origin rpy="3.14159265359 0 1.570796327" xyz="0.29 0 0.012001"/>
    <axis xyz="0 0 1"/>
    <parent link="mico_upper_arm_link"/>
    <child link="mico_lower_arm_link"/>
    <limit effort="200" lower="-4.363323" upper="1.22173044" velocity="0.837758016"/>
    <dynamics damping="50.5"/>
  </joint>
  <transmission name="mico_elbow_pitch_joint_transmission">
    <type>transmission_interface/SimpleTransmission</type>
    <actuator name="mico_elbow_pitch_joint_motor">
      <hardwareInterface>EffortJointInterface</hardwareInterface>
      <mechanicalReduction>50</mechanicalReduction>
    </actuator>
    <joint name="mico_elbow_pitch_joint"/>
    <mechanicalReduction>50</mechanicalReduction>
    <motorTorqueConstant>1</motorTorqueConstant>
    <pulsesPerRevolution>10000</pulsesPerRevolution>
  </transmission>
  <link name="mico_lower_arm_link">
    <inertial>
      <!-- fnh -->
      <origin xyz="0 0 0"/>
      <mass value="0.8"/>
      <inertia ixx="1" ixy="0" ixz="0" iyy="1" iyz="0" izz="1"/>
    </inertial>
    <visual>
      <material name="JacoGrey"/>
      <origin rpy="3.14159265359 0 3.14159265359" xyz="0 0 -0.012"/>
      <geometry>
        <mesh filename="package://jaco_description/meshes/jaco_elbow_pitch_joint.dae" scale="1 0.601463414634 1"/>
      </geometry>
    </visual>
    <collision>
      <origin rpy="3.14159265359 0 3.14159265359" xyz="0 0 -0.012"/>
      <geometry>
        <mesh filename="package://jaco_description/meshes/jaco_elbow_pitch_joint.dae" scale="1 0.601463414634 1"/>
      </geometry>
    </collision>
  </link>
  <gazebo reference="mico_lower_arm_link">
    <!-- fnh -->
    <material>Gazebo/Grey</material>
    <turnGravityOff>false</turnGravityOff>
    <selfCollide>true</selfCollide>
    <mu1>100.0</mu1>
    <mu2>100.0</mu2>
    <kp>1000000.0</kp>
    <kd>1.0</kd>
  </gazebo>J_PI
  <joint name="mico_elbow_roll_joint" type="revolute">
    <origin rpy="3.14159265359 1.57079632679 0" xyz="0 0.165571 0 "/>
    <axis xyz="0 0 1"/>
    <parent link="mico_lower_arm_link"/>
    <child link="mico_lower_arm_roll_link"/>
    <limit effort="40" lower="-3.04159265359" upper="3.04159265359" velocity="1.04719752"/>
    <dynamics damping="50.5"/>
  </joint>
  <transmission name="mico_elbow_roll_joint_transmission">
    <type>transmission_interface/SimpleTransmission</type>
    <actuator name="mico_elbow_roll_joint_motor">
      <hardwareInterface>EffortJointInterface</hardwareInterface>
      <mechanicalReduction>50</mechanicalReduction>
    </actuator>
    <joint name="mico_elbow_roll_joint"/>
    <mechanicalReduction>50</mechanicalReduction>
    <motorTorqueConstant>1</motorTorqueConstant>
    <pulsesPerRevolution>10000</pulsesPerRevolution>
  </transmission>
  <link name="mico_lower_arm_roll_link">
    <inertial>
      <!-- fnh -->
      <origin xyz="0 0 0"/>
      <mass value="0.5"/>
      <inertia ixx="1" ixy="0" ixz="0" iyy="1" iyz="0" izz="1"/>
    </inertial>
    <visual>
      <material name="JacoGrey"/>
      <origin rpy="3.14159265359 0 1.57079632679" xyz="0 0 -0.04227"/>
      <geometry>
        <mesh filename="package://jaco_description/meshes/jaco_elbow_roll_joint.dae"/>
      </geometry>
    </visual>
    <collision>
      <origin rpy="3.14159265359 0 1.57079632679" xyz="0 0 -0.04227"/>
      <geometry>
        <mesh filename="package://jaco_description/meshes/jaco_elbow_roll_joint.dae"/>
      </geometry>
    </collision>
  </link>
  <gazebo reference="mico_lower_arm_roll_link">
    <!-- fnh -->
    <material>Gazebo/Grey</material>
    <turnGravityOff>false</turnGravityOff>
    <selfCollide>true</selfCollide>
    <mu1>100.0</mu1>
    <mu2>100.0</mu2>
    <kp>1000000.0</kp>
    <kd>1.0</kd>
  </gazebo>
  <joint name="mico_wrist_roll_joint" type="revolute">
    <origin rpy="0 -0.959931088597 0" xyz="0 -0.0692622919853 0.0484979789618"/>
    <axis xyz="0 0 1"/>
    <parent link="mico_lower_arm_roll_link"/>
    <child link="mico_wrist_link"/>
    <limit effort="40" lower="-3.04159265359" upper="3.04159265359" velocity="1.04719752"/>
    <dynamics damping="50.5"/>
  </joint>
  <transmission name="mico_wrist_roll_joint_transmission">
    <type>transmission_interface/SimpleTransmission</type>
    <actuator name="mico_wrist_roll_joint_motor">
      <hardwareInterface>EffortJointInterface</hardwareInterface>
      <mechanicalReduction>50</mechanicalReduction>
    </actuator>
    <joint name="mico_wrist_roll_joint"/>
    <mechanicalReduction>50</mechanicalReduction>
    <motorTorqueConstant>1</motorTorqueConstant>
    <pulsesPerRevolution>10000</pulsesPerRevolution>
  </transmission>
  <link name="mico_wrist_link">
    <inertial>
      <!-- fnh -->
      <origin xyz="0 0 0"/>
      <mass value="0.5"/>
      <inertia ixx="1" ixy="0" ixz="0" iyy="1" iyz="0" izz="1"/>
    </inertial>
    <visual>
      <material name="JacoGrey"/>
      <origin rpy="0 3.14159265359 -1.57079632679" xyz="0 0 -0.0422768230075"/>
      <geometry>
        <mesh filename="package://jaco_description/meshes/jaco_wrist_roll_joint.dae"/>
      </geometry>
    </visual>
    <collision>
      <origin rpy="0 3.14159265359 -1.57079632679" xyz="0 0 -0.0422768230075"/>
      <geometry>
        <mesh filename="package://jaco_description/meshes/jaco_wrist_roll_joint.dae"/>
      </geometry>
    </collision>
  </link>
  <gazebo reference="mico_wrist_link">
    <!-- fnh -->
    <material>Gazebo/Grey</material>
    <turnGravityOff>false</turnGravityOff>
    <selfCollide>true</selfCollide>
    <mu1>100.0</mu1>
    <mu2>100.0</mu2>
    <kp>1000000.0</kp>
    <kd>1.0</kd>
  </gazebo>
  <joint name="mico_hand_roll_joint" type="revolute">
    <origin rpy="-0.959931088597 0 1.57079632679" xyz="0 -0.186174274186 0.130360630206"/>
    <axis xyz="0 0 1"/>
    <parent link="mico_wrist_link"/>
    <child link="mico_hand_link"/>
    <limit effort="40" lower="-1.7" upper="4.5" velocity="1.04719752"/>
    <dynamics damping="50.5"/>
  </joint>
  <transmission name="mico_hand_roll_joint_transmission">
    <type>transmission_interface/SimpleTransmission</type>
    <actuator name="mico_hand_roll_joint_motor">
      <hardwareInterface>EffortJointInterface</hardwareInterface>
      <mechanicalReduction>50</mechanicalReduction>
    </actuator>
    <joint name="mico_hand_roll_joint"/>
    <mechanicalReduction>50</mechanicalReduction>
    <motorTorqueConstant>1</motorTorqueConstant>
    <pulsesPerRevolution>10000</pulsesPerRevolution>
  </transmission>
  <link name="mico_hand_link">
    <inertial>
      <!-- fnh -->
      <origin xyz="0 0 0"/>
      <mass value="0.6"/>
      <inertia ixx="1" ixy="0" ixz="0" iyy="1" iyz="0" izz="1"/>
    </inertial>
    <visual>
      <material name="JacoGrey"/>
      <origin rpy="0 0 -3.14159265359" xyz="0 0 -0.185"/>
      <geometry>
        <mesh filename="package://jaco_description/meshes/jaco_hand_roll_joint.dae"/>
      </geometry>
    </visual>
    <collision>
      <origin rpy="0 0 -3.14159265359" xyz="0 0 -0.185"/>
      <geometry>
        <!--<mesh filename="package://jaco_description/meshes/jaco_hand_roll_joint.stl" scale="0.9 0.9 0.7" />  fnh -->
        <mesh filename="package://jaco_description/meshes/jaco_hand_roll_joint.dae"/>
      </geometry>
    </collision>
  </link>
  <gazebo reference="mico_hand_link">
    <!-- fnh -->
    <material>Gazebo/Grey</material>
    <turnGravityOff>false</turnGravityOff>
    <selfCollide>true</selfCollide>
    <mu1>100.0</mu1>
    <mu2>100.0</mu2>
    <kp>1000000.0</kp>
    <kd>1.0</kd>
  </gazebo>
  <joint name="mico_finger_1_joint" type="revolute">
    <!-- <origin xyz="-0.036 0.021 ${-0.07}" rpy="0 ${-M_PI/7} 0"/> -->
    <origin rpy="0 -0.448798950513 0" xyz="-0.036 0.021 -0.07"/>
    <axis xyz="0 1 0"/>
    <parent link="mico_hand_link"/>
    <child link="mico_finger_1_link"/>
    <limit effort="10" lower="-0.1" upper="1.04719752" velocity="1.0"/>
    <dynamics damping="50.5"/>
  </joint>
  <transmission name="mico_finger_1_joint_transmission">
    <type>transmission_interfacmico_arm_v0e/SimpleTransmission</type>
    <actuator name="mico_finger_1_joint_motor">
      <hardwareInterface>EffortJointInterface</hardwareInterface>
      <mechanicalReduction>50</mechanicalReduction>
    </actuator>
    <joint name="mico_finger_1_joint"/>
    <mechanicalReduction>50</mechanicalReduction>
    <motorTorqueConstant>1</motorTorqueConstant>
    <pulsesPerRevolution>10000</pulsesPerRevolution>
  </transmission>
  <link name="mico_finger_1_link">
    <inertial>
      <!-- fnh -->
      <origin xyz="0 0 0"/>
      <mass value="0.1"/>
      <inertia ixx="1" ixy="0" ixz="0" iyy="1" iyz="0" izz="1"/>
    </inertial>
    <visual>
      <material name="JacoGrey"/>
      <origin rpy="0 0 0" xyz="0 0 0"/>
      <geometry>
        <mesh filename="package://jaco_description/meshes/finger_new.dae"/>
      </geometry>
    </visual>
    <collision>
      <origin rpy="0 0 0" xyz="0 0 0"/>
      <geometry>
        <mesh filename="package://jaco_description/meshes/finger_new.dae"/>
      </geometry>
    </collision>
  </link>
  <gazebo reference="mico_finger_1_link">
    <!-- fnh -->
    <material>Gazebo/Grey</material>
    <turnGravityOff>false</turnGravityOff>
    <selfCollide>true</selfCollide>
    <mu1>100.0</mu1>
    <mu2>100.0</mu2>
    <kp>1000000.0</kp>
    <kd>1.0</kd>
  </gazebo>
  <joint name="mico_finger_2_joint" type="revolute">
    <origin rpy="0 -0.448798950513 -3.14159265359" xyz="0.036 -0 -0.07"/>
    <axis xyz="0 1 0"/>
    <parent link="mico_hand_link"/>
    <child link="mico_finger_2_link"/>
    <limit effort="10" lower="-0.1" upper="1.04719752" velocity="1.0"/>
    <dynamics damping="50.5"/>
  </joint>
  <transmission name="mico_finger_2_joint_transmission">
    <type>transmission_interface/SimpleTransmission</type>
    <actuator name="mico_finger_2_joint_motor">
      <hardwareInterface>EffortJointInterface</hardwareInterface>
      <mechanicalReduction>50</mechanicalReduction>
    </actuator>
    <joint name="mico_finger_2_joint"/>
    <mechanicalReduction>50</mechanicalReduction>
    <motorTorqueConstant>1</motorTorqueConstant>
    <pulsesPerRevolution>10000</pulsesPerRevolution>
  </transmission>
  <link name="mico_finger_2_link">
    <inertial>
      <!-- fnh -->
      <origin xyz="0 0 0"/>
      <mass value="0.1"/>
      <inertia ixx="1" ixy="0" ixz="0" iyy="1" iyz="0" izz="1"/>
    </inertial>
    <visual>
      <material name="JacoGrey"/>
      <origin rpy="0 0 0" xyz="0 0 0"/>
      <geometry>
        <mesh filename="package://jaco_description/meshes/finger_new.dae"/>
      </geometry>
    </visual>
    <collision>
      <origin rpy="0 0 0" xyz="0 0 0"/>
      <geometry>
        <mesh filename="package://jaco_description/meshes/finger_new.dae"/>
      </geometry>
    </collision>
  </link>
  <gazebo reference="mico_finger_2_link">
    <!-- fnh -->
    <material>Gazebo/Grey</material>
    <turnGravityOff>false</turnGravityOff>
    <selfCollide>true</selfCollide>
    <mu1>100.0</mu1>
    <mu2>100.0</mu2>
    <kp>1000000.0</kp>
    <kd>1.0</kd>
  </gazebo>
  <joint name="mico_finger_3_joint" type="revolute">
    <origin rpy="0 -0.448798950513 0" xyz="-0.036 -0.021 -0.07"/>
    <axis xyz="0 1 0"/>
    <parent link="mico_hand_link"/>
    <child link="mico_finger_3_link"/>
    <limit effort="10" lower="-0.1" upper="1.04719752" velocity="1.0"/>
    <dynamics damping="50.5"/>
  </joint>
  <transmission name="mico_finger_3_joint_transmission">
    <type>transmission_interface/SimpleTransmission</type>
    <actuator name="mico_finger_3_joint_motor">
      <hardwareInterface>EffortJointInterface</hardwareInterface>
      <mechanicalReduction>50</mechanicalReduction>
    </actuator>
    <joint name="mico_finger_3_joint"/>
    <mechanicalReduction>50</mechanicalReduction>
    <motorTorqueConstant>1</motorTorqueConstant>
    <pulsesPerRevolution>10000</pulsesPerRevolution>
  </transmission>
  <link name="mico_finger_3_link">
    <inertial>
      <!-- fnh -->
      <origin xyz="0 0 0"/>
      <mass value="0.1"/>
      <inertia ixx="1" ixy="0" ixz="0" iyy="1" iyz="0" izz="1"/>
    </inertial>
    <visual>
      <material name="JacoGrey"/>
      <origin rpy="0 0 0" xyz="0 0 0"/>
      <geometry>
        <mesh filename="package://jaco_description/meshes/finger_new.dae"/>
      </geometry>
    </visual>
    <collision>
      <origin rpy="0 0 0" xyz="0 0 0"/>
      <geometry>
        <mesh filename="package://jaco_description/meshes/finger_new.dae"/>
      </geometry>
    </collision>
  </link>
  <gazebo reference="mico_finger_3_link">
    <!-- fnh -->
    <material>Gazebo/Grey</material>
    <turnGravityOff>false</turnGravityOff>
    <selfCollide>true</selfCollide>
    <mu1>100.0</mu1>
    <mu2>100.0</mu2>
    <kp>1000000.0</kp>
    <kd>1.0</kd>
  </gazebo>
  <gazebo>
   <plugin name="gazebo_ros_control" filename="libgazebo_ros_control.so">
     <robotNamespace>sudo</robotNamespace>
   </plugin>
  </gazebo>
  
  <!-- The link for top kinect-->
  <link name="camera_link">
    <visual name="visual">
      <geometry>
        <mesh filename="package://sudo_description/models/kinect/meshes/kinect.dae"/>
      </geometry>
    </visual>
  </link>
  
  <!-- Connection between top kinect and top body-->
  <joint name="top_kinect_to_chassis" type="fixed">
    <origin rpy="0 1.24 0" xyz="0.3 0 1.62"/>
    
    <child link="camera_link"/>
    <parent link="chassis"/>
    <!--axis xyz="0 1 0"/>
    <limit effort="100" lower="0" upper="0" velocity="0.1"/-->
  </joint>
  
  <!-- Gazebo Kinect plugin -->
  <gazebo reference="camera_link">
    <selfCollide>false</selfCollide>
    <static>true</static>
    <turnGravityOff>false</turnGravityOff>
    <sensor type="depth" name="openni_camera_camera">
      <!--pose xyz="0 0 0" rpy="-1.57 0 -2.81" /-->
      <pose>0 0 0 -1.58 0 -1.58</pose>
      <always_on>1</always_on>
      <visualize>true</visualize>
      <camera>
	<!--pose>0 0 0 -1.57 0 -2.81</pose-->
	<horizontal_fov>1.047</horizontal_fov>
	<image>
	  <width>640</width>
	  <height>480</height>
	  <format>R8G8B8</format>
	</image>
	<depth_camera>
	</depth_camera>
	<clip>
	  <near>0.1</near>
	  <far>100</far>
	</clip>
      </camera>
      <plugin name="camera_controller" filename="libgazebo_ros_openni_kinect.so">
	<alwaysOn>true</alwaysOn>
	<updateRate>10.0</updateRate>
	<cameraName>camera</cameraName>
	<frameName>camera_link</frameName>
	<imageTopicName>rgb/image_raw</imageTopicName>
	<depthImageTopicName>depth/image_raw</depthImageTopicName>
	<pointCloudTopicName>depth/points</pointCloudTopicName>
	<cameraInfoTopicName>rgb/camera_info</cameraInfoTopicName>
	<depthImageCameraInfoTopicName>depth/camera_info</depthImageCameraInfoTopicName>
	<pointCloudCutoff>0.4</pointCloudCutoff>
	<hackBaseline>0.07</hackBaseline>
	<distortionK1>0.0</distortionK1>
	<distortionK2>0.0</distortionK2>
	<distortionK3>0.0</distortionK3>
	<distortionT1>0.0</distortionT1>
	<distortionT2>0.0</distortionT2>
	<CxPrime>0.0</CxPrime>
	<Cx>0.0</Cx>
	<Cy>0.0</Cy>
	<focalLength>0.0</focalLength>
      </plugin>
    </sensor>
  </gazebo>

</robot>
