<?xml version="1.0" ?>
<!-- =================================================================================== -->
<!-- |    This document was autogenerated by xacro from model.urdf.xacro               | -->
<!-- |    EDITING THIS FILE BY HAND IS NOT RECOMMENDED                                 | -->
<!-- =================================================================================== -->

<robot name="sudo" xmlns:controller="http://playerstage.sourceforge.net/gazebo/xmlschema/#controller" xmlns:interface="http://playerstage.sourceforge.net/gazebo/xmlschema/#interface" xmlns:sensor="http://playerstage.sourceforge.net/gazebo/xmlschema/#sensor" xmlns:xacro="http://ros.org/wiki/xacro">
  <origin rpy="0 0 0" xyz="0 0 0"/>
  <!-- Pioneer 2 Chassis-->
  <link name="chassis">
    <origin rpy="0 0 0" xyz="0 0 0.16"/>
    <visual name="visual">
      <origin rpy="0 0 0" xyz="0 0 0.04"/>
      <geometry>
        <mesh filename="package://sudo_description/models/pioneer2dx/meshes/chassis.dae"/>
      </geometry>
    </visual>
    <visual name="castor_visual">
      <origin rpy="0 0 0" xyz="-0.200 0 -0.12"/>
      <geometry>
        <sphere radius="0.04"/>
      </geometry>
      <material name="black">
        <color rgba="0 0 0 1.0"/>
      </material>
    </visual>
    <collision>
      <origin rpy="0 0 0" xyz="0 0 0.04"/>
      <geometry>
        <mesh filename="package://sudo_description/models/pioneer2dx/meshes/chassis.dae"/>
      </geometry>
    </collision>
  </link>
  <!-- Bottom cube of Sudo-->
  <link name="bottom_body_box">
    <visual name="visual">
      <geometry>
        <box size="0.315 0.38 0.42"/>
      </geometry>
      <material name="black">
        <color rgba="0 0 0 1.0"/>
      </material>
    </visual>
    <collision>
      <geometry>
        <box size="0.315 0.38 0.42"/>
      </geometry>
    </collision>
  </link>
  <!-- Top bar left of sudo-->
  <link name="top_bar_left">
    <origin rpy="0 0 0" xyz="0.04 0.165 1"/>
    <visual name="visual">
      <geometry>
        <box size="0.025 0.025 0.9"/>
      </geometry>
      <material name="black">
        <color rgba="0 0 0 1.0"/>
      </material>
    </visual>
    <collision>
      <geometry>
        <box size="0.025 0.025 0.9"/>
      </geometry>
    </collision>
  </link>
  <!-- Top bar right of sudo-->
  <link name="top_bar_right">
    <origin rpy="0 0 0" xyz="0.04 -0.165 1"/>
    <visual name="visual">
      <geometry>
        <box size="0.025 0.025 0.9"/>
      </geometry>
      <material name="black">
        <color rgba="0 0 0 1.0"/>
      </material>
    </visual>
    <collision>
      <geometry>
        <box size="0.025 0.025 0.9"/>
      </geometry>
    </collision>
  </link>
  <!-- Top part of sudo-->
  <link name="top_body_box">
    <origin rpy="0 0 0" xyz="0.04 0 1.7"/>
    <visual name="visual">
      <geometry>
        <box size="0.05 0.377 0.23"/>
      </geometry>
      <material name="black">
        <color rgba="0 0 0 1.0"/>
      </material>
    </visual>
    <collision>
      <geometry>
        <box size="0.05 0.377 0.23"/>
      </geometry>
    </collision>
  </link>
  <!-- Small webcam that Amir uses for Navigation-->
  <link name="webcam_link">
    <origin rpy="0 0 0" xyz="0.2 0 0.77"/>
    <visual name="visual">
      <geometry>
        <box size="0.029 0.068 0.040"/>
      </geometry>
    </visual>
  </link>
  <!-- The link for bottom kinect-->
  <link name="camera_link">
    <origin rpy="0 1.24 0" xyz="0.2 0 1.62"/>
    <visual name="visual">
      <geometry>
        <mesh filename="package://sudo_description/models/kinect/meshes/kinect.dae"/>
      </geometry>
    </visual>
  </link>
  <!-- The link for top kinect-->
  <link name="camera2_link">
    <origin rpy="0 0.33 0" xyz="0.07 0 1.85"/>
    <visual name="visual">
      <geometry>
        <mesh filename="package://sudo_description/models/kinect/meshes/kinect.dae"/>
      </geometry>
    </visual>
  </link>
  <!-- The link for sick laser. The used model is actually hokoyu-->
  <link name="laser_link">
    <origin rpy="0 0 3.14" xyz="-0.2 0 0.3"/>
    <visual name="visual">
      <geometry>
        <mesh filename="package://sudo_description/models/hokuyo/meshes/hokuyo.dae"/>
      </geometry>
    </visual>
  </link>



  <link name="right_wheel">
    <origin rpy="1.5707 1.5707 0" xyz="0.1 -0.17 0.11"/>
    <visual name="visual">
      <geometry>
        <cylinder length="0.05" radius="0.11"/>
      </geometry>
      <material name="black">
        <color rgba="0 0 0 1.0"/>
      </material>
    </visual>
    <collision>
      <geometry>
        <cylinder length="0.05" radius="0.11"/>
      </geometry>
    </collision>
  </link>

  <gazebo reference="right_wheel">
    <!-- fnh -->
    <material>Gazebo/Black</material>
    <turnGravityOff>false</turnGravityOff>
    <selfCollide>true</selfCollide>
    <mu1>100.0</mu1>
    <mu2>100.0</mu2>
    <kp>1000000.0</kp>
    <kd>1.0</kd>
  </gazebo>    

  <link name="left_wheel">
    <origin rpy="1.5707 1.5707 0" xyz="0.1 0.17 0.11"/>
    <visual name="visual">
      <geometry>
        <cylinder length="0.05" radius="0.11"/>
      </geometry>
      <material name="black">
        <color rgba="0 0 0 1.0"/>
      </material>
    </visual>
    <collision>
      <geometry>
        <cylinder length="0.05" radius="0.11"/>
      </geometry>
    </collision>
  </link>

  <gazebo reference="left_wheel">
    <!-- fnh -->
    <material>Gazebo/Black</material>
    <turnGravityOff>false</turnGravityOff>
    <selfCollide>true</selfCollide>
    <mu1>100.0</mu1>
    <mu2>100.0</mu2>
    <kp>1000000.0</kp>
    <kd>1.0</kd>
  </gazebo>
  

  <controller:diffdrive_plugin name="differential_drive_controller" plugin="libdiffdrive_plugin.so">
    <alwaysOn>true</alwaysOn>
    <update>100</update>
    <updateRate>100.0</updateRate>
    <leftJoint>left_wheel_hinge</leftJoint>
    <rightJoint>right_wheel_hinge</rightJoint>
    <wheelSeparation>0.34</wheelSeparation>
    <wheelDiameter>0.11</wheelDiameter>
    <torque>5</torque>
    <interface:position name="position_iface_0"/>
    <robotNamespace>/</robotNamespace>
    <topicName>cmd_vel</topicName>
  </controller:diffdrive_plugin>

  <joint name="left_wheel_hinge" type="continuous">
    <origin rpy="1.5707 0 0" xyz="0.1 0.17 -0.03"/>
    <child link="left_wheel"/>
    <parent link="chassis"/>
    <axis xyz="0 1 0"/>
    <limit effort="100" velocity="100"/>
    <joint_properties damping="0.0" friction="0.0"/>
  </joint>
  
    <transmission name="left_wheel_transmission">
    <type>transmission_interface/SimpleTransmission</type>
    <actuator name="left_wheel_motor">
      <hardwareInterface>EffortJointInterface</hardwareInterface>
      <mechanicalReduction>50</mechanicalReduction>
    </actuator>
    <joint name="left_wheel_hinge"/>
    <mechanicalReduction>50</mechanicalReduction>
    <motorTorqueConstant>1</motorTorqueConstant>
    <pulsesPerRevolution>10000</pulsesPerRevolution>
  </transmission>
  
  <joint name="right_wheel_hinge" type="continuous">
    <origin rpy="1.5707 0 0" xyz="0.1 -0.17 -0.03"/>
    <child link="right_wheel"/>
    <parent link="chassis"/>
    <axis xyz=" 0 1 0"/>
    <limit effort="100" velocity="100"/>
    <joint_properties damping="0.0" friction="0.0"/>
  </joint>
  <transmission name="right_wheel_transmission">
    <type>transmission_interface/SimpleTransmission</type>
    <actuator name="right_wheel_motor">
      <hardwareInterface>EffortJointInterface</hardwareInterface>
      <mechanicalReduction>50</mechanicalReduction>
    </actuator>
    <joint name="right_wheel_hinge"/>
    <mechanicalReduction>50</mechanicalReduction>
    <motorTorqueConstant>1</motorTorqueConstant>
    <pulsesPerRevolution>10000</pulsesPerRevolution>
  </transmission>
  
  <!-- Connection between chassis and bottom rectangular box-->
  <joint name="chassis_to_bottom" type="fixed">
    <origin rpy=" 0 0 0" xyz="0 0 0.315"/>
    <child link="bottom_body_box"/>
    <parent link="chassis"/>
  </joint>
  <!-- Connection between chassis and laser-->
  <joint name="laser_to_chassis" type="fixed">
    <origin rpy="0 0 3.14" xyz="-0.2 0 0.15 "/>
    <child link="laser_link"/>
    <parent link="chassis"/>
  </joint>
  <!-- Connection between top bar left and bottom rectangular boxes-->
  <joint name="bottom_to_bar_left" type="fixed">
    <origin rpy="0 0 0" xyz="0 0.177 0.66"/>
    <child link="top_bar_left"/>
    <parent link="bottom_body_box"/>
  </joint>
  <!-- Connection between top bar right and bottom rectangular boxes-->
  <joint name="bottom_to_bar_right" type="fixed">
    <origin rpy="0 0 0" xyz="0 -0.177 0.66"/>
    <child link="top_bar_right"/>
    <parent link="bottom_body_box"/>
  </joint>
  <!-- Connection between top and bottom rectangular boxes-->
  <joint name="bar_left_to_top" type="fixed">
    <origin rpy="0 0 0" xyz="0 -0.178 0.565"/>
    <child link="top_body_box"/>
    <parent link="top_bar_left"/>
  </joint>
  <!-- Connection between webcam and bottom rectangular box-->
  <joint name="bottom_to_webcam" type="fixed">
    <origin rpy="0 0 0" xyz="0.2 0 0.21"/>
    <child link="webcam_link"/>
    <parent link="bottom_body_box"/>
  </joint>
  <!-- Connection between bottom kinect and top body-->
  <joint name="bottom_kinect_to_top_body" type="fixed">
    <origin rpy="0 0.33 0" xyz="0.07 0 1.66"/>
    <child link="camera_link"/>
    <parent link="chassis"/>
  </joint>
  <!-- Connection between top kinect and top body-->
  <joint name="top_kinect_to_top_body" type="fixed">
    <origin rpy="0 1.24 0" xyz="0.2 0 1.43"/>
    <child link="camera2_link"/>
    <parent link="chassis"/>
  </joint>
  <!-- Mico -->
  <material name="JacoGrey">
    <color rgba="0.2 0.2 0.9 1.0"/>
  </material>
  <joint name="mico_base_joint" type="fixed">
    <origin rpy="0 0 1.57" xyz="0.1 0 0.31"/>
    <!-- fnh was: <origin xyz="0 0 0" rpy="0 0 0"/> -->
    <parent link="bottom_body_box"/>
    <child link="mico_base_link"/>
  </joint>
  <link name="mico_base_link">
    <inertial>
      <!-- fnh -->
      <origin xyz="0 0 0"/>
      <mass value="1.0"/>
      <inertia ixx="1" ixy="0" ixz="0" iyy="1" iyz="0" izz="1"/>
    </inertial>
    <visual>
      <material name="JacoGrey"/>
      <origin rpy="0 0 1.57079632679" xyz="0 0 0"/>
      <geometry>
        <mesh filename="package://jaco_description/meshes/jaco_base_joint.dae"/>
      </geometry>
    </visual>
    <collision>
      <origin rpy="0 0 1.57079632679" xyz="0 0 0"/>
      <geometry>
        <mesh filename="package://jaco_description/meshes/jaco_base_joint.dae"/>
      </geometry>
    </collision>
  </link>
  <gazebo reference="mico_base_link">
    <!-- fnh -->
    <material>Gazebo/Grey</material>
    <turnGravityOff>false</turnGravityOff>
    <selfCollide>true</selfCollide>
    <mu1>100.0</mu1>
    <mu2>100.0</mu2>
    <kp>1000000.0</kp>
    <kd>1.0</kd>
  </gazebo>
  <joint name="mico_shoulder_yaw_joint" type="revolute">
    <!--<origin xyz="0 0 ${D1}" rpy="0 0 0"/>-->
    <origin rpy="0 0 -1.57" xyz="0 0 0.2142"/>
    <axis rpy="0 0 0" xyz="0 0 1"/>
    <parent link="mico_base_link"/>
    <child link="mico_shoulder_link"/>
    <limit effort="200" lower="-3.04159265359" upper="3.04159265359" velocity="0.837758016"/>
    <dynamics damping="50.5"/>
  </joint>
  <transmission name="mico_shoulder_yaw_joint_transmission">
    <type>transmission_interface/SimpleTransmission</type>
    <actuator name="mico_shoulder_yaw_joint_motor">
      <hardwareInterface>EffortJointInterface</hardwareInterface>
      <mechanicalReduction>50</mechanicalReduction>
    </actuator>
    <joint name="mico_shoulder_yaw_joint"/>
    <mechanicalReduction>50</mechanicalReduction>
    <motorTorqueConstant>1</motorTorqueConstant>
    <pulsesPerRevolution>10000</pulsesPerRevolution>
  </transmission>
  <link name="mico_shoulder_link">
    <inertial>
      <!-- fnh -->
      <origin xyz="0 0 0"/>
      <mass value="1.0"/>
      <inertia ixx="1" ixy="0" ixz="0" iyy="1" iyz="0" izz="1"/>
    </inertial>
    <visual>
      <material name="JacoGrey"/>
      <origin rpy="1.57079632679 -1.57079632679 0" xyz="0 0 0"/>
      <geometry>
        <mesh filename="package://jaco_description/meshes/jaco_shoulder_yaw_joint.dae"/>
      </geometry>
    </visual>
    <collision>
      <origin rpy="1.57079632679 -1.57079632679 0" xyz="0 0 0"/>
      <geometry>
        <mesh filename="package://jaco_description/meshes/jaco_shoulder_yaw_joint.dae"/>
      </geometry>
    </collision>
  </link>
  <gazebo reference="mico_shoulder_link">
    <!-- fnh -->
    <material>Gazebo/Grey</material>
    <turnGravityOff>false</turnGravityOff>
    <selfCollide>true</selfCollide>
    <mu1>100.0</mu1>
    <mu2>100.0</mu2>
    <kp>1000000.0</kp>
    <kd>1.0</kd>
  </gazebo>
  <joint name="mico_shoulder_pitch_joint" type="revolute">
    <origin rpy="-1.57079632679 0 0" xyz="0 -1e-06 0"/>
    <axis xyz="0 0 1"/>
    <parent link="mico_shoulder_link"/>
    <child link="mico_upper_arm_link"/>
    <limit effort="300" lower="-3.83972424" upper="0.69813168" velocity="0.837758016"/>
    <dynamics damping="50.5"/>
  </joint>
  <transmission name="mico_shoulder_pitch_joint_transmission">
    <type>transmission_interface/SimpleTransmission</type>
    <actuator name="mico_shoulder_pitch_joint_motor">
      <hardwareInterface>EffortJointInterface</hardwareInterface>
      <mechanicalReduction>50</mechanicalReduction>
    </actuator>
    <joint name="mico_shoulder_pitch_joint"/>
    <mechanicalReduction>50</mechanicalReduction>
    <motorTorqueConstant>1</motorTorqueConstant>
    <pulsesPerRevolution>10000</pulsesPerRevolution>
  </transmission>
  <link name="mico_upper_arm_link">
    <inertial>
      <!-- fnh -->
      <origin xyz="0 0 0"/>
      <mass value="1.0"/>
      <inertia ixx="1" ixy="0" ixz="0" iyy="1" iyz="0" izz="1"/>
    </inertial>
    <visual>
      <material name="JacoGrey"/>
      <origin rpy="0 0 -1.57079632679" xyz="0 0 0"/>
      <geometry>
        <mesh filename="package://jaco_description/meshes/jaco_shoulder_pitch_joint.dae" scale="1 0.707317073171 1"/>
      </geometry>
    </visual>
    <collision>
      <origin rpy="0 0 -1.57079632679" xyz="0 0 0"/>
      <geometry>
        <mesh filename="package://jaco_description/meshes/jaco_shoulder_pitch_joint.dae" scale="1 0.707317073171 1"/>
      </geometry>
    </collision>
  </link>
  <gazebo reference="mico_upper_arm_link">
    <!-- fnh -->
    <material>Gazebo/Grey</material>
    <turnGravityOff>false</turnGravityOff>
    <selfCollide>true</selfCollide>
    <mu1>100.0</mu1>
    <mu2>100.0</mu2>
    <kp>1000000.0</kp>
    <kd>1.0</kd>
  </gazebo>
  <joint name="mico_elbow_pitch_joint" type="revolute">
    <origin rpy="0 0 0" xyz="0.29 0 0.012001"/>
    <axis xyz="0 0 1"/>
    <parent link="mico_upper_arm_link"/>
    <child link="mico_lower_arm_link"/>
    <limit effort="200" lower="-4.363323" upper="1.22173044" velocity="0.837758016"/>
    <dynamics damping="50.5"/>
  </joint>
  <transmission name="mico_elbow_pitch_joint_transmission">
    <type>transmission_interface/SimpleTransmission</type>
    <actuator name="mico_elbow_pitch_joint_motor">
      <hardwareInterface>EffortJointInterface</hardwareInterface>
      <mechanicalReduction>50</mechanicalReduction>
    </actuator>
    <joint name="mico_elbow_pitch_joint"/>
    <mechanicalReduction>50</mechanicalReduction>
    <motorTorqueConstant>1</motorTorqueConstant>
    <pulsesPerRevolution>10000</pulsesPerRevolution>
  </transmission>
  <link name="mico_lower_arm_link">
    <inertial>
      <!-- fnh -->
      <origin xyz="0 0 0"/>
      <mass value="0.8"/>
      <inertia ixx="1" ixy="0" ixz="0" iyy="1" iyz="0" izz="1"/>
    </inertial>
    <visual>
      <material name="JacoGrey"/>
      <origin rpy="3.14159265359 0 3.14159265359" xyz="0 0 -0.012"/>
      <geometry>
        <mesh filename="package://jaco_description/meshes/jaco_elbow_pitch_joint.dae" scale="1 0.601463414634 1"/>
      </geometry>
    </visual>
    <collision>
      <origin rpy="3.14159265359 0 3.14159265359" xyz="0 0 -0.012"/>
      <geometry>
        <mesh filename="package://jaco_description/meshes/jaco_elbow_pitch_joint.dae" scale="1 0.601463414634 1"/>
      </geometry>
    </collision>
  </link>
  <gazebo reference="mico_lower_arm_link">
    <!-- fnh -->
    <material>Gazebo/Grey</material>
    <turnGravityOff>false</turnGravityOff>
    <selfCollide>true</selfCollide>
    <mu1>100.0</mu1>
    <mu2>100.0</mu2>
    <kp>1000000.0</kp>
    <kd>1.0</kd>
  </gazebo>
  <joint name="mico_elbow_roll_joint" type="revolute">
    <origin rpy="-1.57079632679 0 0" xyz="0 0.165571 0 "/>
    <axis xyz="0 0 1"/>
    <parent link="mico_lower_arm_link"/>
    <child link="mico_lower_arm_roll_link"/>
    <limit effort="40" lower="-3.04159265359" upper="3.04159265359" velocity="1.04719752"/>
    <dynamics damping="50.5"/>
  </joint>
  <transmission name="mico_elbow_roll_joint_transmission">
    <type>transmission_interface/SimpleTransmission</type>
    <actuator name="mico_elbow_roll_joint_motor">
      <hardwareInterface>EffortJointInterface</hardwareInterface>
      <mechanicalReduction>50</mechanicalReduction>
    </actuator>
    <joint name="mico_elbow_roll_joint"/>
    <mechanicalReduction>50</mechanicalReduction>
    <motorTorqueConstant>1</motorTorqueConstant>
    <pulsesPerRevolution>10000</pulsesPerRevolution>
  </transmission>
  <link name="mico_lower_arm_roll_link">
    <inertial>
      <!-- fnh -->
      <origin xyz="0 0 0"/>
      <mass value="0.5"/>
      <inertia ixx="1" ixy="0" ixz="0" iyy="1" iyz="0" izz="1"/>
    </inertial>
    <visual>
      <material name="JacoGrey"/>
      <origin rpy="3.14159265359 0 1.57079632679" xyz="0 0 -0.04227"/>
      <geometry>
        <mesh filename="package://jaco_description/meshes/jaco_elbow_roll_joint.dae"/>
      </geometry>
    </visual>
    <collision>
      <origin rpy="3.14159265359 0 1.57079632679" xyz="0 0 -0.04227"/>
      <geometry>
        <mesh filename="package://jaco_description/meshes/jaco_elbow_roll_joint.dae"/>
      </geometry>
    </collision>
  </link>
  <gazebo reference="mico_lower_arm_roll_link">
    <!-- fnh -->
    <material>Gazebo/Grey</material>
    <turnGravityOff>false</turnGravityOff>
    <selfCollide>true</selfCollide>
    <mu1>100.0</mu1>
    <mu2>100.0</mu2>
    <kp>1000000.0</kp>
    <kd>1.0</kd>
  </gazebo>
  <joint name="mico_wrist_roll_joint" type="revolute">
    <origin rpy="0.959931088597 0 0" xyz="0 -0.0692622919853 0.0484979789618"/>
    <axis xyz="0 0 1"/>
    <parent link="mico_lower_arm_roll_link"/>
    <child link="mico_wrist_link"/>
    <limit effort="40" lower="-3.04159265359" upper="3.04159265359" velocity="1.04719752"/>
    <dynamics damping="50.5"/>
  </joint>
  <transmission name="mico_wrist_roll_joint_transmission">
    <type>transmission_interface/SimpleTransmission</type>
    <actuator name="mico_wrist_roll_joint_motor">
      <hardwareInterface>EffortJointInterface</hardwareInterface>
      <mechanicalReduction>50</mechanicalReduction>
    </actuator>
    <joint name="mico_wrist_roll_joint"/>
    <mechanicalReduction>50</mechanicalReduction>
    <motorTorqueConstant>1</motorTorqueConstant>
    <pulsesPerRevolution>10000</pulsesPerRevolution>
  </transmission>
  <link name="mico_wrist_link">
    <inertial>
      <!-- fnh -->
      <origin xyz="0 0 0"/>
      <mass value="0.5"/>
      <inertia ixx="1" ixy="0" ixz="0" iyy="1" iyz="0" izz="1"/>
    </inertial>
    <visual>
      <material name="JacoGrey"/>
      <origin rpy="0 3.14159265359 -1.57079632679" xyz="0 0 -0.0422768230075"/>
      <geometry>
        <mesh filename="package://jaco_description/meshes/jaco_wrist_roll_joint.dae"/>
      </geometry>
    </visual>
    <collision>
      <origin rpy="0 3.14159265359 -1.57079632679" xyz="0 0 -0.0422768230075"/>
      <geometry>
        <mesh filename="package://jaco_description/meshes/jaco_wrist_roll_joint.dae"/>
      </geometry>
    </collision>
  </link>
  <gazebo reference="mico_wrist_link">
    <!-- fnh -->
    <material>Gazebo/Grey</material>
    <turnGravityOff>false</turnGravityOff>
    <selfCollide>true</selfCollide>
    <mu1>100.0</mu1>
    <mu2>100.0</mu2>
    <kp>1000000.0</kp>
    <kd>1.0</kd>
  </gazebo>
  <joint name="mico_hand_roll_joint" type="revolute">
    <origin rpy="0.959931088597 0 0" xyz="0 -0.186174274186 0.130360630206"/>
    <axis xyz="0 0 1"/>
    <parent link="mico_wrist_link"/>
    <child link="mico_hand_link"/>
    <limit effort="40" lower="-3.04159265359" upper="3.04159265359" velocity="1.04719752"/>
    <dynamics damping="50.5"/>
  </joint>
  <transmission name="mico_hand_roll_joint_transmission">
    <type>transmission_interface/SimpleTransmission</type>
    <actuator name="mico_hand_roll_joint_motor">
      <hardwareInterface>EffortJointInterface</hardwareInterface>
      <mechanicalReduction>50</mechanicalReduction>
    </actuator>
    <joint name="mico_hand_roll_joint"/>
    <mechanicalReduction>50</mechanicalReduction>
    <motorTorqueConstant>1</motorTorqueConstant>
    <pulsesPerRevolution>10000</pulsesPerRevolution>
  </transmission>
  <link name="mico_hand_link">
    <inertial>
      <!-- fnh -->
      <origin xyz="0 0 0"/>
      <mass value="0.6"/>
      <inertia ixx="1" ixy="0" ixz="0" iyy="1" iyz="0" izz="1"/>
    </inertial>
    <visual>
      <material name="JacoGrey"/>
      <origin rpy="0 0 -3.14159265359" xyz="0 0 -0.185"/>
      <geometry>
        <mesh filename="package://jaco_description/meshes/jaco_hand_roll_joint.dae"/>
      </geometry>
    </visual>
    <collision>
      <origin rpy="0 0 -3.14159265359" xyz="0 0 -0.185"/>
      <geometry>
        <!--<mesh filename="package://jaco_description/meshes/jaco_hand_roll_joint.stl" scale="0.9 0.9 0.7" />  fnh -->
        <mesh filename="package://jaco_description/meshes/jaco_hand_roll_joint.dae"/>
      </geometry>
    </collision>
  </link>
  <gazebo reference="mico_hand_link">
    <!-- fnh -->
    <material>Gazebo/Grey</material>
    <turnGravityOff>false</turnGravityOff>
    <selfCollide>true</selfCollide>
    <mu1>100.0</mu1>
    <mu2>100.0</mu2>
    <kp>1000000.0</kp>
    <kd>1.0</kd>
  </gazebo>
  <joint name="mico_finger_1_joint" type="revolute">
    <!-- <origin xyz="-0.036 0.021 ${-0.07}" rpy="0 ${-M_PI/7} 0"/> -->
    <origin rpy="0 -0.448798950513 0" xyz="-0.036 0.021 -0.07"/>
    <axis xyz="0 1 0"/>
    <parent link="mico_hand_link"/>
    <child link="mico_finger_1_link"/>
    <limit effort="10" lower="-0.1" upper="1.04719752" velocity="1.0"/>
    <dynamics damping="50.5"/>
  </joint>
  <transmission name="mico_finger_1_joint_transmission">
    <type>transmission_interfacmico_arm_v0e/SimpleTransmission</type>
    <actuator name="mico_finger_1_joint_motor">
      <hardwareInterface>EffortJointInterface</hardwareInterface>
      <mechanicalReduction>50</mechanicalReduction>
    </actuator>
    <joint name="mico_finger_1_joint"/>
    <mechanicalReduction>50</mechanicalReduction>
    <motorTorqueConstant>1</motorTorqueConstant>
    <pulsesPerRevolution>10000</pulsesPerRevolution>
  </transmission>
  <link name="mico_finger_1_link">
    <inertial>
      <!-- fnh -->
      <origin xyz="0 0 0"/>
      <mass value="0.1"/>
      <inertia ixx="1" ixy="0" ixz="0" iyy="1" iyz="0" izz="1"/>
    </inertial>
    <visual>
      <material name="JacoGrey"/>
      <origin rpy="0 0 0" xyz="0 0 0"/>
      <geometry>
        <mesh filename="package://jaco_description/meshes/finger_new.dae"/>
      </geometry>
    </visual>
    <collision>
      <origin rpy="0 0 0" xyz="0 0 0"/>
      <geometry>
        <mesh filename="package://jaco_description/meshes/finger_new.dae"/>
      </geometry>
    </collision>
  </link>
  <gazebo reference="mico_finger_1_link">
    <!-- fnh -->
    <material>Gazebo/Grey</material>
    <turnGravityOff>false</turnGravityOff>
    <selfCollide>true</selfCollide>
    <mu1>100.0</mu1>
    <mu2>100.0</mu2>
    <kp>1000000.0</kp>
    <kd>1.0</kd>
  </gazebo>
  <joint name="mico_finger_2_joint" type="revolute">
    <origin rpy="0 -0.448798950513 -3.14159265359" xyz="0.036 -0 -0.07"/>
    <axis xyz="0 1 0"/>
    <parent link="mico_hand_link"/>
    <child link="mico_finger_2_link"/>
    <limit effort="10" lower="-0.1" upper="1.04719752" velocity="1.0"/>
    <dynamics damping="50.5"/>
  </joint>
  <transmission name="mico_finger_2_joint_transmission">
    <type>transmission_interface/SimpleTransmission</type>
    <actuator name="mico_finger_2_joint_motor">
      <hardwareInterface>EffortJointInterface</hardwareInterface>
      <mechanicalReduction>50</mechanicalReduction>
    </actuator>
    <joint name="mico_finger_2_joint"/>
    <mechanicalReduction>50</mechanicalReduction>
    <motorTorqueConstant>1</motorTorqueConstant>
    <pulsesPerRevolution>10000</pulsesPerRevolution>
  </transmission>
  <link name="mico_finger_2_link">
    <inertial>
      <!-- fnh -->
      <origin xyz="0 0 0"/>
      <mass value="0.1"/>
      <inertia ixx="1" ixy="0" ixz="0" iyy="1" iyz="0" izz="1"/>
    </inertial>
    <visual>
      <material name="JacoGrey"/>
      <origin rpy="0 0 0" xyz="0 0 0"/>
      <geometry>
        <mesh filename="package://jaco_description/meshes/finger_new.dae"/>
      </geometry>
    </visual>
    <collision>
      <origin rpy="0 0 0" xyz="0 0 0"/>
      <geometry>
        <mesh filename="package://jaco_description/meshes/finger_new.dae"/>
      </geometry>
    </collision>
  </link>
  <gazebo reference="mico_finger_2_link">
    <!-- fnh -->
    <material>Gazebo/Grey</material>
    <turnGravityOff>false</turnGravityOff>
    <selfCollide>true</selfCollide>
    <mu1>100.0</mu1>
    <mu2>100.0</mu2>
    <kp>1000000.0</kp>
    <kd>1.0</kd>
  </gazebo>
  <joint name="mico_finger_3_joint" type="revolute">
    <origin rpy="0 -0.448798950513 0" xyz="-0.036 -0.021 -0.07"/>
    <axis xyz="0 1 0"/>
    <parent link="mico_hand_link"/>
    <child link="mico_finger_3_link"/>
    <limit effort="10" lower="-0.1" upper="1.04719752" velocity="1.0"/>
    <dynamics damping="50.5"/>
  </joint>
  <transmission name="mico_finger_3_joint_transmission">
    <type>transmission_interface/SimpleTransmission</type>
    <actuator name="mico_finger_3_joint_motor">
      <hardwareInterface>EffortJointInterface</hardwareInterface>
      <mechanicalReduction>50</mechanicalReduction>
    </actuator>
    <joint name="mico_finger_3_joint"/>
    <mechanicalReduction>50</mechanicalReduction>
    <motorTorqueConstant>1</motorTorqueConstant>
    <pulsesPerRevolution>10000</pulsesPerRevolution>
  </transmission>
  <link name="mico_finger_3_link">
    <inertial>
      <!-- fnh -->
      <origin xyz="0 0 0"/>
      <mass value="0.1"/>
      <inertia ixx="1" ixy="0" ixz="0" iyy="1" iyz="0" izz="1"/>
    </inertial>
    <visual>
      <material name="JacoGrey"/>
      <origin rpy="0 0 0" xyz="0 0 0"/>
      <geometry>
        <mesh filename="package://jaco_description/meshes/finger_new.dae"/>
      </geometry>
    </visual>
    <collision>
      <origin rpy="0 0 0" xyz="0 0 0"/>
      <geometry>
        <mesh filename="package://jaco_description/meshes/finger_new.dae"/>
      </geometry>
    </collision>
  </link>
  <gazebo reference="mico_finger_3_link">
    <!-- fnh -->
    <material>Gazebo/Grey</material>
    <turnGravityOff>false</turnGravityOff>
    <selfCollide>true</selfCollide>
    <mu1>100.0</mu1>
    <mu2>100.0</mu2>
    <kp>1000000.0</kp>
    <kd>1.0</kd>
  </gazebo>
</robot>
