<sdf version='1.6'>
  <world name='default'>
    <light name='sun' type='directional'>
      <cast_shadows>1</cast_shadows>
      <pose frame=''>0 0 10 0 -0 0</pose>
      <diffuse>0.8 0.8 0.8 1</diffuse>
      <specular>0.2 0.2 0.2 1</specular>
      <attenuation>
        <range>1000</range>
        <constant>0.9</constant>
        <linear>0.01</linear>
        <quadratic>0.001</quadratic>
      </attenuation>
      <direction>-0.5 0.1 -0.9</direction>
    </light>
    <model name='ground_plane'>
      <static>1</static>
      <link name='link'>
        <collision name='collision'>
          <geometry>
            <plane>
              <normal>0 0 1</normal>
              <size>100 100</size>
            </plane>
          </geometry>
          <surface>
            <friction>
              <ode>
                <mu>100</mu>
                <mu2>50</mu2>
              </ode>
              <torsional>
                <ode/>
              </torsional>
            </friction>
            <contact>
              <ode/>
            </contact>
            <bounce/>
          </surface>
          <max_contacts>10</max_contacts>
        </collision>
        <visual name='visual'>
          <cast_shadows>0</cast_shadows>
          <geometry>
            <plane>
              <normal>0 0 1</normal>
              <size>100 100</size>
            </plane>
          </geometry>
          <material>
            <script>
              <uri>file://media/materials/scripts/gazebo.material</uri>
              <name>Gazebo/Grey</name>
            </script>
          </material>
        </visual>
        <self_collide>0</self_collide>
        <kinematic>0</kinematic>
      </link>
    </model>
    <gravity>0 0 -9.8</gravity>
    <magnetic_field>6e-06 2.3e-05 -4.2e-05</magnetic_field>
    <atmosphere type='adiabatic'/>
    <physics name='default_physics' default='0' type='ode'>
      <max_step_size>0.001</max_step_size>
      <real_time_factor>1</real_time_factor>
      <real_time_update_rate>1000</real_time_update_rate>
    </physics>
    <scene>
      <ambient>0.4 0.4 0.4 1</ambient>
      <background>0.7 0.7 0.7 1</background>
      <shadows>1</shadows>
    </scene>
    <spherical_coordinates>
      <surface_model>EARTH_WGS84</surface_model>
      <latitude_deg>0</latitude_deg>
      <longitude_deg>0</longitude_deg>
      <elevation>0</elevation>
      <heading_deg>0</heading_deg>
    </spherical_coordinates>
    <model name='mico-spawn'>
      <link name='root'>
        <pose frame=''>0 0 0 0 -0 0</pose>
        <inertial>
          <pose frame=''>0 0 5.5e-05 0 -0 0</pose>
          <mass>10002.2</mass>
          <inertia>
            <ixx>3.82412</ixx>
            <ixy>-6.8551e-16</ixy>
            <ixz>4.16006e-32</ixz>
            <iyy>3.82356</iyy>
            <iyz>3.36776e-20</iyz>
            <izz>3.00058</izz>
          </inertia>
        </inertial>
        <collision name='root_collision'>
          <pose frame=''>0 0 0 0 -0 0</pose>
          <geometry>
            <box>
              <size>0.5 0.5 0.02</size>
            </box>
          </geometry>
          <max_contacts>10</max_contacts>
          <surface>
            <contact>
              <ode/>
            </contact>
            <bounce/>
            <friction>
              <torsional>
                <ode/>
              </torsional>
              <ode/>
            </friction>
          </surface>
        </collision>
        <collision name='root_fixed_joint_lump__mico_link_base_collision_1'>
          <pose frame=''>0 0 0 0 -0 0</pose>
          <geometry>
            <mesh>
              <scale>1 1 1</scale>
              <uri>/home/student/sudo/ros/catkin_ws/src/mico_gazebo/meshes/mico_link_base.dae</uri>
            </mesh>
          </geometry>
          <surface>
            <contact>
              <ode>
                <kp>1e+06</kp>
                <kd>1</kd>
              </ode>
            </contact>
            <friction>
              <ode>
                <mu>100</mu>
                <mu2>100</mu2>
              </ode>
              <torsional>
                <ode/>
              </torsional>
            </friction>
            <bounce/>
          </surface>
          <max_contacts>10</max_contacts>
        </collision>
        <collision name='root_fixed_joint_lump__mico_large_ring_cover_1_collision_2'>
          <pose frame=''>0 0 0.1535 -3.14159 -0 0</pose>
          <geometry>
            <mesh>
              <scale>1 1 1</scale>
              <uri>/home/student/sudo/ros/catkin_ws/src/mico_gazebo/meshes/mico_large_ring_cover.dae</uri>
            </mesh>
          </geometry>
          <surface>
            <contact>
              <ode>
                <kp>1e+06</kp>
                <kd>1</kd>
              </ode>
            </contact>
            <friction>
              <ode>
                <mu>100</mu>
                <mu2>100</mu2>
              </ode>
              <torsional>
                <ode/>
              </torsional>
            </friction>
            <bounce/>
          </surface>
          <max_contacts>10</max_contacts>
        </collision>
        <collision name='root_fixed_joint_lump__front_xtion_link_collision_3'>
          <pose frame=''>0 0 2 1.57079 1.57079 1.57079</pose>
          <geometry>
            <mesh>
              <scale>1 1 1</scale>
              <uri>/home/student/sudo/ros/catkin_ws/src/alice_description/models/box.dae</uri>
            </mesh>
          </geometry>
          <surface>
            <contact>
              <ode/>
            </contact>
            <friction>
              <ode/>
              <torsional>
                <ode/>
              </torsional>
            </friction>
            <bounce/>
          </surface>
          <max_contacts>10</max_contacts>
        </collision>
        <visual name='root_visual'>
          <pose frame=''>0 0 0 0 -0 0</pose>
          <geometry>
            <box>
              <size>0.5 0.5 0.02</size>
            </box>
          </geometry>
        </visual>
        <visual name='root_fixed_joint_lump__mico_link_base_visual_1'>
          <pose frame=''>0 0 0 0 -0 0</pose>
          <geometry>
            <mesh>
              <scale>1 1 1</scale>
              <uri>/home/student/sudo/ros/catkin_ws/src/mico_gazebo/meshes/mico_link_base.dae</uri>
            </mesh>
          </geometry>
          <material>
            <script>
              <name>Gazebo/Grey</name>
              <uri>file://media/materials/scripts/gazebo.material</uri>
            </script>
          </material>
        </visual>
        <visual name='root_fixed_joint_lump__mico_large_ring_cover_1_visual_2'>
          <pose frame=''>0 0 0.1535 -3.14159 -0 0</pose>
          <geometry>
            <mesh>
              <scale>1 1 1</scale>
              <uri>/home/student/sudo/ros/catkin_ws/src/mico_gazebo/meshes/mico_large_ring_cover.dae</uri>
            </mesh>
          </geometry>
          <material>
            <script>
              <name>Gazebo/Grey</name>
              <uri>file://media/materials/scripts/gazebo.material</uri>
            </script>
          </material>
        </visual>
        <visual name='root_fixed_joint_lump__front_xtion_link_visual_3'>
          <pose frame=''>0 0 2 1.57079 1.57079 1.57079</pose>
          <geometry>
            <mesh>
              <scale>1 1 1</scale>
              <uri>/home/student/sudo/ros/catkin_ws/src/alice_description/models/box.dae</uri>
            </mesh>
          </geometry>
          <material>
            <script>
              <uri>__default__</uri>
              <name>__default__</name>
            </script>
          </material>
        </visual>
        <velocity_decay/>
        <velocity_decay/>
        <gravity>1</gravity>
        <velocity_decay/>
        <self_collide>0</self_collide>
        <sensor name='front_xtion' type='depth'>
          <always_on>1</always_on>
          <visualize>1</visualize>
          <camera name='__default__'>
            <horizontal_fov>1.047</horizontal_fov>
            <image>
              <width>320</width>
              <height>240</height>
              <format>R8G8B8</format>
            </image>
            <depth_camera>
              <output>depths</output>
            </depth_camera>
            <clip>
              <near>0.1</near>
              <far>100</far>
            </clip>
          </camera>
          <plugin name='camera_controller' filename='libgazebo_ros_openni_kinect.so'>
            <alwaysOn>true</alwaysOn>
            <updateRate>30.0</updateRate>
            <cameraName>front_xtion</cameraName>
            <frameName>front_rgb_optical_link</frameName>
            <imageTopicName>rgb/image_raw</imageTopicName>
            <depthImageTopicName>depth/image_raw</depthImageTopicName>
            <pointCloudTopicName>depth/points</pointCloudTopicName>
            <cameraInfoTopicName>rgb/camera_info</cameraInfoTopicName>
            <depthImageCameraInfoTopicName>depth/camera_info</depthImageCameraInfoTopicName>
            <pointCloudCutoff>0.35</pointCloudCutoff>
            <pointCloudCutoffMax>4.5</pointCloudCutoffMax>
            <hackBaseline>0.07</hackBaseline>
            <distortionK1>0.0</distortionK1>
            <distortionK2>0.0</distortionK2>
            <distortionK3>0.0</distortionK3>
            <distortionT1>0.0</distortionT1>
            <distortionT2>0.0</distortionT2>
            <CxPrime>0.0</CxPrime>
            <Cx>0.0</Cx>
            <Cy>0.0</Cy>
            <focalLength>0.0</focalLength>
            <robotNamespace>/</robotNamespace>
          </plugin>
          <pose frame=''>0 0 2 1.57079 1.57079 1.57079</pose>
        </sensor>
        <kinematic>0</kinematic>
      </link>
      <joint name='fixed' type='revolute'>
        <child>root</child>
        <parent>world</parent>
        <axis>
          <limit>
            <lower>0</lower>
            <upper>0</upper>
          </limit>
          <dynamics>
            <damping>0</damping>
            <friction>0</friction>
            <spring_reference>0</spring_reference>
            <spring_stiffness>0</spring_stiffness>
          </dynamics>
          <use_parent_model_frame>1</use_parent_model_frame>
          <xyz>0 0 1</xyz>
        </axis>
      </joint>
      <link name='mico_link_1'>
        <pose frame=''>0 0 0.1535 -3.14159 -0 0</pose>
        <inertial>
          <pose frame=''>0 0 -0.05925 0 -0 0</pose>
          <mass>2</mass>
          <inertia>
            <ixx>2.00702</ixx>
            <ixy>0</ixy>
            <ixz>0</ixz>
            <iyy>2.00702</iyy>
            <iyz>0</iyz>
            <izz>2</izz>
          </inertia>
        </inertial>
        <collision name='mico_link_1_collision'>
          <pose frame=''>0 0 0 0 -0 0</pose>
          <geometry>
            <mesh>
              <scale>1 1 1</scale>
              <uri>/home/student/sudo/ros/catkin_ws/src/mico_gazebo/meshes/mico_link_1.dae</uri>
            </mesh>
          </geometry>
          <surface>
            <contact>
              <ode>
                <kp>1e+06</kp>
                <kd>1</kd>
              </ode>
            </contact>
            <friction>
              <ode>
                <mu>100</mu>
                <mu2>100</mu2>
              </ode>
              <torsional>
                <ode/>
              </torsional>
            </friction>
            <bounce/>
          </surface>
          <max_contacts>10</max_contacts>
        </collision>
        <collision name='mico_link_1_fixed_joint_lump__mico_large_ring_cover_2_collision_1'>
          <pose frame=''>0 0 -0.1185 1.57078 -1.57079 -3.14158</pose>
          <geometry>
            <mesh>
              <scale>1 1 1</scale>
              <uri>/home/student/sudo/ros/catkin_ws/src/mico_gazebo/meshes/mico_large_ring_cover.dae</uri>
            </mesh>
          </geometry>
          <surface>
            <contact>
              <ode>
                <kp>1e+06</kp>
                <kd>1</kd>
              </ode>
            </contact>
            <friction>
              <ode>
                <mu>100</mu>
                <mu2>100</mu2>
              </ode>
              <torsional>
                <ode/>
              </torsional>
            </friction>
            <bounce/>
          </surface>
          <max_contacts>10</max_contacts>
        </collision>
        <visual name='mico_link_1_visual'>
          <pose frame=''>0 0 0 0 -0 0</pose>
          <geometry>
            <mesh>
              <scale>1 1 1</scale>
              <uri>/home/student/sudo/ros/catkin_ws/src/mico_gazebo/meshes/mico_link_1.dae</uri>
            </mesh>
          </geometry>
          <material>
            <script>
              <name>Gazebo/Grey</name>
              <uri>file://media/materials/scripts/gazebo.material</uri>
            </script>
          </material>
        </visual>
        <visual name='mico_link_1_fixed_joint_lump__mico_large_ring_cover_2_visual_1'>
          <pose frame=''>0 0 -0.1185 1.57078 -1.57079 -3.14158</pose>
          <geometry>
            <mesh>
              <scale>1 1 1</scale>
              <uri>/home/student/sudo/ros/catkin_ws/src/mico_gazebo/meshes/mico_large_ring_cover.dae</uri>
            </mesh>
          </geometry>
          <material>
            <script>
              <name>Gazebo/Grey</name>
              <uri>file://media/materials/scripts/gazebo.material</uri>
            </script>
          </material>
        </visual>
        <velocity_decay/>
        <gravity>1</gravity>
        <velocity_decay/>
        <self_collide>1</self_collide>
        <kinematic>0</kinematic>
      </link>
      <joint name='mico_joint_1' type='revolute'>
        <child>mico_link_1</child>
        <parent>root</parent>
        <axis>
          <xyz>0 0 -1</xyz>
          <limit>
            <lower>-1e+16</lower>
            <upper>1e+16</upper>
          </limit>
          <dynamics>
            <spring_reference>0</spring_reference>
            <spring_stiffness>0</spring_stiffness>
          </dynamics>
          <use_parent_model_frame>1</use_parent_model_frame>
        </axis>
      </joint>
      <link name='mico_link_2'>
        <pose frame=''>0 -0 0.272 -1.57079 1.57079 3.14159</pose>
        <inertial>
          <pose frame=''>0.145 0 0 0 -0 0</pose>
          <mass>2</mass>
          <inertia>
            <ixx>2</ixx>
            <ixy>0</ixy>
            <ixz>0</ixz>
            <iyy>2.04205</iyy>
            <iyz>0</iyz>
            <izz>2.04205</izz>
          </inertia>
        </inertial>
        <collision name='mico_link_2_collision'>
          <pose frame=''>0 0 0 0 -0 0</pose>
          <geometry>
            <mesh>
              <scale>1 1 1</scale>
              <uri>/home/student/sudo/ros/catkin_ws/src/mico_gazebo/meshes/mico_link_2.dae</uri>
            </mesh>
          </geometry>
          <surface>
            <contact>
              <ode>
                <kp>1e+06</kp>
                <kd>1</kd>
              </ode>
            </contact>
            <friction>
              <ode>
                <mu>100</mu>
                <mu2>100</mu2>
              </ode>
              <torsional>
                <ode/>
              </torsional>
            </friction>
            <bounce/>
          </surface>
          <max_contacts>10</max_contacts>
        </collision>
        <collision name='mico_link_2_fixed_joint_lump__mico_large_ring_cover_3_collision_1'>
          <pose frame=''>0.29 0 0 -3.14159 -0 -3.14159</pose>
          <geometry>
            <mesh>
              <scale>1 1 1</scale>
              <uri>/home/student/sudo/ros/catkin_ws/src/mico_gazebo/meshes/mico_large_ring_cover.dae</uri>
            </mesh>
          </geometry>
          <surface>
            <contact>
              <ode>
                <kp>1e+06</kp>
                <kd>1</kd>
              </ode>
            </contact>
            <friction>
              <ode>
                <mu>100</mu>
                <mu2>100</mu2>
              </ode>
              <torsional>
                <ode/>
              </torsional>
            </friction>
            <bounce/>
          </surface>
          <max_contacts>10</max_contacts>
        </collision>
        <visual name='mico_link_2_visual'>
          <pose frame=''>0 0 0 0 -0 0</pose>
          <geometry>
            <mesh>
              <scale>1 1 1</scale>
              <uri>/home/student/sudo/ros/catkin_ws/src/mico_gazebo/meshes/mico_link_2.dae</uri>
            </mesh>
          </geometry>
          <material>
            <script>
              <name>Gazebo/Grey</name>
              <uri>file://media/materials/scripts/gazebo.material</uri>
            </script>
          </material>
        </visual>
        <visual name='mico_link_2_fixed_joint_lump__mico_large_ring_cover_3_visual_1'>
          <pose frame=''>0.29 0 0 -3.14159 -0 -3.14159</pose>
          <geometry>
            <mesh>
              <scale>1 1 1</scale>
              <uri>/home/student/sudo/ros/catkin_ws/src/mico_gazebo/meshes/mico_large_ring_cover.dae</uri>
            </mesh>
          </geometry>
          <material>
            <script>
              <name>Gazebo/Grey</name>
              <uri>file://media/materials/scripts/gazebo.material</uri>
            </script>
          </material>
        </visual>
        <velocity_decay/>
        <gravity>1</gravity>
        <velocity_decay/>
        <self_collide>1</self_collide>
        <kinematic>0</kinematic>
      </link>
      <joint name='mico_joint_2' type='revolute'>
        <child>mico_link_2</child>
        <parent>mico_link_1</parent>
        <axis>
          <xyz>0 -1 0</xyz>
          <limit>
            <lower>0.872665</lower>
            <upper>5.41052</upper>
            <effort>30000</effort>
            <velocity>5</velocity>
          </limit>
          <dynamics>
            <spring_reference>0</spring_reference>
            <spring_stiffness>0</spring_stiffness>
          </dynamics>
          <use_parent_model_frame>1</use_parent_model_frame>
        </axis>
      </joint>
      <link name='mico_link_3'>
        <pose frame=''>0 0 -0.018 1.57079 -1.57079 3.14159</pose>
        <inertial>
          <pose frame=''>0.0615 0 -0.004225 0 -0 0</pose>
          <mass>2</mass>
          <inertia>
            <ixx>2.00004</ixx>
            <ixy>0</ixy>
            <ixz>0.000519675</ixz>
            <iyy>2.0076</iyy>
            <iyz>0</iyz>
            <izz>2.00756</izz>
          </inertia>
        </inertial>
        <collision name='mico_link_3_collision'>
          <pose frame=''>0 0 0 0 -0 0</pose>
          <geometry>
            <mesh>
              <scale>1 1 1</scale>
              <uri>/home/student/sudo/ros/catkin_ws/src/mico_gazebo/meshes/mico_link_3.dae</uri>
            </mesh>
          </geometry>
          <surface>
            <contact>
              <ode>
                <kp>1e+06</kp>
                <kd>1</kd>
              </ode>
            </contact>
            <friction>
              <ode>
                <mu>100</mu>
                <mu2>100</mu2>
              </ode>
              <torsional>
                <ode/>
              </torsional>
            </friction>
            <bounce/>
          </surface>
          <max_contacts>10</max_contacts>
        </collision>
        <collision name='mico_link_3_fixed_joint_lump__mico_small_ring_cover_1_collision_1'>
          <pose frame=''>0.123 0 -0.00845 3.14159 -1.57079 3.14159</pose>
          <geometry>
            <mesh>
              <scale>1 1 1</scale>
              <uri>/home/student/sudo/ros/catkin_ws/src/mico_gazebo/meshes/mico_small_ring_cover.dae</uri>
            </mesh>
          </geometry>
          <surface>
            <contact>
              <ode>
                <kp>1e+06</kp>
                <kd>1</kd>
              </ode>
            </contact>
            <friction>
              <ode>
                <mu>100</mu>
                <mu2>100</mu2>
              </ode>
              <torsional>
                <ode/>
              </torsional>
            </friction>
            <bounce/>
          </surface>
          <max_contacts>10</max_contacts>
        </collision>
        <visual name='mico_link_3_visual'>
          <pose frame=''>0 0 0 0 -0 0</pose>
          <geometry>
            <mesh>
              <scale>1 1 1</scale>
              <uri>/home/student/sudo/ros/catkin_ws/src/mico_gazebo/meshes/mico_link_3.dae</uri>
            </mesh>
          </geometry>
          <material>
            <script>
              <name>Gazebo/Grey</name>
              <uri>file://media/materials/scripts/gazebo.material</uri>
            </script>
          </material>
        </visual>
        <visual name='mico_link_3_fixed_joint_lump__mico_small_ring_cover_1_visual_1'>
          <pose frame=''>0.123 0 -0.00845 3.14159 -1.57079 3.14159</pose>
          <geometry>
            <mesh>
              <scale>1 1 1</scale>
              <uri>/home/student/sudo/ros/catkin_ws/src/mico_gazebo/meshes/mico_small_ring_cover.dae</uri>
            </mesh>
          </geometry>
          <material>
            <script>
              <name>Gazebo/Grey</name>
              <uri>file://media/materials/scripts/gazebo.material</uri>
            </script>
          </material>
        </visual>
        <velocity_decay/>
        <gravity>1</gravity>
        <velocity_decay/>
        <self_collide>1</self_collide>
        <kinematic>0</kinematic>
      </link>
      <joint name='mico_joint_3' type='revolute'>
        <child>mico_link_3</child>
        <parent>mico_link_2</parent>
        <axis>
          <xyz>0 1 0</xyz>
          <limit>
            <lower>0.610865</lower>
            <upper>5.67232</upper>
            <effort>30000</effort>
            <velocity>5</velocity>
          </limit>
          <dynamics>
            <spring_reference>0</spring_reference>
            <spring_stiffness>0</spring_stiffness>
          </dynamics>
          <use_parent_model_frame>1</use_parent_model_frame>
        </axis>
      </joint>
      <link name='mico_link_4'>
        <pose frame=''>0 -0.00845 0.105 3.14159 -0 1.5708</pose>
        <inertial>
          <pose frame=''>0.01715 0 -0.03294 0 -0 0</pose>
          <mass>2</mass>
          <inertia>
            <ixx>2.00217</ixx>
            <ixy>0</ixy>
            <ixz>0.00112984</ixz>
            <iyy>2.00276</iyy>
            <iyz>0</iyz>
            <izz>2.00059</izz>
          </inertia>
        </inertial>
        <collision name='mico_link_4_collision'>
          <pose frame=''>0 0 0 0 -0 0</pose>
          <geometry>
            <mesh>
              <scale>1 1 1</scale>
              <uri>/home/student/sudo/ros/catkin_ws/src/mico_gazebo/meshes/mico_link_4_5.dae</uri>
            </mesh>
          </geometry>
          <surface>
            <contact>
              <ode>
                <kp>1e+06</kp>
                <kd>1</kd>
              </ode>
            </contact>
            <friction>
              <ode>
                <mu>100</mu>
                <mu2>100</mu2>
              </ode>
              <torsional>
                <ode/>
              </torsional>
            </friction>
            <bounce/>
          </surface>
          <max_contacts>10</max_contacts>
        </collision>
        <collision name='mico_link_4_fixed_joint_lump__mico_small_ring_cover_2_collision_1'>
          <pose frame=''>0.0343 0 -0.06588 0 0.959931 -3.14159</pose>
          <geometry>
            <mesh>
              <scale>1 1 1</scale>
              <uri>/home/student/sudo/ros/catkin_ws/src/mico_gazebo/meshes/mico_small_ring_cover.dae</uri>
            </mesh>
          </geometry>
          <surface>
            <contact>
              <ode>
                <kp>1e+06</kp>
                <kd>1</kd>
              </ode>
            </contact>
            <friction>
              <ode>
                <mu>100</mu>
                <mu2>100</mu2>
              </ode>
              <torsional>
                <ode/>
              </torsional>
            </friction>
            <bounce/>
          </surface>
          <max_contacts>10</max_contacts>
        </collision>
        <visual name='mico_link_4_visual'>
          <pose frame=''>0 0 0 0 -0 0</pose>
          <geometry>
            <mesh>
              <scale>1 1 1</scale>
              <uri>/home/student/sudo/ros/catkin_ws/src/mico_gazebo/meshes/mico_link_4_5.dae</uri>
            </mesh>
          </geometry>
          <material>
            <script>
              <name>Gazebo/Grey</name>
              <uri>file://media/materials/scripts/gazebo.material</uri>
            </script>
          </material>
        </visual>
        <visual name='mico_link_4_fixed_joint_lump__mico_small_ring_cover_2_visual_1'>
          <pose frame=''>0.0343 0 -0.06588 0 0.959931 -3.14159</pose>
          <geometry>
            <mesh>
              <scale>1 1 1</scale>
              <uri>/home/student/sudo/ros/catkin_ws/src/mico_gazebo/meshes/mico_small_ring_cover.dae</uri>
            </mesh>
          </geometry>
          <material>
            <script>
              <name>Gazebo/Grey</name>
              <uri>file://media/materials/scripts/gazebo.material</uri>
            </script>
          </material>
        </visual>
        <velocity_decay/>
        <gravity>1</gravity>
        <velocity_decay/>
        <self_collide>1</self_collide>
        <kinematic>0</kinematic>
      </link>
      <joint name='mico_joint_4' type='revolute'>
        <child>mico_link_4</child>
        <parent>mico_link_3</parent>
        <axis>
          <xyz>0 0 -1</xyz>
          <limit>
            <lower>-1e+16</lower>
            <upper>1e+16</upper>
          </limit>
          <dynamics>
            <spring_reference>0</spring_reference>
            <spring_stiffness>0</spring_stiffness>
          </dynamics>
          <use_parent_model_frame>1</use_parent_model_frame>
        </axis>
      </joint>
      <link name='mico_link_5'>
        <pose frame=''>0 0.02585 0.17088 -3.14159 -0.959931 -1.5708</pose>
        <inertial>
          <pose frame=''>0.01715 0 -0.03294 0 -0 0</pose>
          <mass>2</mass>
          <inertia>
            <ixx>2.00217</ixx>
            <ixy>0</ixy>
            <ixz>0.00112984</ixz>
            <iyy>2.00276</iyy>
            <iyz>0</iyz>
            <izz>2.00059</izz>
          </inertia>
        </inertial>
        <collision name='mico_link_5_collision'>
          <pose frame=''>0 0 0 0 -0 0</pose>
          <geometry>
            <mesh>
              <scale>1 1 1</scale>
              <uri>/home/student/sudo/ros/catkin_ws/src/mico_gazebo/meshes/mico_link_4_5.dae</uri>
            </mesh>
          </geometry>
          <surface>
            <contact>
              <ode>
                <kp>1e+06</kp>
                <kd>1</kd>
              </ode>
            </contact>
            <friction>
              <ode>
                <mu>100</mu>
                <mu2>100</mu2>
              </ode>
              <torsional>
                <ode/>
              </torsional>
            </friction>
            <bounce/>
          </surface>
          <max_contacts>10</max_contacts>
        </collision>
        <collision name='mico_link_5_fixed_joint_lump__mico_small_ring_cover_3_collision_1'>
          <pose frame=''>0.0343 0 -0.06588 0 0.959931 -3.14159</pose>
          <geometry>
            <mesh>
              <scale>1 1 1</scale>
              <uri>/home/student/sudo/ros/catkin_ws/src/mico_gazebo/meshes/mico_small_ring_cover.dae</uri>
            </mesh>
          </geometry>
          <surface>
            <contact>
              <ode>
                <kp>1e+06</kp>
                <kd>1</kd>
              </ode>
            </contact>
            <friction>
              <ode>
                <mu>100</mu>
                <mu2>100</mu2>
              </ode>
              <torsional>
                <ode/>
              </torsional>
            </friction>
            <bounce/>
          </surface>
          <max_contacts>10</max_contacts>
        </collision>
        <visual name='mico_link_5_visual'>
          <pose frame=''>0 0 0 0 -0 0</pose>
          <geometry>
            <mesh>
              <scale>1 1 1</scale>
              <uri>/home/student/sudo/ros/catkin_ws/src/mico_gazebo/meshes/mico_link_4_5.dae</uri>
            </mesh>
          </geometry>
          <material>
            <script>
              <name>Gazebo/Grey</name>
              <uri>file://media/materials/scripts/gazebo.material</uri>
            </script>
          </material>
        </visual>
        <visual name='mico_link_5_fixed_joint_lump__mico_small_ring_cover_3_visual_1'>
          <pose frame=''>0.0343 0 -0.06588 0 0.959931 -3.14159</pose>
          <geometry>
            <mesh>
              <scale>1 1 1</scale>
              <uri>/home/student/sudo/ros/catkin_ws/src/mico_gazebo/meshes/mico_small_ring_cover.dae</uri>
            </mesh>
          </geometry>
          <material>
            <script>
              <name>Gazebo/Grey</name>
              <uri>file://media/materials/scripts/gazebo.material</uri>
            </script>
          </material>
        </visual>
        <velocity_decay/>
        <gravity>1</gravity>
        <velocity_decay/>
        <self_collide>1</self_collide>
        <kinematic>0</kinematic>
      </link>
      <joint name='mico_joint_5' type='revolute'>
        <child>mico_link_5</child>
        <parent>mico_link_4</parent>
        <axis>
          <xyz>0 -0.819152 -0.573576</xyz>
          <limit>
            <lower>-1e+16</lower>
            <upper>1e+16</upper>
          </limit>
          <dynamics>
            <spring_reference>0</spring_reference>
            <spring_stiffness>0</spring_stiffness>
          </dynamics>
          <use_parent_model_frame>1</use_parent_model_frame>
        </axis>
      </joint>
      <link name='mico_link_hand'>
        <pose frame=''>0 0.060142 0.236764 3.14159 -0 1.5708</pose>
        <inertial>
          <pose frame=''>0 0 0 0 -0 0</pose>
          <mass>1</mass>
          <inertia>
            <ixx>1</ixx>
            <ixy>0</ixy>
            <ixz>0</ixz>
            <iyy>1</iyy>
            <iyz>0</iyz>
            <izz>1</izz>
          </inertia>
        </inertial>
        <collision name='mico_link_hand_collision'>
          <pose frame=''>0 0 0 0 -0 0</pose>
          <geometry>
            <mesh>
              <scale>1 1 1</scale>
              <uri>/home/student/sudo/ros/catkin_ws/src/mico_gazebo/meshes/mico_link_hand.dae</uri>
            </mesh>
          </geometry>
          <surface>
            <contact>
              <ode>
                <kp>1e+06</kp>
                <kd>1</kd>
              </ode>
            </contact>
            <friction>
              <ode>
                <mu>100</mu>
                <mu2>100</mu2>
              </ode>
              <torsional>
                <ode/>
              </torsional>
            </friction>
            <bounce/>
          </surface>
          <max_contacts>10</max_contacts>
        </collision>
        <visual name='mico_link_hand_visual'>
          <pose frame=''>0 0 0 0 -0 0</pose>
          <geometry>
            <mesh>
              <scale>1 1 1</scale>
              <uri>/home/student/sudo/ros/catkin_ws/src/mico_gazebo/meshes/mico_link_hand.dae</uri>
            </mesh>
          </geometry>
          <material>
            <script>
              <name>Gazebo/Grey</name>
              <uri>file://media/materials/scripts/gazebo.material</uri>
            </script>
          </material>
        </visual>
        <gravity>1</gravity>
        <velocity_decay/>
        <self_collide>1</self_collide>
        <kinematic>0</kinematic>
      </link>
      <joint name='mico_joint_6' type='revolute'>
        <child>mico_link_hand</child>
        <parent>mico_link_5</parent>
        <axis>
          <xyz>0 0 -1</xyz>
          <limit>
            <lower>-1e+16</lower>
            <upper>1e+16</upper>
          </limit>
          <dynamics>
            <spring_reference>0</spring_reference>
            <spring_stiffness>0</spring_stiffness>
          </dynamics>
          <use_parent_model_frame>1</use_parent_model_frame>
        </axis>
      </joint>
      <link name='mico_link_finger_1'>
        <pose frame=''>-0 0.020362 0.337474 1.57089 -1.1 -1.5708</pose>
        <inertial>
          <pose frame=''>0.022047 -0.00145 0 0 -0 0</pose>
          <mass>2</mass>
          <inertia>
            <ixx>2</ixx>
            <ixy>6.39363e-05</ixy>
            <ixz>0</ixz>
            <iyy>2.00097</iyy>
            <iyz>0</iyz>
            <izz>2.00098</izz>
          </inertia>
        </inertial>
        <collision name='mico_link_finger_1_collision'>
          <pose frame=''>0 0 0 0 -0 0</pose>
          <geometry>
            <mesh>
              <scale>1 1 1</scale>
              <uri>/home/student/sudo/ros/catkin_ws/src/mico_gazebo/meshes/mico_link_finger.dae</uri>
            </mesh>
          </geometry>
          <surface>
            <contact>
              <ode>
                <kp>1e+06</kp>
                <kd>1</kd>
              </ode>
            </contact>
            <friction>
              <ode>
                <mu>100</mu>
                <mu2>100</mu2>
              </ode>
              <torsional>
                <ode/>
              </torsional>
            </friction>
            <bounce/>
          </surface>
          <max_contacts>10</max_contacts>
        </collision>
        <collision name='mico_link_finger_1_fixed_joint_lump__mico_link_finger_tip_1_collision_1'>
          <pose frame=''>0.044094 -0.0029 0 0 -0 0</pose>
          <geometry>
            <mesh>
              <scale>1 1 1</scale>
              <uri>/home/student/sudo/ros/catkin_ws/src/mico_gazebo/meshes/mico_link_finger_tip.dae</uri>
            </mesh>
          </geometry>
          <surface>
            <contact>
              <ode>
                <kp>1e+06</kp>
                <kd>1</kd>
              </ode>
            </contact>
            <friction>
              <ode>
                <mu>100</mu>
                <mu2>100</mu2>
              </ode>
              <torsional>
                <ode/>
              </torsional>
            </friction>
            <bounce/>
          </surface>
          <max_contacts>10</max_contacts>
        </collision>
        <visual name='mico_link_finger_1_visual'>
          <pose frame=''>0 0 0 0 -0 0</pose>
          <geometry>
            <mesh>
              <scale>1 1 1</scale>
              <uri>/home/student/sudo/ros/catkin_ws/src/mico_gazebo/meshes/mico_link_finger.dae</uri>
            </mesh>
          </geometry>
          <material>
            <script>
              <name>Gazebo/Grey</name>
              <uri>file://media/materials/scripts/gazebo.material</uri>
            </script>
          </material>
        </visual>
        <visual name='mico_link_finger_1_fixed_joint_lump__mico_link_finger_tip_1_visual_1'>
          <pose frame=''>0.044094 -0.0029 0 0 -0 0</pose>
          <geometry>
            <mesh>
              <scale>1 1 1</scale>
              <uri>/home/student/sudo/ros/catkin_ws/src/mico_gazebo/meshes/mico_link_finger_tip.dae</uri>
            </mesh>
          </geometry>
          <material>
            <script>
              <name>Gazebo/Grey</name>
              <uri>file://media/materials/scripts/gazebo.material</uri>
            </script>
          </material>
        </visual>
        <velocity_decay/>
        <gravity>1</gravity>
        <velocity_decay/>
        <self_collide>1</self_collide>
        <kinematic>0</kinematic>
      </link>
      <joint name='mico_joint_finger_1' type='revolute'>
        <child>mico_link_finger_1</child>
        <parent>mico_link_hand</parent>
        <axis>
          <xyz>-1 -7.9e-05 -4.4e-05</xyz>
          <limit>
            <lower>0</lower>
            <upper>0.698132</upper>
            <effort>30000</effort>
            <velocity>36</velocity>
          </limit>
          <dynamics>
            <spring_reference>0</spring_reference>
            <spring_stiffness>0</spring_stiffness>
          </dynamics>
          <use_parent_model_frame>1</use_parent_model_frame>
        </axis>
      </joint>
      <link name='mico_link_finger_2'>
        <pose frame=''>0 0.099922 0.337474 1.57089 -1.1 1.5708</pose>
        <inertial>
          <pose frame=''>0.022047 -0.00145 0 0 -0 0</pose>
          <mass>2</mass>
          <inertia>
            <ixx>2</ixx>
            <ixy>6.39363e-05</ixy>
            <ixz>0</ixz>
            <iyy>2.00097</iyy>
            <iyz>0</iyz>
            <izz>2.00098</izz>
          </inertia>
        </inertial>
        <collision name='mico_link_finger_2_collision'>
          <pose frame=''>0 0 0 0 -0 0</pose>
          <geometry>
            <mesh>
              <scale>1 1 1</scale>
              <uri>/home/student/sudo/ros/catkin_ws/src/mico_gazebo/meshes/mico_link_finger.dae</uri>
            </mesh>
          </geometry>
          <surface>
            <contact>
              <ode>
                <kp>1e+06</kp>
                <kd>1</kd>
              </ode>
            </contact>
            <friction>
              <ode>
                <mu>100</mu>
                <mu2>100</mu2>
              </ode>
              <torsional>
                <ode/>
              </torsional>
            </friction>
            <bounce/>
          </surface>
          <max_contacts>10</max_contacts>
        </collision>
        <collision name='mico_link_finger_2_fixed_joint_lump__mico_link_finger_tip_2_collision_1'>
          <pose frame=''>0.044094 -0.0029 0 0 -0 0</pose>
          <geometry>
            <mesh>
              <scale>1 1 1</scale>
              <uri>/home/student/sudo/ros/catkin_ws/src/mico_gazebo/meshes/mico_link_finger_tip.dae</uri>
            </mesh>
          </geometry>
          <surface>
            <contact>
              <ode>
                <kp>1e+06</kp>
                <kd>1</kd>
              </ode>
            </contact>
            <friction>
              <ode>
                <mu>100</mu>
                <mu2>100</mu2>
              </ode>
              <torsional>
                <ode/>
              </torsional>
            </friction>
            <bounce/>
          </surface>
          <max_contacts>10</max_contacts>
        </collision>
        <visual name='mico_link_finger_2_visual'>
          <pose frame=''>0 0 0 0 -0 0</pose>
          <geometry>
            <mesh>
              <scale>1 1 1</scale>
              <uri>/home/student/sudo/ros/catkin_ws/src/mico_gazebo/meshes/mico_link_finger.dae</uri>
            </mesh>
          </geometry>
          <material>
            <script>
              <name>Gazebo/Grey</name>
              <uri>file://media/materials/scripts/gazebo.material</uri>
            </script>
          </material>
        </visual>
        <visual name='mico_link_finger_2_fixed_joint_lump__mico_link_finger_tip_2_visual_1'>
          <pose frame=''>0.044094 -0.0029 0 0 -0 0</pose>
          <geometry>
            <mesh>
              <scale>1 1 1</scale>
              <uri>/home/student/sudo/ros/catkin_ws/src/mico_gazebo/meshes/mico_link_finger_tip.dae</uri>
            </mesh>
          </geometry>
          <material>
            <script>
              <name>Gazebo/Grey</name>
              <uri>file://media/materials/scripts/gazebo.material</uri>
            </script>
          </material>
        </visual>
        <velocity_decay/>
        <gravity>1</gravity>
        <velocity_decay/>
        <self_collide>1</self_collide>
        <kinematic>0</kinematic>
      </link>
      <joint name='mico_joint_finger_2' type='revolute'>
        <child>mico_link_finger_2</child>
        <parent>mico_link_hand</parent>
        <axis>
          <xyz>1 8.6e-05 -4.4e-05</xyz>
          <limit>
            <lower>0</lower>
            <upper>0.698132</upper>
            <effort>30000</effort>
            <velocity>36</velocity>
          </limit>
          <dynamics>
            <spring_reference>0</spring_reference>
            <spring_stiffness>0</spring_stiffness>
          </dynamics>
          <use_parent_model_frame>1</use_parent_model_frame>
        </axis>
      </joint>
      <plugin name='gazebo_ros_control' filename='libgazebo_ros_control.so'>
        <robotNamespace>/mico</robotNamespace>
      </plugin>
      <static>0</static>
      <gripper name='grasper'>
        <grasp_check>
          <attach_steps>2</attach_steps>
          <detach_steps>2</detach_steps>
          <min_contact_count>1</min_contact_count>
        </grasp_check>
        <gripper_link>mico_link_finger_1</gripper_link>
        <gripper_link>mico_link_finger_2</gripper_link>
        <palm_link>mico_link_hand</palm_link>
      </gripper>
      <pose frame=''>0 0 0.01 0 -0 0</pose>
    </model>
    <model name='board'>
      <link name='link'>
        <pose frame=''>0 0 0 0 -0 0</pose>
        <inertial>
          <mass>1</mass>
          <inertia>
            <ixx>0.166667</ixx>
            <ixy>0</ixy>
            <ixz>0</ixz>
            <iyy>0.166667</iyy>
            <iyz>0</iyz>
            <izz>0.166667</izz>
          </inertia>
          <pose frame=''>0 0 0 0 -0 0</pose>
        </inertial>
        <self_collide>0</self_collide>
        <kinematic>0</kinematic>
        <gravity>1</gravity>
        <visual name='visual'>
          <geometry>
            <box>
              <size>0.027451 1 1</size>
            </box>
          </geometry>
          <material>
            <script>
              <name>Gazebo/White</name>
              <uri>file://media/materials/scripts/gazebo.material</uri>
            </script>
            <ambient>1 1 1 1</ambient>
            <diffuse>1 1 1 1</diffuse>
            <specular>0.1 0.1 0.1 1</specular>
            <emissive>0 0 0 0</emissive>
            <shader type='vertex'>
              <normal_map>__default__</normal_map>
            </shader>
          </material>
          <pose frame=''>0 0 0 0 -0 0</pose>
          <transparency>0</transparency>
          <cast_shadows>1</cast_shadows>
        </visual>
        <collision name='collision'>
          <laser_retro>0</laser_retro>
          <max_contacts>10</max_contacts>
          <pose frame=''>0 0 0 0 -0 0</pose>
          <geometry>
            <box>
              <size>0.027451 1 1</size>
            </box>
          </geometry>
          <surface>
            <friction>
              <ode>
                <mu>1</mu>
                <mu2>1</mu2>
                <fdir1>0 0 0</fdir1>
                <slip1>0</slip1>
                <slip2>0</slip2>
              </ode>
              <torsional>
                <coefficient>1</coefficient>
                <patch_radius>0</patch_radius>
                <surface_radius>0</surface_radius>
                <use_patch_radius>1</use_patch_radius>
                <ode>
                  <slip>0</slip>
                </ode>
              </torsional>
            </friction>
            <bounce>
              <restitution_coefficient>0</restitution_coefficient>
              <threshold>1e+06</threshold>
            </bounce>
            <contact>
              <collide_without_contact>0</collide_without_contact>
              <collide_without_contact_bitmask>1</collide_without_contact_bitmask>
              <collide_bitmask>1</collide_bitmask>
              <ode>
                <soft_cfm>0</soft_cfm>
                <soft_erp>0.2</soft_erp>
                <kp>1e+13</kp>
                <kd>1</kd>
                <max_vel>0.01</max_vel>
                <min_depth>0</min_depth>
              </ode>
              <bullet>
                <split_impulse>1</split_impulse>
                <split_impulse_penetration_threshold>-0.01</split_impulse_penetration_threshold>
                <soft_cfm>0</soft_cfm>
                <soft_erp>0.2</soft_erp>
                <kp>1e+13</kp>
                <kd>1</kd>
              </bullet>
            </contact>
          </surface>
        </collision>
      </link>
      <static>1</static>
      <allow_auto_disable>1</allow_auto_disable>
      <pose frame=''>0.944649 -0.022652 0 0 -0 0</pose>
    </model>
    <state world_name='default'>
      <sim_time>805 108000000</sim_time>
      <real_time>824 30646952</real_time>
      <wall_time>1495102314 87744306</wall_time>
      <iterations>805108</iterations>
      <model name='board'>
        <pose frame=''>0.618845 -0.022652 0.484449 0 -0 0</pose>
        <scale>1 1 1</scale>
        <link name='link'>
          <pose frame=''>0.618845 -0.022652 0.484449 0 -0 0</pose>
          <velocity>0 0 0 0 -0 0</velocity>
          <acceleration>0 0 0 0 -0 0</acceleration>
          <wrench>0 0 0 0 -0 0</wrench>
        </link>
      </model>
      <model name='ground_plane'>
        <pose frame=''>0 0 0 0 -0 0</pose>
        <scale>1 1 1</scale>
        <link name='link'>
          <pose frame=''>0 0 0 0 -0 0</pose>
          <velocity>0 0 0 0 -0 0</velocity>
          <acceleration>0 0 0 0 -0 0</acceleration>
          <wrench>0 0 0 0 -0 0</wrench>
        </link>
      </model>
      <model name='mico-spawn'>
        <pose frame=''>-0 -0 0.01 0 -0 0</pose>
        <scale>1 1 1</scale>
        <link name='mico_link_1'>
          <pose frame=''>0 -0 0.1635 -3.14159 0 2.58114</pose>
          <velocity>-0 -0 0 0 -0 4e-06</velocity>
          <acceleration>-0 -0 0 -0 -1e-06 0.003909</acceleration>
          <wrench>-0 -0 0 0 -0 0</wrench>
        </link>
        <link name='mico_link_2'>
          <pose frame=''>0 -0 0.282 -1.57079 -1.01386 -0.560449</pose>
          <velocity>-0 -0 0 1.3e-05 2.1e-05 4e-06</velocity>
          <acceleration>0.002704 -0.001344 -0.001871 0.012741 0.020659 0.003966</acceleration>
          <wrench>0.005408 -0.002688 -0.003742 0 -0 0</wrench>
        </link>
        <link name='mico_link_3'>
          <pose frame=''>0.129841 -0.081485 0.528174 1.57079 1.27764 -0.560449</pose>
          <velocity>5e-06 -3e-06 -4e-06 2.5e-05 4.1e-05 4e-06</velocity>
          <acceleration>0.003045 -0.001122 -0.004593 0.02535 0.040544 0.003917</acceleration>
          <wrench>0.006089 -0.002243 -0.009186 0 -0 0</wrench>
        </link>
        <link name='mico_link_4'>
          <pose frame=''>0.164439 -0.093222 0.410421 -0.288709 0.051644 1.18243</pose>
          <velocity>1e-06 0 -5e-06 2.5e-05 4.1e-05 7e-06</velocity>
          <acceleration>-0.000731 0.001347 -0.005776 0.024581 0.041096 0.007297</acceleration>
          <wrench>-0.001461 0.002694 -0.011553 0 -0 0</wrench>
        </link>
        <link name='mico_link_5'>
          <pose frame=''>0.193536 -0.071638 0.345581 0.912897 -0.256888 -0.398416</pose>
          <velocity>-2e-06 2e-06 -6e-06 3.1e-05 5e-05 -1e-06</velocity>
          <acceleration>-0.002889 0.002695 -0.007138 0.030626 0.050045 -0.000591</acceleration>
          <wrench>-0.005778 0.00539 -0.014276 0 -0 0</wrench>
        </link>
        <link name='mico_link_finger_1'>
          <pose frame=''>0.356786 -0.072242 0.305307 -0.062811 0.140685 0.207202</pose>
          <velocity>-4e-06 3e-06 -1.4e-05 3.2e-05 5e-05 3e-06</velocity>
          <acceleration>-0.004321 0.003541 -0.015323 0.031924 0.050415 0.002844</acceleration>
          <wrench>-0.008642 0.007082 -0.030645 0 -0 0</wrench>
        </link>
        <link name='mico_link_finger_2'>
          <pose frame=''>0.34984 0.006759 0.29896 3.04482 0.120053 -0.052632</pose>
          <velocity>-4e-06 4e-06 -1.1e-05 3.2e-05 5e-05 1e-06</velocity>
          <acceleration>-0.004563 0.003696 -0.012586 0.031678 0.050235 0.000905</acceleration>
          <wrench>-0.009127 0.007392 -0.025172 0 -0 0</wrench>
        </link>
        <link name='mico_link_hand'>
          <pose frame=''>0.253769 -0.040433 0.315335 -1.43891 0.079859 1.65849</pose>
          <velocity>-4e-06 3e-06 -8e-06 3.1e-05 5e-05 -1e-06</velocity>
          <acceleration>-0.003636 0.00314 -0.008167 0.031475 0.050087 -0.000701</acceleration>
          <wrench>-0.003636 0.00314 -0.008167 0 -0 0</wrench>
        </link>
        <link name='root'>
          <pose frame=''>-0 -0 0.01 0 -0 0</pose>
          <velocity>-0 -0 0 0 -0 0</velocity>
          <acceleration>0 0 -0 0 -0 0</acceleration>
          <wrench>0 0 -0 0 -0 0</wrench>
        </link>
      </model>
      <light name='sun'>
        <pose frame=''>0 0 10 0 -0 0</pose>
      </light>
    </state>
    <gui fullscreen='0'>
      <camera name='user_camera'>
        <pose frame=''>-0.351005 1.69007 3.41439 0 1.21564 -1.68781</pose>
        <view_controller>orbit</view_controller>
        <projection_type>perspective</projection_type>
      </camera>
    </gui>
  </world>
</sdf>
