<?xml version="1.0" ?>
<!-- =================================================================================== -->
<!-- |    This document was autogenerated by xacro from test.urdf.xacro                | -->
<!-- |    EDITING THIS FILE BY HAND IS NOT RECOMMENDED                                 | -->
<!-- =================================================================================== -->
<robot name="mico" xmlns:body="http://playerstage.sourceforge.net/gazebo/xmlschema/#body" xmlns:controller="http://playerstage.sourceforge.net/gazebo/xmlschema/#controller" xmlns:gazebo="http://playerstage.sourceforge.net/gazebo/xmlschema/#gz" xmlns:geom="http://playerstage.sourceforge.net/gazebo/xmlschema/#geom" xmlns:interface="http://playerstage.sourceforge.net/gazebo/xmlschema/#interface" xmlns:joint="http://playerstage.sourceforge.net/gazebo/xmlschema/#joint" xmlns:model="http://playerstage.sourceforge.net/gazebo/xmlschema/#model" xmlns:physics="http://playerstage.sourceforge.net/gazebo/xmlschema/#physics" xmlns:renderable="http://playerstage.sourceforge.net/gazebo/xmlschema/#renderable" xmlns:rendering="http://playerstage.sourceforge.net/gazebo/xmlschema/#rendering" xmlns:sensor="http://playerstage.sourceforge.net/gazebo/xmlschema/#sensor" xmlns:xacro="http://ros.org/wiki/xacro" xmlns:xi="http://www.w3.org/2001/XInclude">
  <link name="eef"/>
  <joint name="eef_joint" type="fixed">
    <parent link="mico_link_hand"/>
    <child link="eef"/>
    <origin rpy="0 0 0" xyz="0.0 0.0 -0.16"/>
  </joint>
  <link name="root">
    <inertial>
      <!-- fnh -->
      <origin xyz="0 0 0"/>
      <mass value="10000.0"/>
      <inertia ixx="1" ixy="0" ixz="0" iyy="1" iyz="0" izz="1"/>
    </inertial>
    <visual>
      <origin rpy="0 0 0" xyz="0 0 0"/>
      <geometry>
        <box size="0.5 0.5 0.02"/>
      </geometry>
    </visual>
    <collision>
      <origin rpy="0 0 0" xyz="0 0 0"/>
      <geometry>
        <box size="0.5 0.5 0.02"/>
      </geometry>
    </collision>
  </link>
  <link name="mico_link_base">
    <inertial>
      <!-- fnh -->
      <origin xyz="0 0 0"/>
      <mass value="1.0"/>
      <inertia ixx="1" ixy="0" ixz="0" iyy="1" iyz="0" izz="1"/>
    </inertial>
    <visual>
      <geometry>
        <mesh filename="package://mico_gazebo/meshes/mico_link_base.dae"/>
      </geometry>
      <material name="carbon_fiber">
        <color rgba="0.792156862745098 0.819607843137255 0.933333333333333 1"/>
      </material>
    </visual>
    <collision>
      <geometry>
        <mesh filename="package://mico_gazebo/meshes/mico_link_base.dae"/>
      </geometry>
    </collision>
  </link>
  <gazebo reference="mico_link_base">
    <!-- fnh -->
    <material>Gazebo/Grey</material>
    <turnGravityOff>false</turnGravityOff>
    <selfCollide>true</selfCollide>
    <mu1>100.0</mu1>
    <mu2>100.0</mu2>
    <kp>1000000.0</kp>
    <kd>1.0</kd>
  </gazebo>
  <joint name="mico_joint_base" type="fixed">
    <parent link="root"/>
    <child link="mico_link_base"/>
    <axis xyz="0 0 0"/>
    <origin rpy="0 0 0" xyz="0 0 0"/>
    <limit effort="30000" lower="-6.28318530718" upper="6.28318530718" velocity="5"/>
  </joint>
  <link name="mico_link_1">
    <inertial>
      <!-- fnh -->
      <origin xyz="0 0 0"/>
      <mass value="1.0"/>
      <inertia ixx="1" ixy="0" ixz="0" iyy="1" iyz="0" izz="1"/>
    </inertial>
    <visual>
      <geometry>
        <mesh filename="package://mico_gazebo/meshes/mico_link_1.dae"/>
      </geometry>
      <material name="carbon_fiber">
        <color rgba="0.792156862745098 0.819607843137255 0.933333333333333 1"/>
      </material>
    </visual>
    <collision>
      <geometry>
        <mesh filename="package://mico_gazebo/meshes/mico_link_1.dae"/>
      </geometry>
    </collision>
  </link>
  <gazebo reference="mico_link_1">
    <!-- fnh -->
    <material>Gazebo/Grey</material>
    <turnGravityOff>false</turnGravityOff>
    <selfCollide>true</selfCollide>
    <mu1>100.0</mu1>
    <mu2>100.0</mu2>
    <kp>1000000.0</kp>
    <kd>1.0</kd>
  </gazebo>
  <joint name="mico_joint_1" type="continuous">
    <parent link="mico_link_base"/>
    <child link="mico_link_1"/>
    <axis xyz="0 0 1"/>
    <origin rpy="3.14159265359 0 0" xyz="0 0 0.1535"/>
    <limit effort="30000" lower="-6.28318530718" upper="6.28318530718" velocity="5"/>
  </joint>
  <transmission name="mico_joint_1_transmission">
    <type>transmission_interface/SimpleTransmission</type>
    <actuator name="mico_joint_1_motor">
      <hardwareInterface>EffortJointInterface</hardwareInterface>
      <mechanicalReduction>50</mechanicalReduction>
      <motorTorqueConstant>10</motorTorqueConstant>
      <pulsesPerRevolution>10000</pulsesPerRevolution>
    </actuator>
    <joint name="mico_joint_1">
      <hardwareInterface>EffortJointInterface</hardwareInterface>
    </joint>
  </transmission>
  <link name="mico_link_2">
    <inertial>
      <!-- fnh -->
      <origin xyz="0 0 0"/>
      <mass value="1.0"/>
      <inertia ixx="1" ixy="0" ixz="0" iyy="1" iyz="0" izz="1"/>
    </inertial>
    <visual>
      <geometry>
        <mesh filename="package://mico_gazebo/meshes/mico_link_2.dae"/>
      </geometry>
      <material name="carbon_fiber">
        <color rgba="0.792156862745098 0.819607843137255 0.933333333333333 1"/>
      </material>
    </visual>
    <collision>
      <geometry>
        <mesh filename="package://mico_gazebo/meshes/mico_link_2.dae"/>
      </geometry>
    </collision>
  </link>
  <gazebo reference="mico_link_2">
    <!-- fnh -->
    <material>Gazebo/Grey</material>
    <turnGravityOff>false</turnGravityOff>
    <selfCollide>true</selfCollide>
    <mu1>100.0</mu1>
    <mu2>100.0</mu2>
    <kp>1000000.0</kp>
    <kd>1.0</kd>
  </gazebo>
  <joint name="mico_joint_2" type="revolute">
    <parent link="mico_link_1"/>
    <child link="mico_link_2"/>
    <axis xyz="0 0 1"/>
    <origin rpy="-1.57079632679 -1.57079632679 0" xyz="0 0 -0.1185"/>
    <limit effort="30000" lower="0.872664626" upper="5.41052068" velocity="5"/>
  </joint>
  <transmission name="mico_joint_2_transmission">
    <type>transmission_interface/SimpleTransmission</type>
    <actuator name="mico_joint_2_motor">
      <hardwareInterface>EffortJointInterface</hardwareInterface>
      <mechanicalReduction>50</mechanicalReduction>
      <motorTorqueConstant>10</motorTorqueConstant>
      <pulsesPerRevolution>10000</pulsesPerRevolution>
    </actuator>
    <joint name="mico_joint_2">
      <hardwareInterface>EffortJointInterface</hardwareInterface>
    </joint>
  </transmission>
  <link name="mico_link_3">
    <inertial>
      <!-- fnh -->
      <origin xyz="0 0 0"/>
      <mass value="1.0"/>
      <inertia ixx="1" ixy="0" ixz="0" iyy="1" iyz="0" izz="1"/>
    </inertial>
    <visual>
      <geometry>
        <mesh filename="package://mico_gazebo/meshes/mico_link_3.dae"/>
      </geometry>
      <material name="carbon_fiber">
        <color rgba="0.792156862745098 0.819607843137255 0.933333333333333 1"/>
      </material>
    </visual>
    <collision>
      <geometry>
        <mesh filename="package://mico_gazebo/meshes/mico_link_3.dae"/>
      </geometry>
    </collision>
  </link>
  <gazebo reference="mico_link_3">
    <!-- fnh -->
    <material>Gazebo/Grey</material>
    <turnGravityOff>false</turnGravityOff>
    <selfCollide>true</selfCollide>
    <mu1>100.0</mu1>
    <mu2>100.0</mu2>
    <kp>1000000.0</kp>
    <kd>1.0</kd>
  </gazebo>
  <joint name="mico_joint_3" type="revolute">
    <parent link="mico_link_2"/>
    <child link="mico_link_3"/>
    <axis xyz="0 0 1"/>
    <origin rpy="3.14159265359 0 3.14159265359" xyz="0.29 0 0"/>
    <limit effort="30000" lower="0.610865238" upper="5.67232007" velocity="5"/>
  </joint>
  <transmission name="mico_joint_3_transmission">
    <type>transmission_interface/SimpleTransmission</type>
    <actuator name="mico_joint_3_motor">
      <hardwareInterface>EffortJointInterface</hardwareInterface>
      <mechanicalReduction>50</mechanicalReduction>
      <motorTorqueConstant>10</motorTorqueConstant>
      <pulsesPerRevolution>10000</pulsesPerRevolution>
    </actuator>
    <joint name="mico_joint_3">
      <hardwareInterface>EffortJointInterface</hardwareInterface>
    </joint>
  </transmission>
  <link name="mico_link_4">
    <inertial>
      <!-- fnh -->
      <origin xyz="0 0 0"/>
      <mass value="1.0"/>
      <inertia ixx="1" ixy="0" ixz="0" iyy="1" iyz="0" izz="1"/>
    </inertial>
    <visual>
      <geometry>
        <mesh filename="package://mico_gazebo/meshes/mico_link_4_5.dae"/>
      </geometry>
      <material name="carbon_fiber">
        <color rgba="0.792156862745098 0.819607843137255 0.933333333333333 1"/>
      </material>
    </visual>
    <collision>
      <geometry>
        <mesh filename="package://mico_gazebo/meshes/mico_link_4_5.dae"/>
      </geometry>
    </collision>
  </link>
  <gazebo reference="mico_link_4">
    <!-- fnh -->
    <material>Gazebo/Grey</material>
    <turnGravityOff>false</turnGravityOff>
    <selfCollide>true</selfCollide>
    <mu1>100.0</mu1>
    <mu2>100.0</mu2>
    <kp>1000000.0</kp>
    <kd>1.0</kd>
  </gazebo>
  <joint name="mico_joint_4" type="continuous">
    <parent link="mico_link_3"/>
    <child link="mico_link_4"/>
    <axis xyz="0 0 1"/>
    <origin rpy="0 -1.57079632679 0" xyz="0.123 0 -0.00845"/>
    <limit effort="30000" lower="-6.28318530718" upper="6.28318530718" velocity="5"/>
  </joint>
  <transmission name="mico_joint_4_transmission">
    <type>transmission_interface/SimpleTransmission</type>
    <actuator name="mico_joint_4_motor">
      <hardwareInterface>EffortJointInterface</hardwareInterface>
      <mechanicalReduction>50</mechanicalReduction>
      <motorTorqueConstant>10</motorTorqueConstant>
      <pulsesPerRevolution>10000</pulsesPerRevolution>
    </actuator>
    <joint name="mico_joint_4">
      <hardwareInterface>EffortJointInterface</hardwareInterface>
    </joint>
  </transmission>
  <link name="mico_link_5">
    <inertial>
      <!-- fnh -->
      <origin xyz="0 0 0"/>
      <mass value="1.0"/>
      <inertia ixx="1" ixy="0" ixz="0" iyy="1" iyz="0" izz="1"/>
    </inertial>
    <visual>
      <geometry>
        <mesh filename="package://mico_gazebo/meshes/mico_link_4_5.dae"/>
      </geometry>
      <material name="carbon_fiber">
        <color rgba="0.792156862745098 0.819607843137255 0.933333333333333 1"/>
      </material>
    </visual>
    <collision>
      <geometry>
        <mesh filename="package://mico_gazebo/meshes/mico_link_4_5.dae"/>
      </geometry>
    </collision>
  </link>
  <gazebo reference="mico_link_5">
    <!-- fnh -->
    <material>Gazebo/Grey</material>
    <turnGravityOff>false</turnGravityOff>
    <selfCollide>true</selfCollide>
    <mu1>100.0</mu1>
    <mu2>100.0</mu2>
    <kp>1000000.0</kp>
    <kd>1.0</kd>
  </gazebo>
  <joint name="mico_joint_5" type="continuous">
    <parent link="mico_link_4"/>
    <child link="mico_link_5"/>
    <axis xyz="0 0 1"/>
    <origin rpy="0 0.959931088597 3.14159265359" xyz="0.0343 0 -0.06588"/>
    <limit effort="30000" lower="-6.28318530718" upper="6.28318530718" velocity="5"/>
  </joint>
  <transmission name="mico_joint_5_transmission">
    <type>transmission_interface/SimpleTransmission</type>
    <actuator name="mico_joint_5_motor">
      <hardwareInterface>EffortJointInterface</hardwareInterface>
      <mechanicalReduction>50</mechanicalReduction>
      <motorTorqueConstant>10</motorTorqueConstant>
      <pulsesPerRevolution>10000</pulsesPerRevolution>
    </actuator>
    <joint name="mico_joint_5">
      <hardwareInterface>EffortJointInterface</hardwareInterface>
    </joint>
  </transmission>
  <link name="mico_link_hand">
    <inertial>
      <!-- fnh -->
      <origin xyz="0 0 0"/>
      <mass value="1.0"/>
      <inertia ixx="1" ixy="0" ixz="0" iyy="1" iyz="0" izz="1"/>
    </inertial>
    <visual>
      <geometry>
        <mesh filename="package://mico_gazebo/meshes/mico_link_hand.dae"/>
      </geometry>
      <material name="carbon_fiber">
        <color rgba="0.792156862745098 0.819607843137255 0.933333333333333 1"/>
      </material>
    </visual>
    <collision>
      <geometry>
        <mesh filename="package://mico_gazebo/meshes/mico_link_hand.dae"/>
      </geometry>
    </collision>
  </link>
  <gazebo reference="mico_link_hand">
    <!-- fnh -->
    <material>Gazebo/Grey</material>
    <turnGravityOff>false</turnGravityOff>
    <selfCollide>true</selfCollide>
    <mu1>100.0</mu1>
    <mu2>100.0</mu2>
    <kp>1000000.0</kp>
    <kd>1.0</kd>
  </gazebo>
  <joint name="mico_joint_6" type="continuous">
    <parent link="mico_link_5"/>
    <child link="mico_link_hand"/>
    <axis xyz="0 0 1"/>
    <origin rpy="0 0.959931088597 3.14159265359" xyz="0.0343 0 -0.06588"/>
    <limit effort="30000" lower="-6.28318530718" upper="6.28318530718" velocity="5"/>
  </joint>
  <transmission name="mico_joint_6_transmission">
    <type>transmission_interface/SimpleTransmission</type>
    <actuator name="mico_joint_6_motor">
      <hardwareInterface>EffortJointInterface</hardwareInterface>
      <mechanicalReduction>50</mechanicalReduction>
      <motorTorqueConstant>10</motorTorqueConstant>
      <pulsesPerRevolution>10000</pulsesPerRevolution>
    </actuator>
    <joint name="mico_joint_6">
      <hardwareInterface>EffortJointInterface</hardwareInterface>
    </joint>
  </transmission>
  <link name="mico_large_ring_cover_1">
    <inertial>
      <!-- fnh -->
      <origin xyz="0 0 0"/>
      <mass value="1.0"/>
      <inertia ixx="1" ixy="0" ixz="0" iyy="1" iyz="0" izz="1"/>
    </inertial>
    <visual>
      <geometry>
        <mesh filename="package://mico_gazebo/meshes/mico_large_ring_cover.dae" scale="0.0254 0.0254 0.0254"/>
      </geometry>
      <material name="carbon_fiber">
        <color rgba="0.792156862745098 0.819607843137255 0.933333333333333 1"/>
      </material>
    </visual>
    <collision>
      <geometry>
        <mesh filename="package://mico_gazebo/meshes/mico_large_ring_cover.dae" scale="0.0254 0.0254 0.0254"/>
      </geometry>
    </collision>
  </link>
  <gazebo reference="mico_large_ring_cover_1">
    <!-- fnh -->
    <material>Gazebo/Grey</material>
    <turnGravityOff>false</turnGravityOff>
    <selfCollide>true</selfCollide>
    <mu1>100.0</mu1>
    <mu2>100.0</mu2>
    <kp>1000000.0</kp>
    <kd>1.0</kd>
  </gazebo>
  <joint name="mico_large_ring_cover_1_joint" type="fixed">
    <parent link="mico_link_base"/>
    <child link="mico_large_ring_cover_1"/>
    <axis xyz="0 0 1"/>
    <origin rpy="3.14159265359 0 0" xyz="0 0 0.1535"/>
    <limit effort="30000" lower="-6.28318530718" upper="6.28318530718" velocity="5"/>
  </joint>
  <link name="mico_large_ring_cover_2">
    <inertial>
      <!-- fnh -->
      <origin xyz="0 0 0"/>
      <mass value="1.0"/>
      <inertia ixx="1" ixy="0" ixz="0" iyy="1" iyz="0" izz="1"/>
    </inertial>
    <visual>
      <geometry>
        <mesh filename="package://mico_gazebo/meshes/mico_large_ring_cover.dae" scale="0.0254 0.0254 0.0254"/>
      </geometry>
      <material name="carbon_fiber">
        <color rgba="0.792156862745098 0.819607843137255 0.933333333333333 1"/>
      </material>
    </visual>
    <collision>
      <geometry>
        <mesh filename="package://mico_gazebo/meshes/mico_large_ring_cover.dae" scale="0.0254 0.0254 0.0254"/>
      </geometry>
    </collision>
  </link>
  <gazebo reference="mico_large_ring_cover_2">
    <!-- fnh -->
    <material>Gazebo/Grey</material>
    <turnGravityOff>false</turnGravityOff>
    <selfCollide>true</selfCollide>
    <mu1>100.0</mu1>
    <mu2>100.0</mu2>
    <kp>1000000.0</kp>
    <kd>1.0</kd>
  </gazebo>
  <joint name="mico_large_ring_cover_2_joint" type="fixed">
    <parent link="mico_link_1"/>
    <child link="mico_large_ring_cover_2"/>
    <axis xyz="0 0 1"/>
    <origin rpy="-1.57079632679 -1.57079632679 0" xyz="0 0 -0.1185"/>
    <limit effort="30000" lower="0" upper="6.28318530718" velocity="5"/>
  </joint>
  <link name="mico_large_ring_cover_3">
    <inertial>
      <!-- fnh -->
      <origin xyz="0 0 0"/>
      <mass value="1.0"/>
      <inertia ixx="1" ixy="0" ixz="0" iyy="1" iyz="0" izz="1"/>
    </inertial>
    <visual>
      <geometry>
        <mesh filename="package://mico_gazebo/meshes/mico_large_ring_cover.dae" scale="0.0254 0.0254 0.0254"/>
      </geometry>
      <material name="carbon_fiber">
        <color rgba="0.792156862745098 0.819607843137255 0.933333333333333 1"/>
      </material>
    </visual>
    <collision>
      <geometry>
        <mesh filename="package://mico_gazebo/meshes/mico_large_ring_cover.dae" scale="0.0254 0.0254 0.0254"/>
      </geometry>
    </collision>
  </link>
  <gazebo reference="mico_large_ring_cover_3">
    <!-- fnh -->
    <material>Gazebo/Grey</material>
    <turnGravityOff>false</turnGravityOff>
    <selfCollide>true</selfCollide>
    <mu1>100.0</mu1>
    <mu2>100.0</mu2>
    <kp>1000000.0</kp>
    <kd>1.0</kd>
  </gazebo>
  <joint name="mico_large_ring_cover_3_joint" type="fixed">
    <parent link="mico_link_2"/>
    <child link="mico_large_ring_cover_3"/>
    <axis xyz="0 0 1"/>
    <origin rpy="3.14159265359 0 3.14159265359" xyz="0.29 0 0"/>
    <limit effort="30000" lower="0" upper="6.28318530718" velocity="5"/>
  </joint>
  <link name="mico_small_ring_cover_1">
    <inertial>
      <!-- fnh -->
      <origin xyz="0 0 0"/>
      <mass value="1.0"/>
      <inertia ixx="1" ixy="0" ixz="0" iyy="1" iyz="0" izz="1"/>
    </inertial>
    <visual>
      <geometry>
        <mesh filename="package://mico_gazebo/meshes/mico_small_ring_cover.dae" scale="0.0254 0.0254 0.0254"/>
      </geometry>
      <material name="carbon_fiber">
        <color rgba="0.792156862745098 0.819607843137255 0.933333333333333 1"/>
      </material>
    </visual>
    <collision>
      <geometry>
        <mesh filename="package://mico_gazebo/meshes/mico_small_ring_cover.dae" scale="0.0254 0.0254 0.0254"/>
      </geometry>
    </collision>
  </link>
  <gazebo reference="mico_small_ring_cover_1">
    <!-- fnh -->
    <material>Gazebo/Grey</material>
    <turnGravityOff>false</turnGravityOff>
    <selfCollide>true</selfCollide>
    <mu1>100.0</mu1>
    <mu2>100.0</mu2>
    <kp>1000000.0</kp>
    <kd>1.0</kd>
  </gazebo>
  <joint name="mico_large_ring_cover_4_joint" type="fixed">
    <parent link="mico_link_3"/>
    <child link="mico_small_ring_cover_1"/>
    <axis xyz="0 0 1"/>
    <origin rpy="0 -1.57079632679 0" xyz="0.123 0 -0.00845"/>
    <limit effort="30000" lower="-6.28318530718" upper="6.28318530718" velocity="5"/>
  </joint>
  <link name="mico_small_ring_cover_2">
    <inertial>
      <!-- fnh -->
      <origin xyz="0 0 0"/>
      <mass value="1.0"/>
      <inertia ixx="1" ixy="0" ixz="0" iyy="1" iyz="0" izz="1"/>
    </inertial>
    <visual>
      <geometry>
        <mesh filename="package://mico_gazebo/meshes/mico_small_ring_cover.dae" scale="0.0254 0.0254 0.0254"/>
      </geometry>
      <material name="carbon_fiber">
        <color rgba="0.792156862745098 0.819607843137255 0.933333333333333 1"/>
      </material>
    </visual>
    <collision>
      <geometry>
        <mesh filename="package://mico_gazebo/meshes/mico_small_ring_cover.dae" scale="0.0254 0.0254 0.0254"/>
      </geometry>
    </collision>
  </link>
  <gazebo reference="mico_small_ring_cover_2">
    <!-- fnh -->
    <material>Gazebo/Grey</material>
    <turnGravityOff>false</turnGravityOff>
    <selfCollide>true</selfCollide>
    <mu1>100.0</mu1>
    <mu2>100.0</mu2>
    <kp>1000000.0</kp>
    <kd>1.0</kd>
  </gazebo>
  <joint name="mico_large_ring_cover_5_joint" type="fixed">
    <parent link="mico_link_4"/>
    <child link="mico_small_ring_cover_2"/>
    <axis xyz="0 0 1"/>
    <origin rpy="0 0.959931088597 3.14159265359" xyz="0.0343 0 -0.06588"/>
    <limit effort="30000" lower="-6.28318530718" upper="6.28318530718" velocity="5"/>
  </joint>
  <link name="mico_small_ring_cover_3">
    <inertial>
      <!-- fnh -->
      <origin xyz="0 0 0"/>
      <mass value="1.0"/>
      <inertia ixx="1" ixy="0" ixz="0" iyy="1" iyz="0" izz="1"/>
    </inertial>
    <visual>
      <geometry>
        <mesh filename="package://mico_gazebo/meshes/mico_small_ring_cover.dae" scale="0.0254 0.0254 0.0254"/>
      </geometry>
      <material name="carbon_fiber">
        <color rgba="0.792156862745098 0.819607843137255 0.933333333333333 1"/>
      </material>
    </visual>
    <collision>
      <geometry>
        <mesh filename="package://mico_gazebo/meshes/mico_small_ring_cover.dae" scale="0.0254 0.0254 0.0254"/>
      </geometry>
    </collision>
  </link>
  <gazebo reference="mico_small_ring_cover_3">
    <!-- fnh -->
    <material>Gazebo/Grey</material>
    <turnGravityOff>false</turnGravityOff>
    <selfCollide>true</selfCollide>
    <mu1>100.0</mu1>
    <mu2>100.0</mu2>
    <kp>1000000.0</kp>
    <kd>1.0</kd>
  </gazebo>
  <joint name="mico_large_ring_cover_6_joint" type="fixed">
    <parent link="mico_link_5"/>
    <child link="mico_small_ring_cover_3"/>
    <axis xyz="0 0 1"/>
    <origin rpy="0 0.959931088597 3.14159265359" xyz="0.0343 0 -0.06588"/>
    <limit effort="30000" lower="-6.28318530718" upper="6.28318530718" velocity="5"/>
  </joint>
  <link name="mico_link_finger_1">
    <inertial>
      <!-- fnh -->
      <origin xyz="0 0 0"/>
      <mass value="1.0"/>
      <inertia ixx="1" ixy="0" ixz="0" iyy="1" iyz="0" izz="1"/>
    </inertial>
    <visual>
      <geometry>
        <mesh filename="package://mico_gazebo/meshes/mico_link_finger.dae" scale="0.0254 0.0254 0.0254"/>
      </geometry>
      <material name="carbon_fiber">
        <color rgba="0.792156862745098 0.819607843137255 0.933333333333333 1"/>
      </material>
    </visual>
    <collision>
      <geometry>
        <mesh filename="package://mico_gazebo/meshes/mico_link_finger.dae" scale="0.0254 0.0254 0.0254"/>
      </geometry>
    </collision>
  </link>
  <gazebo reference="mico_link_finger_1">
    <!-- fnh -->
    <material>Gazebo/Grey</material>
    <turnGravityOff>false</turnGravityOff>
    <selfCollide>true</selfCollide>
    <mu1>100.0</mu1>
    <mu2>100.0</mu2>
    <kp>1000000.0</kp>
    <kd>1.0</kd>
  </gazebo>
  <joint name="mico_joint_finger_1" type="revolute">
    <parent link="mico_link_hand"/>
    <child link="mico_link_finger_1"/>
    <axis xyz="0 0 1"/>
    <origin rpy="-1.5707 1.1 3.1416" xyz="-0.03978 0 -0.10071"/>
    <limit effort="30000" lower="0" upper="0.698131700798" velocity="36"/>
  </joint>
  <transmission name="mico_joint_finger_1_transmission">
    <type>transmission_interface/SimpleTransmission</type>
    <actuator name="mico_joint_finger_1_motor">
      <hardwareInterface>EffortJointInterface</hardwareInterface>
      <mechanicalReduction>50</mechanicalReduction>
      <motorTorqueConstant>10</motorTorqueConstant>
      <pulsesPerRevolution>10000</pulsesPerRevolution>
    </actuator>
    <joint name="mico_joint_finger_1">
      <hardwareInterface>EffortJointInterface</hardwareInterface>
    </joint>
  </transmission>
  <link name="mico_link_finger_2">
    <inertial>
      <!-- fnh -->
      <origin xyz="0 0 0"/>
      <mass value="1.0"/>
      <inertia ixx="1" ixy="0" ixz="0" iyy="1" iyz="0" izz="1"/>
    </inertial>
    <visual>
      <geometry>
        <mesh filename="package://mico_gazebo/meshes/mico_link_finger.dae" scale="0.0254 0.0254 0.0254"/>
      </geometry>
      <material name="carbon_fiber">
        <color rgba="0.792156862745098 0.819607843137255 0.933333333333333 1"/>
      </material>
    </visual>
    <collision>
      <geometry>
        <mesh filename="package://mico_gazebo/meshes/mico_link_finger.dae" scale="0.0254 0.0254 0.0254"/>
      </geometry>
    </collision>
  </link>
  <gazebo reference="mico_link_finger_2">
    <!-- fnh -->
    <material>Gazebo/Grey</material>
    <turnGravityOff>false</turnGravityOff>
    <selfCollide>true</selfCollide>
    <mu1>100.0</mu1>
    <mu2>100.0</mu2>
    <kp>1000000.0</kp>
    <kd>1.0</kd>
  </gazebo>
  <joint name="mico_joint_finger_2" type="revolute">
    <parent link="mico_link_hand"/>
    <child link="mico_link_finger_2"/>
    <axis xyz="0 0 1"/>
    <origin rpy="-1.5707 1.1 0.0" xyz="0.03978 0 -0.10071"/>
    <limit effort="30000" lower="0" upper="0.698131700798" velocity="36"/>
  </joint>
  <transmission name="mico_joint_finger_2_transmission">
    <type>transmission_interface/SimpleTransmission</type>
    <actuator name="mico_joint_finger_2_motor">
      <hardwareInterface>EffortJointInterface</hardwareInterface>
      <mechanicalReduction>50</mechanicalReduction>
      <motorTorqueConstant>10</motorTorqueConstant>
      <pulsesPerRevolution>10000</pulsesPerRevolution>
    </actuator>
    <joint name="mico_joint_finger_2">
      <hardwareInterface>EffortJointInterface</hardwareInterface>
    </joint>
  </transmission>
  <link name="mico_link_finger_tip_1">
    <inertial>
      <!-- fnh -->
      <origin xyz="0 0 0"/>
      <mass value="1.0"/>
      <inertia ixx="1" ixy="0" ixz="0" iyy="1" iyz="0" izz="1"/>
    </inertial>
    <visual>
      <geometry>
        <mesh filename="package://mico_gazebo/meshes/mico_link_finger_tip.dae" scale="0.0254 0.0254 0.0254"/>
      </geometry>
      <material name="carbon_fiber">
        <color rgba="0.792156862745098 0.819607843137255 0.933333333333333 1"/>
      </material>
    </visual>
    <collision>
      <geometry>
        <mesh filename="package://mico_gazebo/meshes/mico_link_finger_tip.dae" scale="0.0254 0.0254 0.0254"/>
      </geometry>
    </collision>
  </link>
  <gazebo reference="mico_link_finger_tip_1">
    <!-- fnh -->
    <material>Gazebo/Grey</material>
    <turnGravityOff>false</turnGravityOff>
    <selfCollide>true</selfCollide>
    <mu1>100.0</mu1>
    <mu2>100.0</mu2>
    <kp>1000000.0</kp>
    <kd>1.0</kd>
  </gazebo>
  <joint name="mico_joint_finger_tip_1" type="fixed">
    <parent link="mico_link_finger_1"/>
    <child link="mico_link_finger_tip_1"/>
    <axis xyz="0 0 1"/>
    <origin rpy="0 0 0" xyz="0.044094 -0.0029 0"/>
    <limit effort="30000" lower="0" upper="0.698131700798" velocity="5"/>
  </joint>
  <link name="mico_link_finger_tip_2">
    <inertial>
      <!-- fnh -->
      <origin xyz="0 0 0"/>
      <mass value="1.0"/>
      <inertia ixx="1" ixy="0" ixz="0" iyy="1" iyz="0" izz="1"/>
    </inertial>
    <visual>
      <geometry>
        <mesh filename="package://mico_gazebo/meshes/mico_link_finger_tip.dae" scale="0.0254 0.0254 0.0254"/>
      </geometry>
      <material name="carbon_fiber">
        <color rgba="0.792156862745098 0.819607843137255 0.933333333333333 1"/>
      </material>
    </visual>
    <collision>
      <geometry>
        <mesh filename="package://mico_gazebo/meshes/mico_link_finger_tip.dae" scale="0.0254 0.0254 0.0254"/>
      </geometry>
    </collision>
  </link>
  <gazebo reference="mico_link_finger_tip_2">
    <!-- fnh -->
    <material>Gazebo/Grey</material>
    <turnGravityOff>false</turnGravityOff>
    <selfCollide>true</selfCollide>
    <mu1>100.0</mu1>
    <mu2>100.0</mu2>
    <kp>1000000.0</kp>
    <kd>1.0</kd>
  </gazebo>
  <joint name="mico_joint_finger_tip_2" type="fixed">
    <parent link="mico_link_finger_2"/>
    <child link="mico_link_finger_tip_2"/>
    <axis xyz="0 0 1"/>
    <origin rpy="0 0 0" xyz="0.044094 -0.0029 0"/>
    <limit effort="30000" lower="0" upper="0.698131700798" velocity="5"/>
  </joint>
  <gazebo>
    <plugin filename="libgazebo_ros_control.so" name="gazebo_ros_control">
      <robotNamespace>/mico</robotNamespace>
    </plugin>
  </gazebo>
</robot>

